2022-02-08 17:12:29,162 - INFO requestbase.py [line:21]: 连通接口"https://supplychain-server-stg.datousoft.jmj1995.com/items/1/belongingStandardAlternativeItemGroup",接口header为:"{'authorization': 'Bearer eyJhbGciOiJIUzUxMiJ9.eyJqdGkiOiI3MTk0NWY1OGYzYTQ0OWY3OWVmYzM4MTdjZDdiYjBlNyIsImF1dGgiOiIiLCJpZCI6NTk5LCJzdWIiOiIxMiJ9.s9x_iYROhFujmW09Bu5HFfhwqp8_8WaC08vyveK_S0SUolxbVY7tnWy17BW6XmROb-gHFxSWfiH3gpurKcNsWg'}",接口param为：
2022-02-08 17:12:29,167 - ERROR requestbase.py [line:28]: 等待接口"https://supplychain-server-stg.datousoft.jmj1995.com/items/1/belongingStandardAlternativeItemGroup"失败
Traceback (most recent call last):
  File "C:\Users\bonjour\AppData\Local\Programs\Python\Python39\lib\site-packages\urllib3\connection.py", line 169, in _new_conn
    conn = connection.create_connection(
  File "C:\Users\bonjour\AppData\Local\Programs\Python\Python39\lib\site-packages\urllib3\util\connection.py", line 73, in create_connection
    for res in socket.getaddrinfo(host, port, family, socket.SOCK_STREAM):
  File "C:\Users\bonjour\AppData\Local\Programs\Python\Python39\lib\socket.py", line 953, in getaddrinfo
    for res in _socket.getaddrinfo(host, port, family, type, proto, flags):
socket.gaierror: [Errno 11001] getaddrinfo failed

During handling of the above exception, another exception occurred:

Traceback (most recent call last):
  File "C:\Users\bonjour\AppData\Local\Programs\Python\Python39\lib\site-packages\urllib3\connectionpool.py", line 699, in urlopen
    httplib_response = self._make_request(
  File "C:\Users\bonjour\AppData\Local\Programs\Python\Python39\lib\site-packages\urllib3\connectionpool.py", line 382, in _make_request
    self._validate_conn(conn)
  File "C:\Users\bonjour\AppData\Local\Programs\Python\Python39\lib\site-packages\urllib3\connectionpool.py", line 1010, in _validate_conn
    conn.connect()
  File "C:\Users\bonjour\AppData\Local\Programs\Python\Python39\lib\site-packages\urllib3\connection.py", line 353, in connect
    conn = self._new_conn()
  File "C:\Users\bonjour\AppData\Local\Programs\Python\Python39\lib\site-packages\urllib3\connection.py", line 181, in _new_conn
    raise NewConnectionError(
urllib3.exceptions.NewConnectionError: <urllib3.connection.HTTPSConnection object at 0x00000189B6823580>: Failed to establish a new connection: [Errno 11001] getaddrinfo failed

During handling of the above exception, another exception occurred:

Traceback (most recent call last):
  File "C:\Users\bonjour\AppData\Local\Programs\Python\Python39\lib\site-packages\requests\adapters.py", line 439, in send
    resp = conn.urlopen(
  File "C:\Users\bonjour\AppData\Local\Programs\Python\Python39\lib\site-packages\urllib3\connectionpool.py", line 755, in urlopen
    retries = retries.increment(
  File "C:\Users\bonjour\AppData\Local\Programs\Python\Python39\lib\site-packages\urllib3\util\retry.py", line 574, in increment
    raise MaxRetryError(_pool, url, error or ResponseError(cause))
urllib3.exceptions.MaxRetryError: HTTPSConnectionPool(host='supplychain-server-stg.datousoft.jmj1995.com', port=443): Max retries exceeded with url: /items/1/belongingStandardAlternativeItemGroup (Caused by NewConnectionError('<urllib3.connection.HTTPSConnection object at 0x00000189B6823580>: Failed to establish a new connection: [Errno 11001] getaddrinfo failed'))

During handling of the above exception, another exception occurred:

Traceback (most recent call last):
  File "..\Common\requestbase.py", line 24, in get_Req
    res=requests.get(url=url,headers=headers,params=params,data=data,json=json)
  File "C:\Users\bonjour\AppData\Local\Programs\Python\Python39\lib\site-packages\requests\api.py", line 76, in get
    return request('get', url, params=params, **kwargs)
  File "C:\Users\bonjour\AppData\Local\Programs\Python\Python39\lib\site-packages\requests\api.py", line 61, in request
    return session.request(method=method, url=url, **kwargs)
  File "C:\Users\bonjour\AppData\Local\Programs\Python\Python39\lib\site-packages\requests\sessions.py", line 542, in request
    resp = self.send(prep, **send_kwargs)
  File "C:\Users\bonjour\AppData\Local\Programs\Python\Python39\lib\site-packages\requests\sessions.py", line 655, in send
    r = adapter.send(request, **kwargs)
  File "C:\Users\bonjour\AppData\Local\Programs\Python\Python39\lib\site-packages\requests\adapters.py", line 516, in send
    raise ConnectionError(e, request=request)
requests.exceptions.ConnectionError: HTTPSConnectionPool(host='supplychain-server-stg.datousoft.jmj1995.com', port=443): Max retries exceeded with url: /items/1/belongingStandardAlternativeItemGroup (Caused by NewConnectionError('<urllib3.connection.HTTPSConnection object at 0x00000189B6823580>: Failed to establish a new connection: [Errno 11001] getaddrinfo failed'))
2022-02-08 17:12:29,185 - INFO requestbase.py [line:69]: 连通接口"https://supplychain-server-stg.datousoft.jmj1995.com/items/1",接口data为:"",接口json{'enable': 'true', 'tags': ['12', '23', '34', '45', '56', '67', '78', '89', '01', '99953816724', '99897524630', '99135297046', '99254607193', '99310649275', '99376528194', '99352478916', '99503247816', '99187059632', '99953042716', '99638017452', '99237065184'], 'enableValidDays': 'true'}
2022-02-08 17:12:29,185 - INFO requestbase.py [line:69]: 连通接口"https://supplychain-server-stg.datousoft.jmj1995.com/items/1",接口data为:"",接口json{'enable': 'true', 'tags': ['12', '23', '34', '45', '56', '67', '78', '89', '01', '99953816724', '99897524630', '99135297046', '99254607193', '99310649275', '99376528194', '99352478916', '99503247816', '99187059632', '99953042716', '99638017452', '99237065184'], 'enableValidDays': 'true'}
2022-02-08 17:12:29,192 - ERROR requestbase.py [line:76]: 等待接口"https://supplychain-server-stg.datousoft.jmj1995.com/items/1"失败
Traceback (most recent call last):
  File "C:\Users\bonjour\AppData\Local\Programs\Python\Python39\lib\site-packages\urllib3\connection.py", line 169, in _new_conn
    conn = connection.create_connection(
  File "C:\Users\bonjour\AppData\Local\Programs\Python\Python39\lib\site-packages\urllib3\util\connection.py", line 73, in create_connection
    for res in socket.getaddrinfo(host, port, family, socket.SOCK_STREAM):
  File "C:\Users\bonjour\AppData\Local\Programs\Python\Python39\lib\socket.py", line 953, in getaddrinfo
    for res in _socket.getaddrinfo(host, port, family, type, proto, flags):
socket.gaierror: [Errno 11001] getaddrinfo failed

During handling of the above exception, another exception occurred:

Traceback (most recent call last):
  File "C:\Users\bonjour\AppData\Local\Programs\Python\Python39\lib\site-packages\urllib3\connectionpool.py", line 699, in urlopen
    httplib_response = self._make_request(
  File "C:\Users\bonjour\AppData\Local\Programs\Python\Python39\lib\site-packages\urllib3\connectionpool.py", line 382, in _make_request
    self._validate_conn(conn)
  File "C:\Users\bonjour\AppData\Local\Programs\Python\Python39\lib\site-packages\urllib3\connectionpool.py", line 1010, in _validate_conn
    conn.connect()
  File "C:\Users\bonjour\AppData\Local\Programs\Python\Python39\lib\site-packages\urllib3\connection.py", line 353, in connect
    conn = self._new_conn()
  File "C:\Users\bonjour\AppData\Local\Programs\Python\Python39\lib\site-packages\urllib3\connection.py", line 181, in _new_conn
    raise NewConnectionError(
urllib3.exceptions.NewConnectionError: <urllib3.connection.HTTPSConnection object at 0x00000189B68234F0>: Failed to establish a new connection: [Errno 11001] getaddrinfo failed

During handling of the above exception, another exception occurred:

Traceback (most recent call last):
  File "C:\Users\bonjour\AppData\Local\Programs\Python\Python39\lib\site-packages\requests\adapters.py", line 439, in send
    resp = conn.urlopen(
  File "C:\Users\bonjour\AppData\Local\Programs\Python\Python39\lib\site-packages\urllib3\connectionpool.py", line 755, in urlopen
    retries = retries.increment(
  File "C:\Users\bonjour\AppData\Local\Programs\Python\Python39\lib\site-packages\urllib3\util\retry.py", line 574, in increment
    raise MaxRetryError(_pool, url, error or ResponseError(cause))
urllib3.exceptions.MaxRetryError: HTTPSConnectionPool(host='supplychain-server-stg.datousoft.jmj1995.com', port=443): Max retries exceeded with url: /items/1 (Caused by NewConnectionError('<urllib3.connection.HTTPSConnection object at 0x00000189B68234F0>: Failed to establish a new connection: [Errno 11001] getaddrinfo failed'))

During handling of the above exception, another exception occurred:

Traceback (most recent call last):
  File "..\Common\requestbase.py", line 72, in patch_Req
    res=requests.patch(url=url,data=data,headers=headers,json=json,params=params)
  File "C:\Users\bonjour\AppData\Local\Programs\Python\Python39\lib\site-packages\requests\api.py", line 149, in patch
    return request('patch', url, data=data, **kwargs)
  File "C:\Users\bonjour\AppData\Local\Programs\Python\Python39\lib\site-packages\requests\api.py", line 61, in request
    return session.request(method=method, url=url, **kwargs)
  File "C:\Users\bonjour\AppData\Local\Programs\Python\Python39\lib\site-packages\requests\sessions.py", line 542, in request
    resp = self.send(prep, **send_kwargs)
  File "C:\Users\bonjour\AppData\Local\Programs\Python\Python39\lib\site-packages\requests\sessions.py", line 655, in send
    r = adapter.send(request, **kwargs)
  File "C:\Users\bonjour\AppData\Local\Programs\Python\Python39\lib\site-packages\requests\adapters.py", line 516, in send
    raise ConnectionError(e, request=request)
requests.exceptions.ConnectionError: HTTPSConnectionPool(host='supplychain-server-stg.datousoft.jmj1995.com', port=443): Max retries exceeded with url: /items/1 (Caused by NewConnectionError('<urllib3.connection.HTTPSConnection object at 0x00000189B68234F0>: Failed to establish a new connection: [Errno 11001] getaddrinfo failed'))
2022-02-08 17:12:29,192 - ERROR requestbase.py [line:76]: 等待接口"https://supplychain-server-stg.datousoft.jmj1995.com/items/1"失败
Traceback (most recent call last):
  File "C:\Users\bonjour\AppData\Local\Programs\Python\Python39\lib\site-packages\urllib3\connection.py", line 169, in _new_conn
    conn = connection.create_connection(
  File "C:\Users\bonjour\AppData\Local\Programs\Python\Python39\lib\site-packages\urllib3\util\connection.py", line 73, in create_connection
    for res in socket.getaddrinfo(host, port, family, socket.SOCK_STREAM):
  File "C:\Users\bonjour\AppData\Local\Programs\Python\Python39\lib\socket.py", line 953, in getaddrinfo
    for res in _socket.getaddrinfo(host, port, family, type, proto, flags):
socket.gaierror: [Errno 11001] getaddrinfo failed

During handling of the above exception, another exception occurred:

Traceback (most recent call last):
  File "C:\Users\bonjour\AppData\Local\Programs\Python\Python39\lib\site-packages\urllib3\connectionpool.py", line 699, in urlopen
    httplib_response = self._make_request(
  File "C:\Users\bonjour\AppData\Local\Programs\Python\Python39\lib\site-packages\urllib3\connectionpool.py", line 382, in _make_request
    self._validate_conn(conn)
  File "C:\Users\bonjour\AppData\Local\Programs\Python\Python39\lib\site-packages\urllib3\connectionpool.py", line 1010, in _validate_conn
    conn.connect()
  File "C:\Users\bonjour\AppData\Local\Programs\Python\Python39\lib\site-packages\urllib3\connection.py", line 353, in connect
    conn = self._new_conn()
  File "C:\Users\bonjour\AppData\Local\Programs\Python\Python39\lib\site-packages\urllib3\connection.py", line 181, in _new_conn
    raise NewConnectionError(
urllib3.exceptions.NewConnectionError: <urllib3.connection.HTTPSConnection object at 0x00000189B68234F0>: Failed to establish a new connection: [Errno 11001] getaddrinfo failed

During handling of the above exception, another exception occurred:

Traceback (most recent call last):
  File "C:\Users\bonjour\AppData\Local\Programs\Python\Python39\lib\site-packages\requests\adapters.py", line 439, in send
    resp = conn.urlopen(
  File "C:\Users\bonjour\AppData\Local\Programs\Python\Python39\lib\site-packages\urllib3\connectionpool.py", line 755, in urlopen
    retries = retries.increment(
  File "C:\Users\bonjour\AppData\Local\Programs\Python\Python39\lib\site-packages\urllib3\util\retry.py", line 574, in increment
    raise MaxRetryError(_pool, url, error or ResponseError(cause))
urllib3.exceptions.MaxRetryError: HTTPSConnectionPool(host='supplychain-server-stg.datousoft.jmj1995.com', port=443): Max retries exceeded with url: /items/1 (Caused by NewConnectionError('<urllib3.connection.HTTPSConnection object at 0x00000189B68234F0>: Failed to establish a new connection: [Errno 11001] getaddrinfo failed'))

During handling of the above exception, another exception occurred:

Traceback (most recent call last):
  File "..\Common\requestbase.py", line 72, in patch_Req
    res=requests.patch(url=url,data=data,headers=headers,json=json,params=params)
  File "C:\Users\bonjour\AppData\Local\Programs\Python\Python39\lib\site-packages\requests\api.py", line 149, in patch
    return request('patch', url, data=data, **kwargs)
  File "C:\Users\bonjour\AppData\Local\Programs\Python\Python39\lib\site-packages\requests\api.py", line 61, in request
    return session.request(method=method, url=url, **kwargs)
  File "C:\Users\bonjour\AppData\Local\Programs\Python\Python39\lib\site-packages\requests\sessions.py", line 542, in request
    resp = self.send(prep, **send_kwargs)
  File "C:\Users\bonjour\AppData\Local\Programs\Python\Python39\lib\site-packages\requests\sessions.py", line 655, in send
    r = adapter.send(request, **kwargs)
  File "C:\Users\bonjour\AppData\Local\Programs\Python\Python39\lib\site-packages\requests\adapters.py", line 516, in send
    raise ConnectionError(e, request=request)
requests.exceptions.ConnectionError: HTTPSConnectionPool(host='supplychain-server-stg.datousoft.jmj1995.com', port=443): Max retries exceeded with url: /items/1 (Caused by NewConnectionError('<urllib3.connection.HTTPSConnection object at 0x00000189B68234F0>: Failed to establish a new connection: [Errno 11001] getaddrinfo failed'))
2022-02-08 17:12:29,210 - INFO requestbase.py [line:69]: 连通接口"https://supplychain-server-stg.datousoft.jmj1995.com/shops/1",接口data为:"",接口json{'deliveryCenterId': 1, 'ownerCompanyId': 1}
2022-02-08 17:12:29,210 - INFO requestbase.py [line:69]: 连通接口"https://supplychain-server-stg.datousoft.jmj1995.com/shops/1",接口data为:"",接口json{'deliveryCenterId': 1, 'ownerCompanyId': 1}
2022-02-08 17:12:29,210 - INFO requestbase.py [line:69]: 连通接口"https://supplychain-server-stg.datousoft.jmj1995.com/shops/1",接口data为:"",接口json{'deliveryCenterId': 1, 'ownerCompanyId': 1}
2022-02-08 17:12:29,215 - ERROR requestbase.py [line:76]: 等待接口"https://supplychain-server-stg.datousoft.jmj1995.com/shops/1"失败
Traceback (most recent call last):
  File "C:\Users\bonjour\AppData\Local\Programs\Python\Python39\lib\site-packages\urllib3\connection.py", line 169, in _new_conn
    conn = connection.create_connection(
  File "C:\Users\bonjour\AppData\Local\Programs\Python\Python39\lib\site-packages\urllib3\util\connection.py", line 73, in create_connection
    for res in socket.getaddrinfo(host, port, family, socket.SOCK_STREAM):
  File "C:\Users\bonjour\AppData\Local\Programs\Python\Python39\lib\socket.py", line 953, in getaddrinfo
    for res in _socket.getaddrinfo(host, port, family, type, proto, flags):
socket.gaierror: [Errno 11001] getaddrinfo failed

During handling of the above exception, another exception occurred:

Traceback (most recent call last):
  File "C:\Users\bonjour\AppData\Local\Programs\Python\Python39\lib\site-packages\urllib3\connectionpool.py", line 699, in urlopen
    httplib_response = self._make_request(
  File "C:\Users\bonjour\AppData\Local\Programs\Python\Python39\lib\site-packages\urllib3\connectionpool.py", line 382, in _make_request
    self._validate_conn(conn)
  File "C:\Users\bonjour\AppData\Local\Programs\Python\Python39\lib\site-packages\urllib3\connectionpool.py", line 1010, in _validate_conn
    conn.connect()
  File "C:\Users\bonjour\AppData\Local\Programs\Python\Python39\lib\site-packages\urllib3\connection.py", line 353, in connect
    conn = self._new_conn()
  File "C:\Users\bonjour\AppData\Local\Programs\Python\Python39\lib\site-packages\urllib3\connection.py", line 181, in _new_conn
    raise NewConnectionError(
urllib3.exceptions.NewConnectionError: <urllib3.connection.HTTPSConnection object at 0x00000189B683D220>: Failed to establish a new connection: [Errno 11001] getaddrinfo failed

During handling of the above exception, another exception occurred:

Traceback (most recent call last):
  File "C:\Users\bonjour\AppData\Local\Programs\Python\Python39\lib\site-packages\requests\adapters.py", line 439, in send
    resp = conn.urlopen(
  File "C:\Users\bonjour\AppData\Local\Programs\Python\Python39\lib\site-packages\urllib3\connectionpool.py", line 755, in urlopen
    retries = retries.increment(
  File "C:\Users\bonjour\AppData\Local\Programs\Python\Python39\lib\site-packages\urllib3\util\retry.py", line 574, in increment
    raise MaxRetryError(_pool, url, error or ResponseError(cause))
urllib3.exceptions.MaxRetryError: HTTPSConnectionPool(host='supplychain-server-stg.datousoft.jmj1995.com', port=443): Max retries exceeded with url: /shops/1 (Caused by NewConnectionError('<urllib3.connection.HTTPSConnection object at 0x00000189B683D220>: Failed to establish a new connection: [Errno 11001] getaddrinfo failed'))

During handling of the above exception, another exception occurred:

Traceback (most recent call last):
  File "..\Common\requestbase.py", line 72, in patch_Req
    res=requests.patch(url=url,data=data,headers=headers,json=json,params=params)
  File "C:\Users\bonjour\AppData\Local\Programs\Python\Python39\lib\site-packages\requests\api.py", line 149, in patch
    return request('patch', url, data=data, **kwargs)
  File "C:\Users\bonjour\AppData\Local\Programs\Python\Python39\lib\site-packages\requests\api.py", line 61, in request
    return session.request(method=method, url=url, **kwargs)
  File "C:\Users\bonjour\AppData\Local\Programs\Python\Python39\lib\site-packages\requests\sessions.py", line 542, in request
    resp = self.send(prep, **send_kwargs)
  File "C:\Users\bonjour\AppData\Local\Programs\Python\Python39\lib\site-packages\requests\sessions.py", line 655, in send
    r = adapter.send(request, **kwargs)
  File "C:\Users\bonjour\AppData\Local\Programs\Python\Python39\lib\site-packages\requests\adapters.py", line 516, in send
    raise ConnectionError(e, request=request)
requests.exceptions.ConnectionError: HTTPSConnectionPool(host='supplychain-server-stg.datousoft.jmj1995.com', port=443): Max retries exceeded with url: /shops/1 (Caused by NewConnectionError('<urllib3.connection.HTTPSConnection object at 0x00000189B683D220>: Failed to establish a new connection: [Errno 11001] getaddrinfo failed'))
2022-02-08 17:12:29,215 - ERROR requestbase.py [line:76]: 等待接口"https://supplychain-server-stg.datousoft.jmj1995.com/shops/1"失败
Traceback (most recent call last):
  File "C:\Users\bonjour\AppData\Local\Programs\Python\Python39\lib\site-packages\urllib3\connection.py", line 169, in _new_conn
    conn = connection.create_connection(
  File "C:\Users\bonjour\AppData\Local\Programs\Python\Python39\lib\site-packages\urllib3\util\connection.py", line 73, in create_connection
    for res in socket.getaddrinfo(host, port, family, socket.SOCK_STREAM):
  File "C:\Users\bonjour\AppData\Local\Programs\Python\Python39\lib\socket.py", line 953, in getaddrinfo
    for res in _socket.getaddrinfo(host, port, family, type, proto, flags):
socket.gaierror: [Errno 11001] getaddrinfo failed

During handling of the above exception, another exception occurred:

Traceback (most recent call last):
  File "C:\Users\bonjour\AppData\Local\Programs\Python\Python39\lib\site-packages\urllib3\connectionpool.py", line 699, in urlopen
    httplib_response = self._make_request(
  File "C:\Users\bonjour\AppData\Local\Programs\Python\Python39\lib\site-packages\urllib3\connectionpool.py", line 382, in _make_request
    self._validate_conn(conn)
  File "C:\Users\bonjour\AppData\Local\Programs\Python\Python39\lib\site-packages\urllib3\connectionpool.py", line 1010, in _validate_conn
    conn.connect()
  File "C:\Users\bonjour\AppData\Local\Programs\Python\Python39\lib\site-packages\urllib3\connection.py", line 353, in connect
    conn = self._new_conn()
  File "C:\Users\bonjour\AppData\Local\Programs\Python\Python39\lib\site-packages\urllib3\connection.py", line 181, in _new_conn
    raise NewConnectionError(
urllib3.exceptions.NewConnectionError: <urllib3.connection.HTTPSConnection object at 0x00000189B683D220>: Failed to establish a new connection: [Errno 11001] getaddrinfo failed

During handling of the above exception, another exception occurred:

Traceback (most recent call last):
  File "C:\Users\bonjour\AppData\Local\Programs\Python\Python39\lib\site-packages\requests\adapters.py", line 439, in send
    resp = conn.urlopen(
  File "C:\Users\bonjour\AppData\Local\Programs\Python\Python39\lib\site-packages\urllib3\connectionpool.py", line 755, in urlopen
    retries = retries.increment(
  File "C:\Users\bonjour\AppData\Local\Programs\Python\Python39\lib\site-packages\urllib3\util\retry.py", line 574, in increment
    raise MaxRetryError(_pool, url, error or ResponseError(cause))
urllib3.exceptions.MaxRetryError: HTTPSConnectionPool(host='supplychain-server-stg.datousoft.jmj1995.com', port=443): Max retries exceeded with url: /shops/1 (Caused by NewConnectionError('<urllib3.connection.HTTPSConnection object at 0x00000189B683D220>: Failed to establish a new connection: [Errno 11001] getaddrinfo failed'))

During handling of the above exception, another exception occurred:

Traceback (most recent call last):
  File "..\Common\requestbase.py", line 72, in patch_Req
    res=requests.patch(url=url,data=data,headers=headers,json=json,params=params)
  File "C:\Users\bonjour\AppData\Local\Programs\Python\Python39\lib\site-packages\requests\api.py", line 149, in patch
    return request('patch', url, data=data, **kwargs)
  File "C:\Users\bonjour\AppData\Local\Programs\Python\Python39\lib\site-packages\requests\api.py", line 61, in request
    return session.request(method=method, url=url, **kwargs)
  File "C:\Users\bonjour\AppData\Local\Programs\Python\Python39\lib\site-packages\requests\sessions.py", line 542, in request
    resp = self.send(prep, **send_kwargs)
  File "C:\Users\bonjour\AppData\Local\Programs\Python\Python39\lib\site-packages\requests\sessions.py", line 655, in send
    r = adapter.send(request, **kwargs)
  File "C:\Users\bonjour\AppData\Local\Programs\Python\Python39\lib\site-packages\requests\adapters.py", line 516, in send
    raise ConnectionError(e, request=request)
requests.exceptions.ConnectionError: HTTPSConnectionPool(host='supplychain-server-stg.datousoft.jmj1995.com', port=443): Max retries exceeded with url: /shops/1 (Caused by NewConnectionError('<urllib3.connection.HTTPSConnection object at 0x00000189B683D220>: Failed to establish a new connection: [Errno 11001] getaddrinfo failed'))
2022-02-08 17:12:29,215 - ERROR requestbase.py [line:76]: 等待接口"https://supplychain-server-stg.datousoft.jmj1995.com/shops/1"失败
Traceback (most recent call last):
  File "C:\Users\bonjour\AppData\Local\Programs\Python\Python39\lib\site-packages\urllib3\connection.py", line 169, in _new_conn
    conn = connection.create_connection(
  File "C:\Users\bonjour\AppData\Local\Programs\Python\Python39\lib\site-packages\urllib3\util\connection.py", line 73, in create_connection
    for res in socket.getaddrinfo(host, port, family, socket.SOCK_STREAM):
  File "C:\Users\bonjour\AppData\Local\Programs\Python\Python39\lib\socket.py", line 953, in getaddrinfo
    for res in _socket.getaddrinfo(host, port, family, type, proto, flags):
socket.gaierror: [Errno 11001] getaddrinfo failed

During handling of the above exception, another exception occurred:

Traceback (most recent call last):
  File "C:\Users\bonjour\AppData\Local\Programs\Python\Python39\lib\site-packages\urllib3\connectionpool.py", line 699, in urlopen
    httplib_response = self._make_request(
  File "C:\Users\bonjour\AppData\Local\Programs\Python\Python39\lib\site-packages\urllib3\connectionpool.py", line 382, in _make_request
    self._validate_conn(conn)
  File "C:\Users\bonjour\AppData\Local\Programs\Python\Python39\lib\site-packages\urllib3\connectionpool.py", line 1010, in _validate_conn
    conn.connect()
  File "C:\Users\bonjour\AppData\Local\Programs\Python\Python39\lib\site-packages\urllib3\connection.py", line 353, in connect
    conn = self._new_conn()
  File "C:\Users\bonjour\AppData\Local\Programs\Python\Python39\lib\site-packages\urllib3\connection.py", line 181, in _new_conn
    raise NewConnectionError(
urllib3.exceptions.NewConnectionError: <urllib3.connection.HTTPSConnection object at 0x00000189B683D220>: Failed to establish a new connection: [Errno 11001] getaddrinfo failed

During handling of the above exception, another exception occurred:

Traceback (most recent call last):
  File "C:\Users\bonjour\AppData\Local\Programs\Python\Python39\lib\site-packages\requests\adapters.py", line 439, in send
    resp = conn.urlopen(
  File "C:\Users\bonjour\AppData\Local\Programs\Python\Python39\lib\site-packages\urllib3\connectionpool.py", line 755, in urlopen
    retries = retries.increment(
  File "C:\Users\bonjour\AppData\Local\Programs\Python\Python39\lib\site-packages\urllib3\util\retry.py", line 574, in increment
    raise MaxRetryError(_pool, url, error or ResponseError(cause))
urllib3.exceptions.MaxRetryError: HTTPSConnectionPool(host='supplychain-server-stg.datousoft.jmj1995.com', port=443): Max retries exceeded with url: /shops/1 (Caused by NewConnectionError('<urllib3.connection.HTTPSConnection object at 0x00000189B683D220>: Failed to establish a new connection: [Errno 11001] getaddrinfo failed'))

During handling of the above exception, another exception occurred:

Traceback (most recent call last):
  File "..\Common\requestbase.py", line 72, in patch_Req
    res=requests.patch(url=url,data=data,headers=headers,json=json,params=params)
  File "C:\Users\bonjour\AppData\Local\Programs\Python\Python39\lib\site-packages\requests\api.py", line 149, in patch
    return request('patch', url, data=data, **kwargs)
  File "C:\Users\bonjour\AppData\Local\Programs\Python\Python39\lib\site-packages\requests\api.py", line 61, in request
    return session.request(method=method, url=url, **kwargs)
  File "C:\Users\bonjour\AppData\Local\Programs\Python\Python39\lib\site-packages\requests\sessions.py", line 542, in request
    resp = self.send(prep, **send_kwargs)
  File "C:\Users\bonjour\AppData\Local\Programs\Python\Python39\lib\site-packages\requests\sessions.py", line 655, in send
    r = adapter.send(request, **kwargs)
  File "C:\Users\bonjour\AppData\Local\Programs\Python\Python39\lib\site-packages\requests\adapters.py", line 516, in send
    raise ConnectionError(e, request=request)
requests.exceptions.ConnectionError: HTTPSConnectionPool(host='supplychain-server-stg.datousoft.jmj1995.com', port=443): Max retries exceeded with url: /shops/1 (Caused by NewConnectionError('<urllib3.connection.HTTPSConnection object at 0x00000189B683D220>: Failed to establish a new connection: [Errno 11001] getaddrinfo failed'))
2022-02-08 17:12:29,235 - INFO requestbase.py [line:21]: 连通接口"https://supplychain-server-stg.datousoft.jmj1995.com/suppliers/1",接口header为:"{'authorization': 'Bearer eyJhbGciOiJIUzUxMiJ9.eyJqdGkiOiI3MTk0NWY1OGYzYTQ0OWY3OWVmYzM4MTdjZDdiYjBlNyIsImF1dGgiOiIiLCJpZCI6NTk5LCJzdWIiOiIxMiJ9.s9x_iYROhFujmW09Bu5HFfhwqp8_8WaC08vyveK_S0SUolxbVY7tnWy17BW6XmROb-gHFxSWfiH3gpurKcNsWg'}",接口param为：
2022-02-08 17:12:29,235 - INFO requestbase.py [line:21]: 连通接口"https://supplychain-server-stg.datousoft.jmj1995.com/suppliers/1",接口header为:"{'authorization': 'Bearer eyJhbGciOiJIUzUxMiJ9.eyJqdGkiOiI3MTk0NWY1OGYzYTQ0OWY3OWVmYzM4MTdjZDdiYjBlNyIsImF1dGgiOiIiLCJpZCI6NTk5LCJzdWIiOiIxMiJ9.s9x_iYROhFujmW09Bu5HFfhwqp8_8WaC08vyveK_S0SUolxbVY7tnWy17BW6XmROb-gHFxSWfiH3gpurKcNsWg'}",接口param为：
2022-02-08 17:12:29,235 - INFO requestbase.py [line:21]: 连通接口"https://supplychain-server-stg.datousoft.jmj1995.com/suppliers/1",接口header为:"{'authorization': 'Bearer eyJhbGciOiJIUzUxMiJ9.eyJqdGkiOiI3MTk0NWY1OGYzYTQ0OWY3OWVmYzM4MTdjZDdiYjBlNyIsImF1dGgiOiIiLCJpZCI6NTk5LCJzdWIiOiIxMiJ9.s9x_iYROhFujmW09Bu5HFfhwqp8_8WaC08vyveK_S0SUolxbVY7tnWy17BW6XmROb-gHFxSWfiH3gpurKcNsWg'}",接口param为：
2022-02-08 17:12:29,235 - INFO requestbase.py [line:21]: 连通接口"https://supplychain-server-stg.datousoft.jmj1995.com/suppliers/1",接口header为:"{'authorization': 'Bearer eyJhbGciOiJIUzUxMiJ9.eyJqdGkiOiI3MTk0NWY1OGYzYTQ0OWY3OWVmYzM4MTdjZDdiYjBlNyIsImF1dGgiOiIiLCJpZCI6NTk5LCJzdWIiOiIxMiJ9.s9x_iYROhFujmW09Bu5HFfhwqp8_8WaC08vyveK_S0SUolxbVY7tnWy17BW6XmROb-gHFxSWfiH3gpurKcNsWg'}",接口param为：
2022-02-08 17:12:29,242 - ERROR requestbase.py [line:28]: 等待接口"https://supplychain-server-stg.datousoft.jmj1995.com/suppliers/1"失败
Traceback (most recent call last):
  File "C:\Users\bonjour\AppData\Local\Programs\Python\Python39\lib\site-packages\urllib3\connection.py", line 169, in _new_conn
    conn = connection.create_connection(
  File "C:\Users\bonjour\AppData\Local\Programs\Python\Python39\lib\site-packages\urllib3\util\connection.py", line 73, in create_connection
    for res in socket.getaddrinfo(host, port, family, socket.SOCK_STREAM):
  File "C:\Users\bonjour\AppData\Local\Programs\Python\Python39\lib\socket.py", line 953, in getaddrinfo
    for res in _socket.getaddrinfo(host, port, family, type, proto, flags):
socket.gaierror: [Errno 11001] getaddrinfo failed

During handling of the above exception, another exception occurred:

Traceback (most recent call last):
  File "C:\Users\bonjour\AppData\Local\Programs\Python\Python39\lib\site-packages\urllib3\connectionpool.py", line 699, in urlopen
    httplib_response = self._make_request(
  File "C:\Users\bonjour\AppData\Local\Programs\Python\Python39\lib\site-packages\urllib3\connectionpool.py", line 382, in _make_request
    self._validate_conn(conn)
  File "C:\Users\bonjour\AppData\Local\Programs\Python\Python39\lib\site-packages\urllib3\connectionpool.py", line 1010, in _validate_conn
    conn.connect()
  File "C:\Users\bonjour\AppData\Local\Programs\Python\Python39\lib\site-packages\urllib3\connection.py", line 353, in connect
    conn = self._new_conn()
  File "C:\Users\bonjour\AppData\Local\Programs\Python\Python39\lib\site-packages\urllib3\connection.py", line 181, in _new_conn
    raise NewConnectionError(
urllib3.exceptions.NewConnectionError: <urllib3.connection.HTTPSConnection object at 0x00000189B68264C0>: Failed to establish a new connection: [Errno 11001] getaddrinfo failed

During handling of the above exception, another exception occurred:

Traceback (most recent call last):
  File "C:\Users\bonjour\AppData\Local\Programs\Python\Python39\lib\site-packages\requests\adapters.py", line 439, in send
    resp = conn.urlopen(
  File "C:\Users\bonjour\AppData\Local\Programs\Python\Python39\lib\site-packages\urllib3\connectionpool.py", line 755, in urlopen
    retries = retries.increment(
  File "C:\Users\bonjour\AppData\Local\Programs\Python\Python39\lib\site-packages\urllib3\util\retry.py", line 574, in increment
    raise MaxRetryError(_pool, url, error or ResponseError(cause))
urllib3.exceptions.MaxRetryError: HTTPSConnectionPool(host='supplychain-server-stg.datousoft.jmj1995.com', port=443): Max retries exceeded with url: /suppliers/1 (Caused by NewConnectionError('<urllib3.connection.HTTPSConnection object at 0x00000189B68264C0>: Failed to establish a new connection: [Errno 11001] getaddrinfo failed'))

During handling of the above exception, another exception occurred:

Traceback (most recent call last):
  File "..\Common\requestbase.py", line 24, in get_Req
    res=requests.get(url=url,headers=headers,params=params,data=data,json=json)
  File "C:\Users\bonjour\AppData\Local\Programs\Python\Python39\lib\site-packages\requests\api.py", line 76, in get
    return request('get', url, params=params, **kwargs)
  File "C:\Users\bonjour\AppData\Local\Programs\Python\Python39\lib\site-packages\requests\api.py", line 61, in request
    return session.request(method=method, url=url, **kwargs)
  File "C:\Users\bonjour\AppData\Local\Programs\Python\Python39\lib\site-packages\requests\sessions.py", line 542, in request
    resp = self.send(prep, **send_kwargs)
  File "C:\Users\bonjour\AppData\Local\Programs\Python\Python39\lib\site-packages\requests\sessions.py", line 655, in send
    r = adapter.send(request, **kwargs)
  File "C:\Users\bonjour\AppData\Local\Programs\Python\Python39\lib\site-packages\requests\adapters.py", line 516, in send
    raise ConnectionError(e, request=request)
requests.exceptions.ConnectionError: HTTPSConnectionPool(host='supplychain-server-stg.datousoft.jmj1995.com', port=443): Max retries exceeded with url: /suppliers/1 (Caused by NewConnectionError('<urllib3.connection.HTTPSConnection object at 0x00000189B68264C0>: Failed to establish a new connection: [Errno 11001] getaddrinfo failed'))
2022-02-08 17:12:29,242 - ERROR requestbase.py [line:28]: 等待接口"https://supplychain-server-stg.datousoft.jmj1995.com/suppliers/1"失败
Traceback (most recent call last):
  File "C:\Users\bonjour\AppData\Local\Programs\Python\Python39\lib\site-packages\urllib3\connection.py", line 169, in _new_conn
    conn = connection.create_connection(
  File "C:\Users\bonjour\AppData\Local\Programs\Python\Python39\lib\site-packages\urllib3\util\connection.py", line 73, in create_connection
    for res in socket.getaddrinfo(host, port, family, socket.SOCK_STREAM):
  File "C:\Users\bonjour\AppData\Local\Programs\Python\Python39\lib\socket.py", line 953, in getaddrinfo
    for res in _socket.getaddrinfo(host, port, family, type, proto, flags):
socket.gaierror: [Errno 11001] getaddrinfo failed

During handling of the above exception, another exception occurred:

Traceback (most recent call last):
  File "C:\Users\bonjour\AppData\Local\Programs\Python\Python39\lib\site-packages\urllib3\connectionpool.py", line 699, in urlopen
    httplib_response = self._make_request(
  File "C:\Users\bonjour\AppData\Local\Programs\Python\Python39\lib\site-packages\urllib3\connectionpool.py", line 382, in _make_request
    self._validate_conn(conn)
  File "C:\Users\bonjour\AppData\Local\Programs\Python\Python39\lib\site-packages\urllib3\connectionpool.py", line 1010, in _validate_conn
    conn.connect()
  File "C:\Users\bonjour\AppData\Local\Programs\Python\Python39\lib\site-packages\urllib3\connection.py", line 353, in connect
    conn = self._new_conn()
  File "C:\Users\bonjour\AppData\Local\Programs\Python\Python39\lib\site-packages\urllib3\connection.py", line 181, in _new_conn
    raise NewConnectionError(
urllib3.exceptions.NewConnectionError: <urllib3.connection.HTTPSConnection object at 0x00000189B68264C0>: Failed to establish a new connection: [Errno 11001] getaddrinfo failed

During handling of the above exception, another exception occurred:

Traceback (most recent call last):
  File "C:\Users\bonjour\AppData\Local\Programs\Python\Python39\lib\site-packages\requests\adapters.py", line 439, in send
    resp = conn.urlopen(
  File "C:\Users\bonjour\AppData\Local\Programs\Python\Python39\lib\site-packages\urllib3\connectionpool.py", line 755, in urlopen
    retries = retries.increment(
  File "C:\Users\bonjour\AppData\Local\Programs\Python\Python39\lib\site-packages\urllib3\util\retry.py", line 574, in increment
    raise MaxRetryError(_pool, url, error or ResponseError(cause))
urllib3.exceptions.MaxRetryError: HTTPSConnectionPool(host='supplychain-server-stg.datousoft.jmj1995.com', port=443): Max retries exceeded with url: /suppliers/1 (Caused by NewConnectionError('<urllib3.connection.HTTPSConnection object at 0x00000189B68264C0>: Failed to establish a new connection: [Errno 11001] getaddrinfo failed'))

During handling of the above exception, another exception occurred:

Traceback (most recent call last):
  File "..\Common\requestbase.py", line 24, in get_Req
    res=requests.get(url=url,headers=headers,params=params,data=data,json=json)
  File "C:\Users\bonjour\AppData\Local\Programs\Python\Python39\lib\site-packages\requests\api.py", line 76, in get
    return request('get', url, params=params, **kwargs)
  File "C:\Users\bonjour\AppData\Local\Programs\Python\Python39\lib\site-packages\requests\api.py", line 61, in request
    return session.request(method=method, url=url, **kwargs)
  File "C:\Users\bonjour\AppData\Local\Programs\Python\Python39\lib\site-packages\requests\sessions.py", line 542, in request
    resp = self.send(prep, **send_kwargs)
  File "C:\Users\bonjour\AppData\Local\Programs\Python\Python39\lib\site-packages\requests\sessions.py", line 655, in send
    r = adapter.send(request, **kwargs)
  File "C:\Users\bonjour\AppData\Local\Programs\Python\Python39\lib\site-packages\requests\adapters.py", line 516, in send
    raise ConnectionError(e, request=request)
requests.exceptions.ConnectionError: HTTPSConnectionPool(host='supplychain-server-stg.datousoft.jmj1995.com', port=443): Max retries exceeded with url: /suppliers/1 (Caused by NewConnectionError('<urllib3.connection.HTTPSConnection object at 0x00000189B68264C0>: Failed to establish a new connection: [Errno 11001] getaddrinfo failed'))
2022-02-08 17:12:29,242 - ERROR requestbase.py [line:28]: 等待接口"https://supplychain-server-stg.datousoft.jmj1995.com/suppliers/1"失败
Traceback (most recent call last):
  File "C:\Users\bonjour\AppData\Local\Programs\Python\Python39\lib\site-packages\urllib3\connection.py", line 169, in _new_conn
    conn = connection.create_connection(
  File "C:\Users\bonjour\AppData\Local\Programs\Python\Python39\lib\site-packages\urllib3\util\connection.py", line 73, in create_connection
    for res in socket.getaddrinfo(host, port, family, socket.SOCK_STREAM):
  File "C:\Users\bonjour\AppData\Local\Programs\Python\Python39\lib\socket.py", line 953, in getaddrinfo
    for res in _socket.getaddrinfo(host, port, family, type, proto, flags):
socket.gaierror: [Errno 11001] getaddrinfo failed

During handling of the above exception, another exception occurred:

Traceback (most recent call last):
  File "C:\Users\bonjour\AppData\Local\Programs\Python\Python39\lib\site-packages\urllib3\connectionpool.py", line 699, in urlopen
    httplib_response = self._make_request(
  File "C:\Users\bonjour\AppData\Local\Programs\Python\Python39\lib\site-packages\urllib3\connectionpool.py", line 382, in _make_request
    self._validate_conn(conn)
  File "C:\Users\bonjour\AppData\Local\Programs\Python\Python39\lib\site-packages\urllib3\connectionpool.py", line 1010, in _validate_conn
    conn.connect()
  File "C:\Users\bonjour\AppData\Local\Programs\Python\Python39\lib\site-packages\urllib3\connection.py", line 353, in connect
    conn = self._new_conn()
  File "C:\Users\bonjour\AppData\Local\Programs\Python\Python39\lib\site-packages\urllib3\connection.py", line 181, in _new_conn
    raise NewConnectionError(
urllib3.exceptions.NewConnectionError: <urllib3.connection.HTTPSConnection object at 0x00000189B68264C0>: Failed to establish a new connection: [Errno 11001] getaddrinfo failed

During handling of the above exception, another exception occurred:

Traceback (most recent call last):
  File "C:\Users\bonjour\AppData\Local\Programs\Python\Python39\lib\site-packages\requests\adapters.py", line 439, in send
    resp = conn.urlopen(
  File "C:\Users\bonjour\AppData\Local\Programs\Python\Python39\lib\site-packages\urllib3\connectionpool.py", line 755, in urlopen
    retries = retries.increment(
  File "C:\Users\bonjour\AppData\Local\Programs\Python\Python39\lib\site-packages\urllib3\util\retry.py", line 574, in increment
    raise MaxRetryError(_pool, url, error or ResponseError(cause))
urllib3.exceptions.MaxRetryError: HTTPSConnectionPool(host='supplychain-server-stg.datousoft.jmj1995.com', port=443): Max retries exceeded with url: /suppliers/1 (Caused by NewConnectionError('<urllib3.connection.HTTPSConnection object at 0x00000189B68264C0>: Failed to establish a new connection: [Errno 11001] getaddrinfo failed'))

During handling of the above exception, another exception occurred:

Traceback (most recent call last):
  File "..\Common\requestbase.py", line 24, in get_Req
    res=requests.get(url=url,headers=headers,params=params,data=data,json=json)
  File "C:\Users\bonjour\AppData\Local\Programs\Python\Python39\lib\site-packages\requests\api.py", line 76, in get
    return request('get', url, params=params, **kwargs)
  File "C:\Users\bonjour\AppData\Local\Programs\Python\Python39\lib\site-packages\requests\api.py", line 61, in request
    return session.request(method=method, url=url, **kwargs)
  File "C:\Users\bonjour\AppData\Local\Programs\Python\Python39\lib\site-packages\requests\sessions.py", line 542, in request
    resp = self.send(prep, **send_kwargs)
  File "C:\Users\bonjour\AppData\Local\Programs\Python\Python39\lib\site-packages\requests\sessions.py", line 655, in send
    r = adapter.send(request, **kwargs)
  File "C:\Users\bonjour\AppData\Local\Programs\Python\Python39\lib\site-packages\requests\adapters.py", line 516, in send
    raise ConnectionError(e, request=request)
requests.exceptions.ConnectionError: HTTPSConnectionPool(host='supplychain-server-stg.datousoft.jmj1995.com', port=443): Max retries exceeded with url: /suppliers/1 (Caused by NewConnectionError('<urllib3.connection.HTTPSConnection object at 0x00000189B68264C0>: Failed to establish a new connection: [Errno 11001] getaddrinfo failed'))
2022-02-08 17:12:29,242 - ERROR requestbase.py [line:28]: 等待接口"https://supplychain-server-stg.datousoft.jmj1995.com/suppliers/1"失败
Traceback (most recent call last):
  File "C:\Users\bonjour\AppData\Local\Programs\Python\Python39\lib\site-packages\urllib3\connection.py", line 169, in _new_conn
    conn = connection.create_connection(
  File "C:\Users\bonjour\AppData\Local\Programs\Python\Python39\lib\site-packages\urllib3\util\connection.py", line 73, in create_connection
    for res in socket.getaddrinfo(host, port, family, socket.SOCK_STREAM):
  File "C:\Users\bonjour\AppData\Local\Programs\Python\Python39\lib\socket.py", line 953, in getaddrinfo
    for res in _socket.getaddrinfo(host, port, family, type, proto, flags):
socket.gaierror: [Errno 11001] getaddrinfo failed

During handling of the above exception, another exception occurred:

Traceback (most recent call last):
  File "C:\Users\bonjour\AppData\Local\Programs\Python\Python39\lib\site-packages\urllib3\connectionpool.py", line 699, in urlopen
    httplib_response = self._make_request(
  File "C:\Users\bonjour\AppData\Local\Programs\Python\Python39\lib\site-packages\urllib3\connectionpool.py", line 382, in _make_request
    self._validate_conn(conn)
  File "C:\Users\bonjour\AppData\Local\Programs\Python\Python39\lib\site-packages\urllib3\connectionpool.py", line 1010, in _validate_conn
    conn.connect()
  File "C:\Users\bonjour\AppData\Local\Programs\Python\Python39\lib\site-packages\urllib3\connection.py", line 353, in connect
    conn = self._new_conn()
  File "C:\Users\bonjour\AppData\Local\Programs\Python\Python39\lib\site-packages\urllib3\connection.py", line 181, in _new_conn
    raise NewConnectionError(
urllib3.exceptions.NewConnectionError: <urllib3.connection.HTTPSConnection object at 0x00000189B68264C0>: Failed to establish a new connection: [Errno 11001] getaddrinfo failed

During handling of the above exception, another exception occurred:

Traceback (most recent call last):
  File "C:\Users\bonjour\AppData\Local\Programs\Python\Python39\lib\site-packages\requests\adapters.py", line 439, in send
    resp = conn.urlopen(
  File "C:\Users\bonjour\AppData\Local\Programs\Python\Python39\lib\site-packages\urllib3\connectionpool.py", line 755, in urlopen
    retries = retries.increment(
  File "C:\Users\bonjour\AppData\Local\Programs\Python\Python39\lib\site-packages\urllib3\util\retry.py", line 574, in increment
    raise MaxRetryError(_pool, url, error or ResponseError(cause))
urllib3.exceptions.MaxRetryError: HTTPSConnectionPool(host='supplychain-server-stg.datousoft.jmj1995.com', port=443): Max retries exceeded with url: /suppliers/1 (Caused by NewConnectionError('<urllib3.connection.HTTPSConnection object at 0x00000189B68264C0>: Failed to establish a new connection: [Errno 11001] getaddrinfo failed'))

During handling of the above exception, another exception occurred:

Traceback (most recent call last):
  File "..\Common\requestbase.py", line 24, in get_Req
    res=requests.get(url=url,headers=headers,params=params,data=data,json=json)
  File "C:\Users\bonjour\AppData\Local\Programs\Python\Python39\lib\site-packages\requests\api.py", line 76, in get
    return request('get', url, params=params, **kwargs)
  File "C:\Users\bonjour\AppData\Local\Programs\Python\Python39\lib\site-packages\requests\api.py", line 61, in request
    return session.request(method=method, url=url, **kwargs)
  File "C:\Users\bonjour\AppData\Local\Programs\Python\Python39\lib\site-packages\requests\sessions.py", line 542, in request
    resp = self.send(prep, **send_kwargs)
  File "C:\Users\bonjour\AppData\Local\Programs\Python\Python39\lib\site-packages\requests\sessions.py", line 655, in send
    r = adapter.send(request, **kwargs)
  File "C:\Users\bonjour\AppData\Local\Programs\Python\Python39\lib\site-packages\requests\adapters.py", line 516, in send
    raise ConnectionError(e, request=request)
requests.exceptions.ConnectionError: HTTPSConnectionPool(host='supplychain-server-stg.datousoft.jmj1995.com', port=443): Max retries exceeded with url: /suppliers/1 (Caused by NewConnectionError('<urllib3.connection.HTTPSConnection object at 0x00000189B68264C0>: Failed to establish a new connection: [Errno 11001] getaddrinfo failed'))
2022-02-08 17:12:29,259 - INFO requestbase.py [line:69]: 连通接口"https://supplychain-server-stg.datousoft.jmj1995.com/suppliers/1",接口data为:"",接口json{'enable': 'false'}
2022-02-08 17:12:29,259 - INFO requestbase.py [line:69]: 连通接口"https://supplychain-server-stg.datousoft.jmj1995.com/suppliers/1",接口data为:"",接口json{'enable': 'false'}
2022-02-08 17:12:29,259 - INFO requestbase.py [line:69]: 连通接口"https://supplychain-server-stg.datousoft.jmj1995.com/suppliers/1",接口data为:"",接口json{'enable': 'false'}
2022-02-08 17:12:29,259 - INFO requestbase.py [line:69]: 连通接口"https://supplychain-server-stg.datousoft.jmj1995.com/suppliers/1",接口data为:"",接口json{'enable': 'false'}
2022-02-08 17:12:29,259 - INFO requestbase.py [line:69]: 连通接口"https://supplychain-server-stg.datousoft.jmj1995.com/suppliers/1",接口data为:"",接口json{'enable': 'false'}
2022-02-08 17:12:29,264 - ERROR requestbase.py [line:76]: 等待接口"https://supplychain-server-stg.datousoft.jmj1995.com/suppliers/1"失败
Traceback (most recent call last):
  File "C:\Users\bonjour\AppData\Local\Programs\Python\Python39\lib\site-packages\urllib3\connection.py", line 169, in _new_conn
    conn = connection.create_connection(
  File "C:\Users\bonjour\AppData\Local\Programs\Python\Python39\lib\site-packages\urllib3\util\connection.py", line 73, in create_connection
    for res in socket.getaddrinfo(host, port, family, socket.SOCK_STREAM):
  File "C:\Users\bonjour\AppData\Local\Programs\Python\Python39\lib\socket.py", line 953, in getaddrinfo
    for res in _socket.getaddrinfo(host, port, family, type, proto, flags):
socket.gaierror: [Errno 11001] getaddrinfo failed

During handling of the above exception, another exception occurred:

Traceback (most recent call last):
  File "C:\Users\bonjour\AppData\Local\Programs\Python\Python39\lib\site-packages\urllib3\connectionpool.py", line 699, in urlopen
    httplib_response = self._make_request(
  File "C:\Users\bonjour\AppData\Local\Programs\Python\Python39\lib\site-packages\urllib3\connectionpool.py", line 382, in _make_request
    self._validate_conn(conn)
  File "C:\Users\bonjour\AppData\Local\Programs\Python\Python39\lib\site-packages\urllib3\connectionpool.py", line 1010, in _validate_conn
    conn.connect()
  File "C:\Users\bonjour\AppData\Local\Programs\Python\Python39\lib\site-packages\urllib3\connection.py", line 353, in connect
    conn = self._new_conn()
  File "C:\Users\bonjour\AppData\Local\Programs\Python\Python39\lib\site-packages\urllib3\connection.py", line 181, in _new_conn
    raise NewConnectionError(
urllib3.exceptions.NewConnectionError: <urllib3.connection.HTTPSConnection object at 0x00000189B665CF70>: Failed to establish a new connection: [Errno 11001] getaddrinfo failed

During handling of the above exception, another exception occurred:

Traceback (most recent call last):
  File "C:\Users\bonjour\AppData\Local\Programs\Python\Python39\lib\site-packages\requests\adapters.py", line 439, in send
    resp = conn.urlopen(
  File "C:\Users\bonjour\AppData\Local\Programs\Python\Python39\lib\site-packages\urllib3\connectionpool.py", line 755, in urlopen
    retries = retries.increment(
  File "C:\Users\bonjour\AppData\Local\Programs\Python\Python39\lib\site-packages\urllib3\util\retry.py", line 574, in increment
    raise MaxRetryError(_pool, url, error or ResponseError(cause))
urllib3.exceptions.MaxRetryError: HTTPSConnectionPool(host='supplychain-server-stg.datousoft.jmj1995.com', port=443): Max retries exceeded with url: /suppliers/1 (Caused by NewConnectionError('<urllib3.connection.HTTPSConnection object at 0x00000189B665CF70>: Failed to establish a new connection: [Errno 11001] getaddrinfo failed'))

During handling of the above exception, another exception occurred:

Traceback (most recent call last):
  File "..\Common\requestbase.py", line 72, in patch_Req
    res=requests.patch(url=url,data=data,headers=headers,json=json,params=params)
  File "C:\Users\bonjour\AppData\Local\Programs\Python\Python39\lib\site-packages\requests\api.py", line 149, in patch
    return request('patch', url, data=data, **kwargs)
  File "C:\Users\bonjour\AppData\Local\Programs\Python\Python39\lib\site-packages\requests\api.py", line 61, in request
    return session.request(method=method, url=url, **kwargs)
  File "C:\Users\bonjour\AppData\Local\Programs\Python\Python39\lib\site-packages\requests\sessions.py", line 542, in request
    resp = self.send(prep, **send_kwargs)
  File "C:\Users\bonjour\AppData\Local\Programs\Python\Python39\lib\site-packages\requests\sessions.py", line 655, in send
    r = adapter.send(request, **kwargs)
  File "C:\Users\bonjour\AppData\Local\Programs\Python\Python39\lib\site-packages\requests\adapters.py", line 516, in send
    raise ConnectionError(e, request=request)
requests.exceptions.ConnectionError: HTTPSConnectionPool(host='supplychain-server-stg.datousoft.jmj1995.com', port=443): Max retries exceeded with url: /suppliers/1 (Caused by NewConnectionError('<urllib3.connection.HTTPSConnection object at 0x00000189B665CF70>: Failed to establish a new connection: [Errno 11001] getaddrinfo failed'))
2022-02-08 17:12:29,264 - ERROR requestbase.py [line:76]: 等待接口"https://supplychain-server-stg.datousoft.jmj1995.com/suppliers/1"失败
Traceback (most recent call last):
  File "C:\Users\bonjour\AppData\Local\Programs\Python\Python39\lib\site-packages\urllib3\connection.py", line 169, in _new_conn
    conn = connection.create_connection(
  File "C:\Users\bonjour\AppData\Local\Programs\Python\Python39\lib\site-packages\urllib3\util\connection.py", line 73, in create_connection
    for res in socket.getaddrinfo(host, port, family, socket.SOCK_STREAM):
  File "C:\Users\bonjour\AppData\Local\Programs\Python\Python39\lib\socket.py", line 953, in getaddrinfo
    for res in _socket.getaddrinfo(host, port, family, type, proto, flags):
socket.gaierror: [Errno 11001] getaddrinfo failed

During handling of the above exception, another exception occurred:

Traceback (most recent call last):
  File "C:\Users\bonjour\AppData\Local\Programs\Python\Python39\lib\site-packages\urllib3\connectionpool.py", line 699, in urlopen
    httplib_response = self._make_request(
  File "C:\Users\bonjour\AppData\Local\Programs\Python\Python39\lib\site-packages\urllib3\connectionpool.py", line 382, in _make_request
    self._validate_conn(conn)
  File "C:\Users\bonjour\AppData\Local\Programs\Python\Python39\lib\site-packages\urllib3\connectionpool.py", line 1010, in _validate_conn
    conn.connect()
  File "C:\Users\bonjour\AppData\Local\Programs\Python\Python39\lib\site-packages\urllib3\connection.py", line 353, in connect
    conn = self._new_conn()
  File "C:\Users\bonjour\AppData\Local\Programs\Python\Python39\lib\site-packages\urllib3\connection.py", line 181, in _new_conn
    raise NewConnectionError(
urllib3.exceptions.NewConnectionError: <urllib3.connection.HTTPSConnection object at 0x00000189B665CF70>: Failed to establish a new connection: [Errno 11001] getaddrinfo failed

During handling of the above exception, another exception occurred:

Traceback (most recent call last):
  File "C:\Users\bonjour\AppData\Local\Programs\Python\Python39\lib\site-packages\requests\adapters.py", line 439, in send
    resp = conn.urlopen(
  File "C:\Users\bonjour\AppData\Local\Programs\Python\Python39\lib\site-packages\urllib3\connectionpool.py", line 755, in urlopen
    retries = retries.increment(
  File "C:\Users\bonjour\AppData\Local\Programs\Python\Python39\lib\site-packages\urllib3\util\retry.py", line 574, in increment
    raise MaxRetryError(_pool, url, error or ResponseError(cause))
urllib3.exceptions.MaxRetryError: HTTPSConnectionPool(host='supplychain-server-stg.datousoft.jmj1995.com', port=443): Max retries exceeded with url: /suppliers/1 (Caused by NewConnectionError('<urllib3.connection.HTTPSConnection object at 0x00000189B665CF70>: Failed to establish a new connection: [Errno 11001] getaddrinfo failed'))

During handling of the above exception, another exception occurred:

Traceback (most recent call last):
  File "..\Common\requestbase.py", line 72, in patch_Req
    res=requests.patch(url=url,data=data,headers=headers,json=json,params=params)
  File "C:\Users\bonjour\AppData\Local\Programs\Python\Python39\lib\site-packages\requests\api.py", line 149, in patch
    return request('patch', url, data=data, **kwargs)
  File "C:\Users\bonjour\AppData\Local\Programs\Python\Python39\lib\site-packages\requests\api.py", line 61, in request
    return session.request(method=method, url=url, **kwargs)
  File "C:\Users\bonjour\AppData\Local\Programs\Python\Python39\lib\site-packages\requests\sessions.py", line 542, in request
    resp = self.send(prep, **send_kwargs)
  File "C:\Users\bonjour\AppData\Local\Programs\Python\Python39\lib\site-packages\requests\sessions.py", line 655, in send
    r = adapter.send(request, **kwargs)
  File "C:\Users\bonjour\AppData\Local\Programs\Python\Python39\lib\site-packages\requests\adapters.py", line 516, in send
    raise ConnectionError(e, request=request)
requests.exceptions.ConnectionError: HTTPSConnectionPool(host='supplychain-server-stg.datousoft.jmj1995.com', port=443): Max retries exceeded with url: /suppliers/1 (Caused by NewConnectionError('<urllib3.connection.HTTPSConnection object at 0x00000189B665CF70>: Failed to establish a new connection: [Errno 11001] getaddrinfo failed'))
2022-02-08 17:12:29,264 - ERROR requestbase.py [line:76]: 等待接口"https://supplychain-server-stg.datousoft.jmj1995.com/suppliers/1"失败
Traceback (most recent call last):
  File "C:\Users\bonjour\AppData\Local\Programs\Python\Python39\lib\site-packages\urllib3\connection.py", line 169, in _new_conn
    conn = connection.create_connection(
  File "C:\Users\bonjour\AppData\Local\Programs\Python\Python39\lib\site-packages\urllib3\util\connection.py", line 73, in create_connection
    for res in socket.getaddrinfo(host, port, family, socket.SOCK_STREAM):
  File "C:\Users\bonjour\AppData\Local\Programs\Python\Python39\lib\socket.py", line 953, in getaddrinfo
    for res in _socket.getaddrinfo(host, port, family, type, proto, flags):
socket.gaierror: [Errno 11001] getaddrinfo failed

During handling of the above exception, another exception occurred:

Traceback (most recent call last):
  File "C:\Users\bonjour\AppData\Local\Programs\Python\Python39\lib\site-packages\urllib3\connectionpool.py", line 699, in urlopen
    httplib_response = self._make_request(
  File "C:\Users\bonjour\AppData\Local\Programs\Python\Python39\lib\site-packages\urllib3\connectionpool.py", line 382, in _make_request
    self._validate_conn(conn)
  File "C:\Users\bonjour\AppData\Local\Programs\Python\Python39\lib\site-packages\urllib3\connectionpool.py", line 1010, in _validate_conn
    conn.connect()
  File "C:\Users\bonjour\AppData\Local\Programs\Python\Python39\lib\site-packages\urllib3\connection.py", line 353, in connect
    conn = self._new_conn()
  File "C:\Users\bonjour\AppData\Local\Programs\Python\Python39\lib\site-packages\urllib3\connection.py", line 181, in _new_conn
    raise NewConnectionError(
urllib3.exceptions.NewConnectionError: <urllib3.connection.HTTPSConnection object at 0x00000189B665CF70>: Failed to establish a new connection: [Errno 11001] getaddrinfo failed

During handling of the above exception, another exception occurred:

Traceback (most recent call last):
  File "C:\Users\bonjour\AppData\Local\Programs\Python\Python39\lib\site-packages\requests\adapters.py", line 439, in send
    resp = conn.urlopen(
  File "C:\Users\bonjour\AppData\Local\Programs\Python\Python39\lib\site-packages\urllib3\connectionpool.py", line 755, in urlopen
    retries = retries.increment(
  File "C:\Users\bonjour\AppData\Local\Programs\Python\Python39\lib\site-packages\urllib3\util\retry.py", line 574, in increment
    raise MaxRetryError(_pool, url, error or ResponseError(cause))
urllib3.exceptions.MaxRetryError: HTTPSConnectionPool(host='supplychain-server-stg.datousoft.jmj1995.com', port=443): Max retries exceeded with url: /suppliers/1 (Caused by NewConnectionError('<urllib3.connection.HTTPSConnection object at 0x00000189B665CF70>: Failed to establish a new connection: [Errno 11001] getaddrinfo failed'))

During handling of the above exception, another exception occurred:

Traceback (most recent call last):
  File "..\Common\requestbase.py", line 72, in patch_Req
    res=requests.patch(url=url,data=data,headers=headers,json=json,params=params)
  File "C:\Users\bonjour\AppData\Local\Programs\Python\Python39\lib\site-packages\requests\api.py", line 149, in patch
    return request('patch', url, data=data, **kwargs)
  File "C:\Users\bonjour\AppData\Local\Programs\Python\Python39\lib\site-packages\requests\api.py", line 61, in request
    return session.request(method=method, url=url, **kwargs)
  File "C:\Users\bonjour\AppData\Local\Programs\Python\Python39\lib\site-packages\requests\sessions.py", line 542, in request
    resp = self.send(prep, **send_kwargs)
  File "C:\Users\bonjour\AppData\Local\Programs\Python\Python39\lib\site-packages\requests\sessions.py", line 655, in send
    r = adapter.send(request, **kwargs)
  File "C:\Users\bonjour\AppData\Local\Programs\Python\Python39\lib\site-packages\requests\adapters.py", line 516, in send
    raise ConnectionError(e, request=request)
requests.exceptions.ConnectionError: HTTPSConnectionPool(host='supplychain-server-stg.datousoft.jmj1995.com', port=443): Max retries exceeded with url: /suppliers/1 (Caused by NewConnectionError('<urllib3.connection.HTTPSConnection object at 0x00000189B665CF70>: Failed to establish a new connection: [Errno 11001] getaddrinfo failed'))
2022-02-08 17:12:29,264 - ERROR requestbase.py [line:76]: 等待接口"https://supplychain-server-stg.datousoft.jmj1995.com/suppliers/1"失败
Traceback (most recent call last):
  File "C:\Users\bonjour\AppData\Local\Programs\Python\Python39\lib\site-packages\urllib3\connection.py", line 169, in _new_conn
    conn = connection.create_connection(
  File "C:\Users\bonjour\AppData\Local\Programs\Python\Python39\lib\site-packages\urllib3\util\connection.py", line 73, in create_connection
    for res in socket.getaddrinfo(host, port, family, socket.SOCK_STREAM):
  File "C:\Users\bonjour\AppData\Local\Programs\Python\Python39\lib\socket.py", line 953, in getaddrinfo
    for res in _socket.getaddrinfo(host, port, family, type, proto, flags):
socket.gaierror: [Errno 11001] getaddrinfo failed

During handling of the above exception, another exception occurred:

Traceback (most recent call last):
  File "C:\Users\bonjour\AppData\Local\Programs\Python\Python39\lib\site-packages\urllib3\connectionpool.py", line 699, in urlopen
    httplib_response = self._make_request(
  File "C:\Users\bonjour\AppData\Local\Programs\Python\Python39\lib\site-packages\urllib3\connectionpool.py", line 382, in _make_request
    self._validate_conn(conn)
  File "C:\Users\bonjour\AppData\Local\Programs\Python\Python39\lib\site-packages\urllib3\connectionpool.py", line 1010, in _validate_conn
    conn.connect()
  File "C:\Users\bonjour\AppData\Local\Programs\Python\Python39\lib\site-packages\urllib3\connection.py", line 353, in connect
    conn = self._new_conn()
  File "C:\Users\bonjour\AppData\Local\Programs\Python\Python39\lib\site-packages\urllib3\connection.py", line 181, in _new_conn
    raise NewConnectionError(
urllib3.exceptions.NewConnectionError: <urllib3.connection.HTTPSConnection object at 0x00000189B665CF70>: Failed to establish a new connection: [Errno 11001] getaddrinfo failed

During handling of the above exception, another exception occurred:

Traceback (most recent call last):
  File "C:\Users\bonjour\AppData\Local\Programs\Python\Python39\lib\site-packages\requests\adapters.py", line 439, in send
    resp = conn.urlopen(
  File "C:\Users\bonjour\AppData\Local\Programs\Python\Python39\lib\site-packages\urllib3\connectionpool.py", line 755, in urlopen
    retries = retries.increment(
  File "C:\Users\bonjour\AppData\Local\Programs\Python\Python39\lib\site-packages\urllib3\util\retry.py", line 574, in increment
    raise MaxRetryError(_pool, url, error or ResponseError(cause))
urllib3.exceptions.MaxRetryError: HTTPSConnectionPool(host='supplychain-server-stg.datousoft.jmj1995.com', port=443): Max retries exceeded with url: /suppliers/1 (Caused by NewConnectionError('<urllib3.connection.HTTPSConnection object at 0x00000189B665CF70>: Failed to establish a new connection: [Errno 11001] getaddrinfo failed'))

During handling of the above exception, another exception occurred:

Traceback (most recent call last):
  File "..\Common\requestbase.py", line 72, in patch_Req
    res=requests.patch(url=url,data=data,headers=headers,json=json,params=params)
  File "C:\Users\bonjour\AppData\Local\Programs\Python\Python39\lib\site-packages\requests\api.py", line 149, in patch
    return request('patch', url, data=data, **kwargs)
  File "C:\Users\bonjour\AppData\Local\Programs\Python\Python39\lib\site-packages\requests\api.py", line 61, in request
    return session.request(method=method, url=url, **kwargs)
  File "C:\Users\bonjour\AppData\Local\Programs\Python\Python39\lib\site-packages\requests\sessions.py", line 542, in request
    resp = self.send(prep, **send_kwargs)
  File "C:\Users\bonjour\AppData\Local\Programs\Python\Python39\lib\site-packages\requests\sessions.py", line 655, in send
    r = adapter.send(request, **kwargs)
  File "C:\Users\bonjour\AppData\Local\Programs\Python\Python39\lib\site-packages\requests\adapters.py", line 516, in send
    raise ConnectionError(e, request=request)
requests.exceptions.ConnectionError: HTTPSConnectionPool(host='supplychain-server-stg.datousoft.jmj1995.com', port=443): Max retries exceeded with url: /suppliers/1 (Caused by NewConnectionError('<urllib3.connection.HTTPSConnection object at 0x00000189B665CF70>: Failed to establish a new connection: [Errno 11001] getaddrinfo failed'))
2022-02-08 17:12:29,264 - ERROR requestbase.py [line:76]: 等待接口"https://supplychain-server-stg.datousoft.jmj1995.com/suppliers/1"失败
Traceback (most recent call last):
  File "C:\Users\bonjour\AppData\Local\Programs\Python\Python39\lib\site-packages\urllib3\connection.py", line 169, in _new_conn
    conn = connection.create_connection(
  File "C:\Users\bonjour\AppData\Local\Programs\Python\Python39\lib\site-packages\urllib3\util\connection.py", line 73, in create_connection
    for res in socket.getaddrinfo(host, port, family, socket.SOCK_STREAM):
  File "C:\Users\bonjour\AppData\Local\Programs\Python\Python39\lib\socket.py", line 953, in getaddrinfo
    for res in _socket.getaddrinfo(host, port, family, type, proto, flags):
socket.gaierror: [Errno 11001] getaddrinfo failed

During handling of the above exception, another exception occurred:

Traceback (most recent call last):
  File "C:\Users\bonjour\AppData\Local\Programs\Python\Python39\lib\site-packages\urllib3\connectionpool.py", line 699, in urlopen
    httplib_response = self._make_request(
  File "C:\Users\bonjour\AppData\Local\Programs\Python\Python39\lib\site-packages\urllib3\connectionpool.py", line 382, in _make_request
    self._validate_conn(conn)
  File "C:\Users\bonjour\AppData\Local\Programs\Python\Python39\lib\site-packages\urllib3\connectionpool.py", line 1010, in _validate_conn
    conn.connect()
  File "C:\Users\bonjour\AppData\Local\Programs\Python\Python39\lib\site-packages\urllib3\connection.py", line 353, in connect
    conn = self._new_conn()
  File "C:\Users\bonjour\AppData\Local\Programs\Python\Python39\lib\site-packages\urllib3\connection.py", line 181, in _new_conn
    raise NewConnectionError(
urllib3.exceptions.NewConnectionError: <urllib3.connection.HTTPSConnection object at 0x00000189B665CF70>: Failed to establish a new connection: [Errno 11001] getaddrinfo failed

During handling of the above exception, another exception occurred:

Traceback (most recent call last):
  File "C:\Users\bonjour\AppData\Local\Programs\Python\Python39\lib\site-packages\requests\adapters.py", line 439, in send
    resp = conn.urlopen(
  File "C:\Users\bonjour\AppData\Local\Programs\Python\Python39\lib\site-packages\urllib3\connectionpool.py", line 755, in urlopen
    retries = retries.increment(
  File "C:\Users\bonjour\AppData\Local\Programs\Python\Python39\lib\site-packages\urllib3\util\retry.py", line 574, in increment
    raise MaxRetryError(_pool, url, error or ResponseError(cause))
urllib3.exceptions.MaxRetryError: HTTPSConnectionPool(host='supplychain-server-stg.datousoft.jmj1995.com', port=443): Max retries exceeded with url: /suppliers/1 (Caused by NewConnectionError('<urllib3.connection.HTTPSConnection object at 0x00000189B665CF70>: Failed to establish a new connection: [Errno 11001] getaddrinfo failed'))

During handling of the above exception, another exception occurred:

Traceback (most recent call last):
  File "..\Common\requestbase.py", line 72, in patch_Req
    res=requests.patch(url=url,data=data,headers=headers,json=json,params=params)
  File "C:\Users\bonjour\AppData\Local\Programs\Python\Python39\lib\site-packages\requests\api.py", line 149, in patch
    return request('patch', url, data=data, **kwargs)
  File "C:\Users\bonjour\AppData\Local\Programs\Python\Python39\lib\site-packages\requests\api.py", line 61, in request
    return session.request(method=method, url=url, **kwargs)
  File "C:\Users\bonjour\AppData\Local\Programs\Python\Python39\lib\site-packages\requests\sessions.py", line 542, in request
    resp = self.send(prep, **send_kwargs)
  File "C:\Users\bonjour\AppData\Local\Programs\Python\Python39\lib\site-packages\requests\sessions.py", line 655, in send
    r = adapter.send(request, **kwargs)
  File "C:\Users\bonjour\AppData\Local\Programs\Python\Python39\lib\site-packages\requests\adapters.py", line 516, in send
    raise ConnectionError(e, request=request)
requests.exceptions.ConnectionError: HTTPSConnectionPool(host='supplychain-server-stg.datousoft.jmj1995.com', port=443): Max retries exceeded with url: /suppliers/1 (Caused by NewConnectionError('<urllib3.connection.HTTPSConnection object at 0x00000189B665CF70>: Failed to establish a new connection: [Errno 11001] getaddrinfo failed'))
