2022-02-08 17:33:04,038 - INFO requestbase.py [line:21]: 连通接口"https://supplychain-server-stg.datousoft.com/suppliers/1",接口header为:"{'authorization': 'Bearer eyJhbGciOiJIUzUxMiJ9.eyJqdGkiOiI4NDVjNDgwMzg3Mzk0MGU0YmMzMzMwMTkzYjEwMWU0NiIsImF1dGgiOiIiLCJpZCI6NTk5LCJzdWIiOiIxMiJ9.h_Kdz9mLAdv5OTeQU5vjvjo3TaINBCjTBOdFMIvr0fGz7FmOU0VzfcZbAxxguUJb9q4mdCycmVgDqWllfKQvmQ'}",接口param为：
2022-02-08 17:33:04,088 - ERROR requestbase.py [line:28]: 等待接口"https://supplychain-server-stg.datousoft.com/suppliers/1"失败
Traceback (most recent call last):
  File "C:\Users\bonjour\AppData\Local\Programs\Python\Python39\lib\site-packages\urllib3\connectionpool.py", line 699, in urlopen
    httplib_response = self._make_request(
  File "C:\Users\bonjour\AppData\Local\Programs\Python\Python39\lib\site-packages\urllib3\connectionpool.py", line 382, in _make_request
    self._validate_conn(conn)
  File "C:\Users\bonjour\AppData\Local\Programs\Python\Python39\lib\site-packages\urllib3\connectionpool.py", line 1010, in _validate_conn
    conn.connect()
  File "C:\Users\bonjour\AppData\Local\Programs\Python\Python39\lib\site-packages\urllib3\connection.py", line 411, in connect
    self.sock = ssl_wrap_socket(
  File "C:\Users\bonjour\AppData\Local\Programs\Python\Python39\lib\site-packages\urllib3\util\ssl_.py", line 428, in ssl_wrap_socket
    ssl_sock = _ssl_wrap_socket_impl(
  File "C:\Users\bonjour\AppData\Local\Programs\Python\Python39\lib\site-packages\urllib3\util\ssl_.py", line 472, in _ssl_wrap_socket_impl
    return ssl_context.wrap_socket(sock, server_hostname=server_hostname)
  File "C:\Users\bonjour\AppData\Local\Programs\Python\Python39\lib\ssl.py", line 500, in wrap_socket
    return self.sslsocket_class._create(
  File "C:\Users\bonjour\AppData\Local\Programs\Python\Python39\lib\ssl.py", line 1040, in _create
    self.do_handshake()
  File "C:\Users\bonjour\AppData\Local\Programs\Python\Python39\lib\ssl.py", line 1309, in do_handshake
    self._sslobj.do_handshake()
ssl.SSLCertVerificationError: [SSL: CERTIFICATE_VERIFY_FAILED] certificate verify failed: self signed certificate (_ssl.c:1123)

During handling of the above exception, another exception occurred:

Traceback (most recent call last):
  File "C:\Users\bonjour\AppData\Local\Programs\Python\Python39\lib\site-packages\requests\adapters.py", line 439, in send
    resp = conn.urlopen(
  File "C:\Users\bonjour\AppData\Local\Programs\Python\Python39\lib\site-packages\urllib3\connectionpool.py", line 755, in urlopen
    retries = retries.increment(
  File "C:\Users\bonjour\AppData\Local\Programs\Python\Python39\lib\site-packages\urllib3\util\retry.py", line 574, in increment
    raise MaxRetryError(_pool, url, error or ResponseError(cause))
urllib3.exceptions.MaxRetryError: HTTPSConnectionPool(host='supplychain-server-stg.datousoft.com', port=443): Max retries exceeded with url: /suppliers/1 (Caused by SSLError(SSLCertVerificationError(1, '[SSL: CERTIFICATE_VERIFY_FAILED] certificate verify failed: self signed certificate (_ssl.c:1123)')))

During handling of the above exception, another exception occurred:

Traceback (most recent call last):
  File "..\Common\requestbase.py", line 24, in get_Req
    res=requests.get(url=url,headers=headers,params=params,data=data,json=json)
  File "C:\Users\bonjour\AppData\Local\Programs\Python\Python39\lib\site-packages\requests\api.py", line 76, in get
    return request('get', url, params=params, **kwargs)
  File "C:\Users\bonjour\AppData\Local\Programs\Python\Python39\lib\site-packages\requests\api.py", line 61, in request
    return session.request(method=method, url=url, **kwargs)
  File "C:\Users\bonjour\AppData\Local\Programs\Python\Python39\lib\site-packages\requests\sessions.py", line 542, in request
    resp = self.send(prep, **send_kwargs)
  File "C:\Users\bonjour\AppData\Local\Programs\Python\Python39\lib\site-packages\requests\sessions.py", line 655, in send
    r = adapter.send(request, **kwargs)
  File "C:\Users\bonjour\AppData\Local\Programs\Python\Python39\lib\site-packages\requests\adapters.py", line 514, in send
    raise SSLError(e, request=request)
requests.exceptions.SSLError: HTTPSConnectionPool(host='supplychain-server-stg.datousoft.com', port=443): Max retries exceeded with url: /suppliers/1 (Caused by SSLError(SSLCertVerificationError(1, '[SSL: CERTIFICATE_VERIFY_FAILED] certificate verify failed: self signed certificate (_ssl.c:1123)')))
2022-02-08 17:33:04,105 - INFO requestbase.py [line:69]: 连通接口"https://supplychain-server-stg.datousoft.com/suppliers/1",接口data为:"",接口json{'enable': 'false'}
2022-02-08 17:33:04,105 - INFO requestbase.py [line:69]: 连通接口"https://supplychain-server-stg.datousoft.com/suppliers/1",接口data为:"",接口json{'enable': 'false'}
2022-02-08 17:33:04,159 - ERROR requestbase.py [line:76]: 等待接口"https://supplychain-server-stg.datousoft.com/suppliers/1"失败
Traceback (most recent call last):
  File "C:\Users\bonjour\AppData\Local\Programs\Python\Python39\lib\site-packages\urllib3\connectionpool.py", line 699, in urlopen
    httplib_response = self._make_request(
  File "C:\Users\bonjour\AppData\Local\Programs\Python\Python39\lib\site-packages\urllib3\connectionpool.py", line 382, in _make_request
    self._validate_conn(conn)
  File "C:\Users\bonjour\AppData\Local\Programs\Python\Python39\lib\site-packages\urllib3\connectionpool.py", line 1010, in _validate_conn
    conn.connect()
  File "C:\Users\bonjour\AppData\Local\Programs\Python\Python39\lib\site-packages\urllib3\connection.py", line 411, in connect
    self.sock = ssl_wrap_socket(
  File "C:\Users\bonjour\AppData\Local\Programs\Python\Python39\lib\site-packages\urllib3\util\ssl_.py", line 428, in ssl_wrap_socket
    ssl_sock = _ssl_wrap_socket_impl(
  File "C:\Users\bonjour\AppData\Local\Programs\Python\Python39\lib\site-packages\urllib3\util\ssl_.py", line 472, in _ssl_wrap_socket_impl
    return ssl_context.wrap_socket(sock, server_hostname=server_hostname)
  File "C:\Users\bonjour\AppData\Local\Programs\Python\Python39\lib\ssl.py", line 500, in wrap_socket
    return self.sslsocket_class._create(
  File "C:\Users\bonjour\AppData\Local\Programs\Python\Python39\lib\ssl.py", line 1040, in _create
    self.do_handshake()
  File "C:\Users\bonjour\AppData\Local\Programs\Python\Python39\lib\ssl.py", line 1309, in do_handshake
    self._sslobj.do_handshake()
ssl.SSLCertVerificationError: [SSL: CERTIFICATE_VERIFY_FAILED] certificate verify failed: self signed certificate (_ssl.c:1123)

During handling of the above exception, another exception occurred:

Traceback (most recent call last):
  File "C:\Users\bonjour\AppData\Local\Programs\Python\Python39\lib\site-packages\requests\adapters.py", line 439, in send
    resp = conn.urlopen(
  File "C:\Users\bonjour\AppData\Local\Programs\Python\Python39\lib\site-packages\urllib3\connectionpool.py", line 755, in urlopen
    retries = retries.increment(
  File "C:\Users\bonjour\AppData\Local\Programs\Python\Python39\lib\site-packages\urllib3\util\retry.py", line 574, in increment
    raise MaxRetryError(_pool, url, error or ResponseError(cause))
urllib3.exceptions.MaxRetryError: HTTPSConnectionPool(host='supplychain-server-stg.datousoft.com', port=443): Max retries exceeded with url: /suppliers/1 (Caused by SSLError(SSLCertVerificationError(1, '[SSL: CERTIFICATE_VERIFY_FAILED] certificate verify failed: self signed certificate (_ssl.c:1123)')))

During handling of the above exception, another exception occurred:

Traceback (most recent call last):
  File "..\Common\requestbase.py", line 72, in patch_Req
    res=requests.patch(url=url,data=data,headers=headers,json=json,params=params)
  File "C:\Users\bonjour\AppData\Local\Programs\Python\Python39\lib\site-packages\requests\api.py", line 149, in patch
    return request('patch', url, data=data, **kwargs)
  File "C:\Users\bonjour\AppData\Local\Programs\Python\Python39\lib\site-packages\requests\api.py", line 61, in request
    return session.request(method=method, url=url, **kwargs)
  File "C:\Users\bonjour\AppData\Local\Programs\Python\Python39\lib\site-packages\requests\sessions.py", line 542, in request
    resp = self.send(prep, **send_kwargs)
  File "C:\Users\bonjour\AppData\Local\Programs\Python\Python39\lib\site-packages\requests\sessions.py", line 655, in send
    r = adapter.send(request, **kwargs)
  File "C:\Users\bonjour\AppData\Local\Programs\Python\Python39\lib\site-packages\requests\adapters.py", line 514, in send
    raise SSLError(e, request=request)
requests.exceptions.SSLError: HTTPSConnectionPool(host='supplychain-server-stg.datousoft.com', port=443): Max retries exceeded with url: /suppliers/1 (Caused by SSLError(SSLCertVerificationError(1, '[SSL: CERTIFICATE_VERIFY_FAILED] certificate verify failed: self signed certificate (_ssl.c:1123)')))
2022-02-08 17:33:04,159 - ERROR requestbase.py [line:76]: 等待接口"https://supplychain-server-stg.datousoft.com/suppliers/1"失败
Traceback (most recent call last):
  File "C:\Users\bonjour\AppData\Local\Programs\Python\Python39\lib\site-packages\urllib3\connectionpool.py", line 699, in urlopen
    httplib_response = self._make_request(
  File "C:\Users\bonjour\AppData\Local\Programs\Python\Python39\lib\site-packages\urllib3\connectionpool.py", line 382, in _make_request
    self._validate_conn(conn)
  File "C:\Users\bonjour\AppData\Local\Programs\Python\Python39\lib\site-packages\urllib3\connectionpool.py", line 1010, in _validate_conn
    conn.connect()
  File "C:\Users\bonjour\AppData\Local\Programs\Python\Python39\lib\site-packages\urllib3\connection.py", line 411, in connect
    self.sock = ssl_wrap_socket(
  File "C:\Users\bonjour\AppData\Local\Programs\Python\Python39\lib\site-packages\urllib3\util\ssl_.py", line 428, in ssl_wrap_socket
    ssl_sock = _ssl_wrap_socket_impl(
  File "C:\Users\bonjour\AppData\Local\Programs\Python\Python39\lib\site-packages\urllib3\util\ssl_.py", line 472, in _ssl_wrap_socket_impl
    return ssl_context.wrap_socket(sock, server_hostname=server_hostname)
  File "C:\Users\bonjour\AppData\Local\Programs\Python\Python39\lib\ssl.py", line 500, in wrap_socket
    return self.sslsocket_class._create(
  File "C:\Users\bonjour\AppData\Local\Programs\Python\Python39\lib\ssl.py", line 1040, in _create
    self.do_handshake()
  File "C:\Users\bonjour\AppData\Local\Programs\Python\Python39\lib\ssl.py", line 1309, in do_handshake
    self._sslobj.do_handshake()
ssl.SSLCertVerificationError: [SSL: CERTIFICATE_VERIFY_FAILED] certificate verify failed: self signed certificate (_ssl.c:1123)

During handling of the above exception, another exception occurred:

Traceback (most recent call last):
  File "C:\Users\bonjour\AppData\Local\Programs\Python\Python39\lib\site-packages\requests\adapters.py", line 439, in send
    resp = conn.urlopen(
  File "C:\Users\bonjour\AppData\Local\Programs\Python\Python39\lib\site-packages\urllib3\connectionpool.py", line 755, in urlopen
    retries = retries.increment(
  File "C:\Users\bonjour\AppData\Local\Programs\Python\Python39\lib\site-packages\urllib3\util\retry.py", line 574, in increment
    raise MaxRetryError(_pool, url, error or ResponseError(cause))
urllib3.exceptions.MaxRetryError: HTTPSConnectionPool(host='supplychain-server-stg.datousoft.com', port=443): Max retries exceeded with url: /suppliers/1 (Caused by SSLError(SSLCertVerificationError(1, '[SSL: CERTIFICATE_VERIFY_FAILED] certificate verify failed: self signed certificate (_ssl.c:1123)')))

During handling of the above exception, another exception occurred:

Traceback (most recent call last):
  File "..\Common\requestbase.py", line 72, in patch_Req
    res=requests.patch(url=url,data=data,headers=headers,json=json,params=params)
  File "C:\Users\bonjour\AppData\Local\Programs\Python\Python39\lib\site-packages\requests\api.py", line 149, in patch
    return request('patch', url, data=data, **kwargs)
  File "C:\Users\bonjour\AppData\Local\Programs\Python\Python39\lib\site-packages\requests\api.py", line 61, in request
    return session.request(method=method, url=url, **kwargs)
  File "C:\Users\bonjour\AppData\Local\Programs\Python\Python39\lib\site-packages\requests\sessions.py", line 542, in request
    resp = self.send(prep, **send_kwargs)
  File "C:\Users\bonjour\AppData\Local\Programs\Python\Python39\lib\site-packages\requests\sessions.py", line 655, in send
    r = adapter.send(request, **kwargs)
  File "C:\Users\bonjour\AppData\Local\Programs\Python\Python39\lib\site-packages\requests\adapters.py", line 514, in send
    raise SSLError(e, request=request)
requests.exceptions.SSLError: HTTPSConnectionPool(host='supplychain-server-stg.datousoft.com', port=443): Max retries exceeded with url: /suppliers/1 (Caused by SSLError(SSLCertVerificationError(1, '[SSL: CERTIFICATE_VERIFY_FAILED] certificate verify failed: self signed certificate (_ssl.c:1123)')))
