--- Logging error ---
Traceback (most recent call last):
  File "C:\Users\bonjour\AppData\Local\Programs\Python\Python39\lib\logging\__init__.py", line 1082, in emit
    stream.write(msg + self.terminator)
OSError: [WinError 6] 句柄无效。
Call stack:
  File "e:\12\TestCase\test_request.py", line 57, in <module>
    pytest.main(["--alluredir", report_path])
  File "C:\Users\bonjour\AppData\Local\Programs\Python\Python39\lib\site-packages\_pytest\config\__init__.py", line 162, in main
    ret: Union[ExitCode, int] = config.hook.pytest_cmdline_main(
  File "C:\Users\bonjour\AppData\Local\Programs\Python\Python39\lib\site-packages\pluggy\_hooks.py", line 265, in __call__
    return self._hookexec(self.name, self.get_hookimpls(), kwargs, firstresult)
  File "C:\Users\bonjour\AppData\Local\Programs\Python\Python39\lib\site-packages\pluggy\_manager.py", line 80, in _hookexec
    return self._inner_hookexec(hook_name, methods, kwargs, firstresult)
  File "C:\Users\bonjour\AppData\Local\Programs\Python\Python39\lib\site-packages\pluggy\_callers.py", line 39, in _multicall
    res = hook_impl.function(*args)
  File "C:\Users\bonjour\AppData\Local\Programs\Python\Python39\lib\site-packages\_pytest\main.py", line 316, in pytest_cmdline_main
    return wrap_session(config, _main)
  File "C:\Users\bonjour\AppData\Local\Programs\Python\Python39\lib\site-packages\_pytest\main.py", line 269, in wrap_session
    session.exitstatus = doit(config, session) or 0
  File "C:\Users\bonjour\AppData\Local\Programs\Python\Python39\lib\site-packages\_pytest\main.py", line 323, in _main
    config.hook.pytest_runtestloop(session=session)
  File "C:\Users\bonjour\AppData\Local\Programs\Python\Python39\lib\site-packages\pluggy\_hooks.py", line 265, in __call__
    return self._hookexec(self.name, self.get_hookimpls(), kwargs, firstresult)
  File "C:\Users\bonjour\AppData\Local\Programs\Python\Python39\lib\site-packages\pluggy\_manager.py", line 80, in _hookexec
    return self._inner_hookexec(hook_name, methods, kwargs, firstresult)
  File "C:\Users\bonjour\AppData\Local\Programs\Python\Python39\lib\site-packages\pluggy\_callers.py", line 39, in _multicall
    res = hook_impl.function(*args)
  File "C:\Users\bonjour\AppData\Local\Programs\Python\Python39\lib\site-packages\_pytest\main.py", line 348, in pytest_runtestloop
    item.config.hook.pytest_runtest_protocol(item=item, nextitem=nextitem)
  File "C:\Users\bonjour\AppData\Local\Programs\Python\Python39\lib\site-packages\pluggy\_hooks.py", line 265, in __call__
    return self._hookexec(self.name, self.get_hookimpls(), kwargs, firstresult)
  File "C:\Users\bonjour\AppData\Local\Programs\Python\Python39\lib\site-packages\pluggy\_manager.py", line 80, in _hookexec
    return self._inner_hookexec(hook_name, methods, kwargs, firstresult)
  File "C:\Users\bonjour\AppData\Local\Programs\Python\Python39\lib\site-packages\pluggy\_callers.py", line 39, in _multicall
    res = hook_impl.function(*args)
  File "c:\users\bonjour\appdata\local\programs\python\python39\lib\site-packages\pytest_rerunfailures.py", line 497, in pytest_runtest_protocol
    reports = runtestprotocol(item, nextitem=nextitem, log=False)
  File "C:\Users\bonjour\AppData\Local\Programs\Python\Python39\lib\site-packages\_pytest\runner.py", line 126, in runtestprotocol
    reports.append(call_and_report(item, "call", log))
  File "C:\Users\bonjour\AppData\Local\Programs\Python\Python39\lib\site-packages\_pytest\runner.py", line 215, in call_and_report
    call = call_runtest_hook(item, when, **kwds)
  File "C:\Users\bonjour\AppData\Local\Programs\Python\Python39\lib\site-packages\_pytest\runner.py", line 254, in call_runtest_hook
    return CallInfo.from_call(
  File "C:\Users\bonjour\AppData\Local\Programs\Python\Python39\lib\site-packages\_pytest\runner.py", line 311, in from_call
    result: Optional[TResult] = func()
  File "C:\Users\bonjour\AppData\Local\Programs\Python\Python39\lib\site-packages\_pytest\runner.py", line 255, in <lambda>
    lambda: ihook(item=item, **kwds), when=when, reraise=reraise
  File "C:\Users\bonjour\AppData\Local\Programs\Python\Python39\lib\site-packages\pluggy\_hooks.py", line 265, in __call__
    return self._hookexec(self.name, self.get_hookimpls(), kwargs, firstresult)
  File "C:\Users\bonjour\AppData\Local\Programs\Python\Python39\lib\site-packages\pluggy\_manager.py", line 80, in _hookexec
    return self._inner_hookexec(hook_name, methods, kwargs, firstresult)
  File "C:\Users\bonjour\AppData\Local\Programs\Python\Python39\lib\site-packages\pluggy\_callers.py", line 39, in _multicall
    res = hook_impl.function(*args)
  File "C:\Users\bonjour\AppData\Local\Programs\Python\Python39\lib\site-packages\_pytest\runner.py", line 162, in pytest_runtest_call
    item.runtest()
  File "C:\Users\bonjour\AppData\Local\Programs\Python\Python39\lib\site-packages\_pytest\python.py", line 1641, in runtest
    self.ihook.pytest_pyfunc_call(pyfuncitem=self)
  File "C:\Users\bonjour\AppData\Local\Programs\Python\Python39\lib\site-packages\pluggy\_hooks.py", line 265, in __call__
    return self._hookexec(self.name, self.get_hookimpls(), kwargs, firstresult)
  File "C:\Users\bonjour\AppData\Local\Programs\Python\Python39\lib\site-packages\pluggy\_manager.py", line 80, in _hookexec
    return self._inner_hookexec(hook_name, methods, kwargs, firstresult)
  File "C:\Users\bonjour\AppData\Local\Programs\Python\Python39\lib\site-packages\pluggy\_callers.py", line 39, in _multicall
    res = hook_impl.function(*args)
  File "C:\Users\bonjour\AppData\Local\Programs\Python\Python39\lib\site-packages\_pytest\python.py", line 183, in pytest_pyfunc_call
    result = testfunction(**testargs)
  File "E:\12\TestCase\test_request.py", line 42, in test_001
    requestdata=RequestsHandler().patch_Req(url=final_data[2]['url'],params="",headers=header_list,json=final_data[2]['bodys'],data="")
  File ".\Common\requestbase.py", line 69, in patch_Req
    self.logger.info(f'连通接口"{url}",接口data为:"{data}",接口json{json}')
Message: '连通接口"https://supplychain-server-stg.jmj1995.com/items/1/belongingStandardAlternativeItemGroup",接口data为:"",接口json{"enable":true,"tags":["12","23","34","45","56","67","78","89","01","99953816724","99897524630","99135297046","99254607193","99310649275","99376528194","99352478916","99503247816","99187059632","99953042716","99638017452","99237065184"],"enableValidDays":true}'
Arguments: ()
--- Logging error ---
Traceback (most recent call last):
  File "C:\Users\bonjour\AppData\Local\Programs\Python\Python39\lib\logging\__init__.py", line 1082, in emit
    stream.write(msg + self.terminator)
OSError: [WinError 6] 句柄无效。
Call stack:
  File "e:\12\TestCase\test_request.py", line 57, in <module>
    pytest.main(["--alluredir", report_path])
  File "C:\Users\bonjour\AppData\Local\Programs\Python\Python39\lib\site-packages\_pytest\config\__init__.py", line 162, in main
    ret: Union[ExitCode, int] = config.hook.pytest_cmdline_main(
  File "C:\Users\bonjour\AppData\Local\Programs\Python\Python39\lib\site-packages\pluggy\_hooks.py", line 265, in __call__
    return self._hookexec(self.name, self.get_hookimpls(), kwargs, firstresult)
  File "C:\Users\bonjour\AppData\Local\Programs\Python\Python39\lib\site-packages\pluggy\_manager.py", line 80, in _hookexec
    return self._inner_hookexec(hook_name, methods, kwargs, firstresult)
  File "C:\Users\bonjour\AppData\Local\Programs\Python\Python39\lib\site-packages\pluggy\_callers.py", line 39, in _multicall
    res = hook_impl.function(*args)
  File "C:\Users\bonjour\AppData\Local\Programs\Python\Python39\lib\site-packages\_pytest\main.py", line 316, in pytest_cmdline_main
    return wrap_session(config, _main)
  File "C:\Users\bonjour\AppData\Local\Programs\Python\Python39\lib\site-packages\_pytest\main.py", line 269, in wrap_session
    session.exitstatus = doit(config, session) or 0
  File "C:\Users\bonjour\AppData\Local\Programs\Python\Python39\lib\site-packages\_pytest\main.py", line 323, in _main
    config.hook.pytest_runtestloop(session=session)
  File "C:\Users\bonjour\AppData\Local\Programs\Python\Python39\lib\site-packages\pluggy\_hooks.py", line 265, in __call__
    return self._hookexec(self.name, self.get_hookimpls(), kwargs, firstresult)
  File "C:\Users\bonjour\AppData\Local\Programs\Python\Python39\lib\site-packages\pluggy\_manager.py", line 80, in _hookexec
    return self._inner_hookexec(hook_name, methods, kwargs, firstresult)
  File "C:\Users\bonjour\AppData\Local\Programs\Python\Python39\lib\site-packages\pluggy\_callers.py", line 39, in _multicall
    res = hook_impl.function(*args)
  File "C:\Users\bonjour\AppData\Local\Programs\Python\Python39\lib\site-packages\_pytest\main.py", line 348, in pytest_runtestloop
    item.config.hook.pytest_runtest_protocol(item=item, nextitem=nextitem)
  File "C:\Users\bonjour\AppData\Local\Programs\Python\Python39\lib\site-packages\pluggy\_hooks.py", line 265, in __call__
    return self._hookexec(self.name, self.get_hookimpls(), kwargs, firstresult)
  File "C:\Users\bonjour\AppData\Local\Programs\Python\Python39\lib\site-packages\pluggy\_manager.py", line 80, in _hookexec
    return self._inner_hookexec(hook_name, methods, kwargs, firstresult)
  File "C:\Users\bonjour\AppData\Local\Programs\Python\Python39\lib\site-packages\pluggy\_callers.py", line 39, in _multicall
    res = hook_impl.function(*args)
  File "c:\users\bonjour\appdata\local\programs\python\python39\lib\site-packages\pytest_rerunfailures.py", line 497, in pytest_runtest_protocol
    reports = runtestprotocol(item, nextitem=nextitem, log=False)
  File "C:\Users\bonjour\AppData\Local\Programs\Python\Python39\lib\site-packages\_pytest\runner.py", line 126, in runtestprotocol
    reports.append(call_and_report(item, "call", log))
  File "C:\Users\bonjour\AppData\Local\Programs\Python\Python39\lib\site-packages\_pytest\runner.py", line 215, in call_and_report
    call = call_runtest_hook(item, when, **kwds)
  File "C:\Users\bonjour\AppData\Local\Programs\Python\Python39\lib\site-packages\_pytest\runner.py", line 254, in call_runtest_hook
    return CallInfo.from_call(
  File "C:\Users\bonjour\AppData\Local\Programs\Python\Python39\lib\site-packages\_pytest\runner.py", line 311, in from_call
    result: Optional[TResult] = func()
  File "C:\Users\bonjour\AppData\Local\Programs\Python\Python39\lib\site-packages\_pytest\runner.py", line 255, in <lambda>
    lambda: ihook(item=item, **kwds), when=when, reraise=reraise
  File "C:\Users\bonjour\AppData\Local\Programs\Python\Python39\lib\site-packages\pluggy\_hooks.py", line 265, in __call__
    return self._hookexec(self.name, self.get_hookimpls(), kwargs, firstresult)
  File "C:\Users\bonjour\AppData\Local\Programs\Python\Python39\lib\site-packages\pluggy\_manager.py", line 80, in _hookexec
    return self._inner_hookexec(hook_name, methods, kwargs, firstresult)
  File "C:\Users\bonjour\AppData\Local\Programs\Python\Python39\lib\site-packages\pluggy\_callers.py", line 39, in _multicall
    res = hook_impl.function(*args)
  File "C:\Users\bonjour\AppData\Local\Programs\Python\Python39\lib\site-packages\_pytest\runner.py", line 162, in pytest_runtest_call
    item.runtest()
  File "C:\Users\bonjour\AppData\Local\Programs\Python\Python39\lib\site-packages\_pytest\python.py", line 1641, in runtest
    self.ihook.pytest_pyfunc_call(pyfuncitem=self)
  File "C:\Users\bonjour\AppData\Local\Programs\Python\Python39\lib\site-packages\pluggy\_hooks.py", line 265, in __call__
    return self._hookexec(self.name, self.get_hookimpls(), kwargs, firstresult)
  File "C:\Users\bonjour\AppData\Local\Programs\Python\Python39\lib\site-packages\pluggy\_manager.py", line 80, in _hookexec
    return self._inner_hookexec(hook_name, methods, kwargs, firstresult)
  File "C:\Users\bonjour\AppData\Local\Programs\Python\Python39\lib\site-packages\pluggy\_callers.py", line 39, in _multicall
    res = hook_impl.function(*args)
  File "C:\Users\bonjour\AppData\Local\Programs\Python\Python39\lib\site-packages\_pytest\python.py", line 183, in pytest_pyfunc_call
    result = testfunction(**testargs)
  File "E:\12\TestCase\test_request.py", line 42, in test_001
    requestdata=RequestsHandler().patch_Req(url=final_data[2]['url'],params="",headers=header_list,json=final_data[2]['bodys'],data="")
  File ".\Common\requestbase.py", line 69, in patch_Req
    self.logger.info(f'连通接口"{url}",接口data为:"{data}",接口json{json}')
Message: '连通接口"https://supplychain-server-stg.jmj1995.com/items/1/belongingStandardAlternativeItemGroup",接口data为:"",接口json{"enable":true,"tags":["12","23","34","45","56","67","78","89","01","99953816724","99897524630","99135297046","99254607193","99310649275","99376528194","99352478916","99503247816","99187059632","99953042716","99638017452","99237065184"],"enableValidDays":true}'
Arguments: ()
2022-01-28 16:06:18,502 - INFO requestbase.py [line:69]: 连通接口"https://supplychain-server-stg.jmj1995.com/items/1/belongingStandardAlternativeItemGroup",接口data为:"",接口json{"enable":true,"tags":["12","23","34","45","56","67","78","89","01","99953816724","99897524630","99135297046","99254607193","99310649275","99376528194","99352478916","99503247816","99187059632","99953042716","99638017452","99237065184"],"enableValidDays":true}
2022-01-28 16:06:18,502 - INFO requestbase.py [line:69]: 连通接口"https://supplychain-server-stg.jmj1995.com/items/1/belongingStandardAlternativeItemGroup",接口data为:"",接口json{"enable":true,"tags":["12","23","34","45","56","67","78","89","01","99953816724","99897524630","99135297046","99254607193","99310649275","99376528194","99352478916","99503247816","99187059632","99953042716","99638017452","99237065184"],"enableValidDays":true}
2022-01-28 16:06:18,502 - INFO requestbase.py [line:69]: 连通接口"https://supplychain-server-stg.jmj1995.com/items/1/belongingStandardAlternativeItemGroup",接口data为:"",接口json{"enable":true,"tags":["12","23","34","45","56","67","78","89","01","99953816724","99897524630","99135297046","99254607193","99310649275","99376528194","99352478916","99503247816","99187059632","99953042716","99638017452","99237065184"],"enableValidDays":true}
2022-01-28 16:06:18,502 - INFO requestbase.py [line:69]: 连通接口"https://supplychain-server-stg.jmj1995.com/items/1/belongingStandardAlternativeItemGroup",接口data为:"",接口json{"enable":true,"tags":["12","23","34","45","56","67","78","89","01","99953816724","99897524630","99135297046","99254607193","99310649275","99376528194","99352478916","99503247816","99187059632","99953042716","99638017452","99237065184"],"enableValidDays":true}
2022-01-28 16:06:18,502 - INFO requestbase.py [line:69]: 连通接口"https://supplychain-server-stg.jmj1995.com/items/1/belongingStandardAlternativeItemGroup",接口data为:"",接口json{"enable":true,"tags":["12","23","34","45","56","67","78","89","01","99953816724","99897524630","99135297046","99254607193","99310649275","99376528194","99352478916","99503247816","99187059632","99953042716","99638017452","99237065184"],"enableValidDays":true}
--- Logging error ---
Traceback (most recent call last):
  File "C:\Users\bonjour\AppData\Local\Programs\Python\Python39\lib\logging\__init__.py", line 1082, in emit
    stream.write(msg + self.terminator)
OSError: [WinError 6] 句柄无效。
Call stack:
  File "e:\12\TestCase\test_request.py", line 57, in <module>
    pytest.main(["--alluredir", report_path])
  File "C:\Users\bonjour\AppData\Local\Programs\Python\Python39\lib\site-packages\_pytest\config\__init__.py", line 162, in main
    ret: Union[ExitCode, int] = config.hook.pytest_cmdline_main(
  File "C:\Users\bonjour\AppData\Local\Programs\Python\Python39\lib\site-packages\pluggy\_hooks.py", line 265, in __call__
    return self._hookexec(self.name, self.get_hookimpls(), kwargs, firstresult)
  File "C:\Users\bonjour\AppData\Local\Programs\Python\Python39\lib\site-packages\pluggy\_manager.py", line 80, in _hookexec
    return self._inner_hookexec(hook_name, methods, kwargs, firstresult)
  File "C:\Users\bonjour\AppData\Local\Programs\Python\Python39\lib\site-packages\pluggy\_callers.py", line 39, in _multicall
    res = hook_impl.function(*args)
  File "C:\Users\bonjour\AppData\Local\Programs\Python\Python39\lib\site-packages\_pytest\main.py", line 316, in pytest_cmdline_main
    return wrap_session(config, _main)
  File "C:\Users\bonjour\AppData\Local\Programs\Python\Python39\lib\site-packages\_pytest\main.py", line 269, in wrap_session
    session.exitstatus = doit(config, session) or 0
  File "C:\Users\bonjour\AppData\Local\Programs\Python\Python39\lib\site-packages\_pytest\main.py", line 323, in _main
    config.hook.pytest_runtestloop(session=session)
  File "C:\Users\bonjour\AppData\Local\Programs\Python\Python39\lib\site-packages\pluggy\_hooks.py", line 265, in __call__
    return self._hookexec(self.name, self.get_hookimpls(), kwargs, firstresult)
  File "C:\Users\bonjour\AppData\Local\Programs\Python\Python39\lib\site-packages\pluggy\_manager.py", line 80, in _hookexec
    return self._inner_hookexec(hook_name, methods, kwargs, firstresult)
  File "C:\Users\bonjour\AppData\Local\Programs\Python\Python39\lib\site-packages\pluggy\_callers.py", line 39, in _multicall
    res = hook_impl.function(*args)
  File "C:\Users\bonjour\AppData\Local\Programs\Python\Python39\lib\site-packages\_pytest\main.py", line 348, in pytest_runtestloop
    item.config.hook.pytest_runtest_protocol(item=item, nextitem=nextitem)
  File "C:\Users\bonjour\AppData\Local\Programs\Python\Python39\lib\site-packages\pluggy\_hooks.py", line 265, in __call__
    return self._hookexec(self.name, self.get_hookimpls(), kwargs, firstresult)
  File "C:\Users\bonjour\AppData\Local\Programs\Python\Python39\lib\site-packages\pluggy\_manager.py", line 80, in _hookexec
    return self._inner_hookexec(hook_name, methods, kwargs, firstresult)
  File "C:\Users\bonjour\AppData\Local\Programs\Python\Python39\lib\site-packages\pluggy\_callers.py", line 39, in _multicall
    res = hook_impl.function(*args)
  File "c:\users\bonjour\appdata\local\programs\python\python39\lib\site-packages\pytest_rerunfailures.py", line 497, in pytest_runtest_protocol
    reports = runtestprotocol(item, nextitem=nextitem, log=False)
  File "C:\Users\bonjour\AppData\Local\Programs\Python\Python39\lib\site-packages\_pytest\runner.py", line 126, in runtestprotocol
    reports.append(call_and_report(item, "call", log))
  File "C:\Users\bonjour\AppData\Local\Programs\Python\Python39\lib\site-packages\_pytest\runner.py", line 215, in call_and_report
    call = call_runtest_hook(item, when, **kwds)
  File "C:\Users\bonjour\AppData\Local\Programs\Python\Python39\lib\site-packages\_pytest\runner.py", line 254, in call_runtest_hook
    return CallInfo.from_call(
  File "C:\Users\bonjour\AppData\Local\Programs\Python\Python39\lib\site-packages\_pytest\runner.py", line 311, in from_call
    result: Optional[TResult] = func()
  File "C:\Users\bonjour\AppData\Local\Programs\Python\Python39\lib\site-packages\_pytest\runner.py", line 255, in <lambda>
    lambda: ihook(item=item, **kwds), when=when, reraise=reraise
  File "C:\Users\bonjour\AppData\Local\Programs\Python\Python39\lib\site-packages\pluggy\_hooks.py", line 265, in __call__
    return self._hookexec(self.name, self.get_hookimpls(), kwargs, firstresult)
  File "C:\Users\bonjour\AppData\Local\Programs\Python\Python39\lib\site-packages\pluggy\_manager.py", line 80, in _hookexec
    return self._inner_hookexec(hook_name, methods, kwargs, firstresult)
  File "C:\Users\bonjour\AppData\Local\Programs\Python\Python39\lib\site-packages\pluggy\_callers.py", line 39, in _multicall
    res = hook_impl.function(*args)
  File "C:\Users\bonjour\AppData\Local\Programs\Python\Python39\lib\site-packages\_pytest\runner.py", line 162, in pytest_runtest_call
    item.runtest()
  File "C:\Users\bonjour\AppData\Local\Programs\Python\Python39\lib\site-packages\_pytest\python.py", line 1641, in runtest
    self.ihook.pytest_pyfunc_call(pyfuncitem=self)
  File "C:\Users\bonjour\AppData\Local\Programs\Python\Python39\lib\site-packages\pluggy\_hooks.py", line 265, in __call__
    return self._hookexec(self.name, self.get_hookimpls(), kwargs, firstresult)
  File "C:\Users\bonjour\AppData\Local\Programs\Python\Python39\lib\site-packages\pluggy\_manager.py", line 80, in _hookexec
    return self._inner_hookexec(hook_name, methods, kwargs, firstresult)
  File "C:\Users\bonjour\AppData\Local\Programs\Python\Python39\lib\site-packages\pluggy\_callers.py", line 39, in _multicall
    res = hook_impl.function(*args)
  File "C:\Users\bonjour\AppData\Local\Programs\Python\Python39\lib\site-packages\_pytest\python.py", line 183, in pytest_pyfunc_call
    result = testfunction(**testargs)
  File "E:\12\TestCase\test_request.py", line 42, in test_001
    requestdata=RequestsHandler().patch_Req(url=final_data[2]['url'],params="",headers=header_list,json=final_data[2]['bodys'],data="")
  File ".\Common\requestbase.py", line 74, in patch_Req
    self.logger.info(f'等待接口"{url}"时长:{end - start}')
Message: '等待接口"https://supplychain-server-stg.jmj1995.com/items/1/belongingStandardAlternativeItemGroup"时长:0:00:00.054853'
Arguments: ()
--- Logging error ---
Traceback (most recent call last):
  File "C:\Users\bonjour\AppData\Local\Programs\Python\Python39\lib\logging\__init__.py", line 1082, in emit
    stream.write(msg + self.terminator)
OSError: [WinError 6] 句柄无效。
Call stack:
  File "e:\12\TestCase\test_request.py", line 57, in <module>
    pytest.main(["--alluredir", report_path])
  File "C:\Users\bonjour\AppData\Local\Programs\Python\Python39\lib\site-packages\_pytest\config\__init__.py", line 162, in main
    ret: Union[ExitCode, int] = config.hook.pytest_cmdline_main(
  File "C:\Users\bonjour\AppData\Local\Programs\Python\Python39\lib\site-packages\pluggy\_hooks.py", line 265, in __call__
    return self._hookexec(self.name, self.get_hookimpls(), kwargs, firstresult)
  File "C:\Users\bonjour\AppData\Local\Programs\Python\Python39\lib\site-packages\pluggy\_manager.py", line 80, in _hookexec
    return self._inner_hookexec(hook_name, methods, kwargs, firstresult)
  File "C:\Users\bonjour\AppData\Local\Programs\Python\Python39\lib\site-packages\pluggy\_callers.py", line 39, in _multicall
    res = hook_impl.function(*args)
  File "C:\Users\bonjour\AppData\Local\Programs\Python\Python39\lib\site-packages\_pytest\main.py", line 316, in pytest_cmdline_main
    return wrap_session(config, _main)
  File "C:\Users\bonjour\AppData\Local\Programs\Python\Python39\lib\site-packages\_pytest\main.py", line 269, in wrap_session
    session.exitstatus = doit(config, session) or 0
  File "C:\Users\bonjour\AppData\Local\Programs\Python\Python39\lib\site-packages\_pytest\main.py", line 323, in _main
    config.hook.pytest_runtestloop(session=session)
  File "C:\Users\bonjour\AppData\Local\Programs\Python\Python39\lib\site-packages\pluggy\_hooks.py", line 265, in __call__
    return self._hookexec(self.name, self.get_hookimpls(), kwargs, firstresult)
  File "C:\Users\bonjour\AppData\Local\Programs\Python\Python39\lib\site-packages\pluggy\_manager.py", line 80, in _hookexec
    return self._inner_hookexec(hook_name, methods, kwargs, firstresult)
  File "C:\Users\bonjour\AppData\Local\Programs\Python\Python39\lib\site-packages\pluggy\_callers.py", line 39, in _multicall
    res = hook_impl.function(*args)
  File "C:\Users\bonjour\AppData\Local\Programs\Python\Python39\lib\site-packages\_pytest\main.py", line 348, in pytest_runtestloop
    item.config.hook.pytest_runtest_protocol(item=item, nextitem=nextitem)
  File "C:\Users\bonjour\AppData\Local\Programs\Python\Python39\lib\site-packages\pluggy\_hooks.py", line 265, in __call__
    return self._hookexec(self.name, self.get_hookimpls(), kwargs, firstresult)
  File "C:\Users\bonjour\AppData\Local\Programs\Python\Python39\lib\site-packages\pluggy\_manager.py", line 80, in _hookexec
    return self._inner_hookexec(hook_name, methods, kwargs, firstresult)
  File "C:\Users\bonjour\AppData\Local\Programs\Python\Python39\lib\site-packages\pluggy\_callers.py", line 39, in _multicall
    res = hook_impl.function(*args)
  File "c:\users\bonjour\appdata\local\programs\python\python39\lib\site-packages\pytest_rerunfailures.py", line 497, in pytest_runtest_protocol
    reports = runtestprotocol(item, nextitem=nextitem, log=False)
  File "C:\Users\bonjour\AppData\Local\Programs\Python\Python39\lib\site-packages\_pytest\runner.py", line 126, in runtestprotocol
    reports.append(call_and_report(item, "call", log))
  File "C:\Users\bonjour\AppData\Local\Programs\Python\Python39\lib\site-packages\_pytest\runner.py", line 215, in call_and_report
    call = call_runtest_hook(item, when, **kwds)
  File "C:\Users\bonjour\AppData\Local\Programs\Python\Python39\lib\site-packages\_pytest\runner.py", line 254, in call_runtest_hook
    return CallInfo.from_call(
  File "C:\Users\bonjour\AppData\Local\Programs\Python\Python39\lib\site-packages\_pytest\runner.py", line 311, in from_call
    result: Optional[TResult] = func()
  File "C:\Users\bonjour\AppData\Local\Programs\Python\Python39\lib\site-packages\_pytest\runner.py", line 255, in <lambda>
    lambda: ihook(item=item, **kwds), when=when, reraise=reraise
  File "C:\Users\bonjour\AppData\Local\Programs\Python\Python39\lib\site-packages\pluggy\_hooks.py", line 265, in __call__
    return self._hookexec(self.name, self.get_hookimpls(), kwargs, firstresult)
  File "C:\Users\bonjour\AppData\Local\Programs\Python\Python39\lib\site-packages\pluggy\_manager.py", line 80, in _hookexec
    return self._inner_hookexec(hook_name, methods, kwargs, firstresult)
  File "C:\Users\bonjour\AppData\Local\Programs\Python\Python39\lib\site-packages\pluggy\_callers.py", line 39, in _multicall
    res = hook_impl.function(*args)
  File "C:\Users\bonjour\AppData\Local\Programs\Python\Python39\lib\site-packages\_pytest\runner.py", line 162, in pytest_runtest_call
    item.runtest()
  File "C:\Users\bonjour\AppData\Local\Programs\Python\Python39\lib\site-packages\_pytest\python.py", line 1641, in runtest
    self.ihook.pytest_pyfunc_call(pyfuncitem=self)
  File "C:\Users\bonjour\AppData\Local\Programs\Python\Python39\lib\site-packages\pluggy\_hooks.py", line 265, in __call__
    return self._hookexec(self.name, self.get_hookimpls(), kwargs, firstresult)
  File "C:\Users\bonjour\AppData\Local\Programs\Python\Python39\lib\site-packages\pluggy\_manager.py", line 80, in _hookexec
    return self._inner_hookexec(hook_name, methods, kwargs, firstresult)
  File "C:\Users\bonjour\AppData\Local\Programs\Python\Python39\lib\site-packages\pluggy\_callers.py", line 39, in _multicall
    res = hook_impl.function(*args)
  File "C:\Users\bonjour\AppData\Local\Programs\Python\Python39\lib\site-packages\_pytest\python.py", line 183, in pytest_pyfunc_call
    result = testfunction(**testargs)
  File "E:\12\TestCase\test_request.py", line 42, in test_001
    requestdata=RequestsHandler().patch_Req(url=final_data[2]['url'],params="",headers=header_list,json=final_data[2]['bodys'],data="")
  File ".\Common\requestbase.py", line 74, in patch_Req
    self.logger.info(f'等待接口"{url}"时长:{end - start}')
Message: '等待接口"https://supplychain-server-stg.jmj1995.com/items/1/belongingStandardAlternativeItemGroup"时长:0:00:00.054853'
Arguments: ()
2022-01-28 16:06:18,559 - INFO requestbase.py [line:74]: 等待接口"https://supplychain-server-stg.jmj1995.com/items/1/belongingStandardAlternativeItemGroup"时长:0:00:00.054853
2022-01-28 16:06:18,559 - INFO requestbase.py [line:74]: 等待接口"https://supplychain-server-stg.jmj1995.com/items/1/belongingStandardAlternativeItemGroup"时长:0:00:00.054853
2022-01-28 16:06:18,559 - INFO requestbase.py [line:74]: 等待接口"https://supplychain-server-stg.jmj1995.com/items/1/belongingStandardAlternativeItemGroup"时长:0:00:00.054853
2022-01-28 16:06:18,559 - INFO requestbase.py [line:74]: 等待接口"https://supplychain-server-stg.jmj1995.com/items/1/belongingStandardAlternativeItemGroup"时长:0:00:00.054853
2022-01-28 16:06:18,559 - INFO requestbase.py [line:74]: 等待接口"https://supplychain-server-stg.jmj1995.com/items/1/belongingStandardAlternativeItemGroup"时长:0:00:00.054853
--- Logging error ---
Traceback (most recent call last):
  File "C:\Users\bonjour\AppData\Local\Programs\Python\Python39\lib\logging\__init__.py", line 1082, in emit
    stream.write(msg + self.terminator)
OSError: [WinError 6] 句柄无效。
Call stack:
  File "e:\12\TestCase\test_request.py", line 57, in <module>
    pytest.main(["--alluredir", report_path])
  File "C:\Users\bonjour\AppData\Local\Programs\Python\Python39\lib\site-packages\_pytest\config\__init__.py", line 162, in main
    ret: Union[ExitCode, int] = config.hook.pytest_cmdline_main(
  File "C:\Users\bonjour\AppData\Local\Programs\Python\Python39\lib\site-packages\pluggy\_hooks.py", line 265, in __call__
    return self._hookexec(self.name, self.get_hookimpls(), kwargs, firstresult)
  File "C:\Users\bonjour\AppData\Local\Programs\Python\Python39\lib\site-packages\pluggy\_manager.py", line 80, in _hookexec
    return self._inner_hookexec(hook_name, methods, kwargs, firstresult)
  File "C:\Users\bonjour\AppData\Local\Programs\Python\Python39\lib\site-packages\pluggy\_callers.py", line 39, in _multicall
    res = hook_impl.function(*args)
  File "C:\Users\bonjour\AppData\Local\Programs\Python\Python39\lib\site-packages\_pytest\main.py", line 316, in pytest_cmdline_main
    return wrap_session(config, _main)
  File "C:\Users\bonjour\AppData\Local\Programs\Python\Python39\lib\site-packages\_pytest\main.py", line 269, in wrap_session
    session.exitstatus = doit(config, session) or 0
  File "C:\Users\bonjour\AppData\Local\Programs\Python\Python39\lib\site-packages\_pytest\main.py", line 323, in _main
    config.hook.pytest_runtestloop(session=session)
  File "C:\Users\bonjour\AppData\Local\Programs\Python\Python39\lib\site-packages\pluggy\_hooks.py", line 265, in __call__
    return self._hookexec(self.name, self.get_hookimpls(), kwargs, firstresult)
  File "C:\Users\bonjour\AppData\Local\Programs\Python\Python39\lib\site-packages\pluggy\_manager.py", line 80, in _hookexec
    return self._inner_hookexec(hook_name, methods, kwargs, firstresult)
  File "C:\Users\bonjour\AppData\Local\Programs\Python\Python39\lib\site-packages\pluggy\_callers.py", line 39, in _multicall
    res = hook_impl.function(*args)
  File "C:\Users\bonjour\AppData\Local\Programs\Python\Python39\lib\site-packages\_pytest\main.py", line 348, in pytest_runtestloop
    item.config.hook.pytest_runtest_protocol(item=item, nextitem=nextitem)
  File "C:\Users\bonjour\AppData\Local\Programs\Python\Python39\lib\site-packages\pluggy\_hooks.py", line 265, in __call__
    return self._hookexec(self.name, self.get_hookimpls(), kwargs, firstresult)
  File "C:\Users\bonjour\AppData\Local\Programs\Python\Python39\lib\site-packages\pluggy\_manager.py", line 80, in _hookexec
    return self._inner_hookexec(hook_name, methods, kwargs, firstresult)
  File "C:\Users\bonjour\AppData\Local\Programs\Python\Python39\lib\site-packages\pluggy\_callers.py", line 39, in _multicall
    res = hook_impl.function(*args)
  File "c:\users\bonjour\appdata\local\programs\python\python39\lib\site-packages\pytest_rerunfailures.py", line 497, in pytest_runtest_protocol
    reports = runtestprotocol(item, nextitem=nextitem, log=False)
  File "C:\Users\bonjour\AppData\Local\Programs\Python\Python39\lib\site-packages\_pytest\runner.py", line 126, in runtestprotocol
    reports.append(call_and_report(item, "call", log))
  File "C:\Users\bonjour\AppData\Local\Programs\Python\Python39\lib\site-packages\_pytest\runner.py", line 215, in call_and_report
    call = call_runtest_hook(item, when, **kwds)
  File "C:\Users\bonjour\AppData\Local\Programs\Python\Python39\lib\site-packages\_pytest\runner.py", line 254, in call_runtest_hook
    return CallInfo.from_call(
  File "C:\Users\bonjour\AppData\Local\Programs\Python\Python39\lib\site-packages\_pytest\runner.py", line 311, in from_call
    result: Optional[TResult] = func()
  File "C:\Users\bonjour\AppData\Local\Programs\Python\Python39\lib\site-packages\_pytest\runner.py", line 255, in <lambda>
    lambda: ihook(item=item, **kwds), when=when, reraise=reraise
  File "C:\Users\bonjour\AppData\Local\Programs\Python\Python39\lib\site-packages\pluggy\_hooks.py", line 265, in __call__
    return self._hookexec(self.name, self.get_hookimpls(), kwargs, firstresult)
  File "C:\Users\bonjour\AppData\Local\Programs\Python\Python39\lib\site-packages\pluggy\_manager.py", line 80, in _hookexec
    return self._inner_hookexec(hook_name, methods, kwargs, firstresult)
  File "C:\Users\bonjour\AppData\Local\Programs\Python\Python39\lib\site-packages\pluggy\_callers.py", line 39, in _multicall
    res = hook_impl.function(*args)
  File "C:\Users\bonjour\AppData\Local\Programs\Python\Python39\lib\site-packages\_pytest\runner.py", line 162, in pytest_runtest_call
    item.runtest()
  File "C:\Users\bonjour\AppData\Local\Programs\Python\Python39\lib\site-packages\_pytest\python.py", line 1641, in runtest
    self.ihook.pytest_pyfunc_call(pyfuncitem=self)
  File "C:\Users\bonjour\AppData\Local\Programs\Python\Python39\lib\site-packages\pluggy\_hooks.py", line 265, in __call__
    return self._hookexec(self.name, self.get_hookimpls(), kwargs, firstresult)
  File "C:\Users\bonjour\AppData\Local\Programs\Python\Python39\lib\site-packages\pluggy\_manager.py", line 80, in _hookexec
    return self._inner_hookexec(hook_name, methods, kwargs, firstresult)
  File "C:\Users\bonjour\AppData\Local\Programs\Python\Python39\lib\site-packages\pluggy\_callers.py", line 39, in _multicall
    res = hook_impl.function(*args)
  File "C:\Users\bonjour\AppData\Local\Programs\Python\Python39\lib\site-packages\_pytest\python.py", line 183, in pytest_pyfunc_call
    result = testfunction(**testargs)
  File "E:\12\TestCase\test_request.py", line 43, in test_001
    asser.assert_code(final_data[2]['status_code'],requestdata.status_code)
  File ".\Common\assertbase.py", line 28, in assert_code
    self.logger.info(f'预计接口返回code为"{code}",实际返回code为:"{url_code}"')
Message: '预计接口返回code为"200.0",实际返回code为:"405"'
Arguments: ()
--- Logging error ---
Traceback (most recent call last):
  File "C:\Users\bonjour\AppData\Local\Programs\Python\Python39\lib\logging\__init__.py", line 1082, in emit
    stream.write(msg + self.terminator)
OSError: [WinError 6] 句柄无效。
Call stack:
  File "e:\12\TestCase\test_request.py", line 57, in <module>
    pytest.main(["--alluredir", report_path])
  File "C:\Users\bonjour\AppData\Local\Programs\Python\Python39\lib\site-packages\_pytest\config\__init__.py", line 162, in main
    ret: Union[ExitCode, int] = config.hook.pytest_cmdline_main(
  File "C:\Users\bonjour\AppData\Local\Programs\Python\Python39\lib\site-packages\pluggy\_hooks.py", line 265, in __call__
    return self._hookexec(self.name, self.get_hookimpls(), kwargs, firstresult)
  File "C:\Users\bonjour\AppData\Local\Programs\Python\Python39\lib\site-packages\pluggy\_manager.py", line 80, in _hookexec
    return self._inner_hookexec(hook_name, methods, kwargs, firstresult)
  File "C:\Users\bonjour\AppData\Local\Programs\Python\Python39\lib\site-packages\pluggy\_callers.py", line 39, in _multicall
    res = hook_impl.function(*args)
  File "C:\Users\bonjour\AppData\Local\Programs\Python\Python39\lib\site-packages\_pytest\main.py", line 316, in pytest_cmdline_main
    return wrap_session(config, _main)
  File "C:\Users\bonjour\AppData\Local\Programs\Python\Python39\lib\site-packages\_pytest\main.py", line 269, in wrap_session
    session.exitstatus = doit(config, session) or 0
  File "C:\Users\bonjour\AppData\Local\Programs\Python\Python39\lib\site-packages\_pytest\main.py", line 323, in _main
    config.hook.pytest_runtestloop(session=session)
  File "C:\Users\bonjour\AppData\Local\Programs\Python\Python39\lib\site-packages\pluggy\_hooks.py", line 265, in __call__
    return self._hookexec(self.name, self.get_hookimpls(), kwargs, firstresult)
  File "C:\Users\bonjour\AppData\Local\Programs\Python\Python39\lib\site-packages\pluggy\_manager.py", line 80, in _hookexec
    return self._inner_hookexec(hook_name, methods, kwargs, firstresult)
  File "C:\Users\bonjour\AppData\Local\Programs\Python\Python39\lib\site-packages\pluggy\_callers.py", line 39, in _multicall
    res = hook_impl.function(*args)
  File "C:\Users\bonjour\AppData\Local\Programs\Python\Python39\lib\site-packages\_pytest\main.py", line 348, in pytest_runtestloop
    item.config.hook.pytest_runtest_protocol(item=item, nextitem=nextitem)
  File "C:\Users\bonjour\AppData\Local\Programs\Python\Python39\lib\site-packages\pluggy\_hooks.py", line 265, in __call__
    return self._hookexec(self.name, self.get_hookimpls(), kwargs, firstresult)
  File "C:\Users\bonjour\AppData\Local\Programs\Python\Python39\lib\site-packages\pluggy\_manager.py", line 80, in _hookexec
    return self._inner_hookexec(hook_name, methods, kwargs, firstresult)
  File "C:\Users\bonjour\AppData\Local\Programs\Python\Python39\lib\site-packages\pluggy\_callers.py", line 39, in _multicall
    res = hook_impl.function(*args)
  File "c:\users\bonjour\appdata\local\programs\python\python39\lib\site-packages\pytest_rerunfailures.py", line 497, in pytest_runtest_protocol
    reports = runtestprotocol(item, nextitem=nextitem, log=False)
  File "C:\Users\bonjour\AppData\Local\Programs\Python\Python39\lib\site-packages\_pytest\runner.py", line 126, in runtestprotocol
    reports.append(call_and_report(item, "call", log))
  File "C:\Users\bonjour\AppData\Local\Programs\Python\Python39\lib\site-packages\_pytest\runner.py", line 215, in call_and_report
    call = call_runtest_hook(item, when, **kwds)
  File "C:\Users\bonjour\AppData\Local\Programs\Python\Python39\lib\site-packages\_pytest\runner.py", line 254, in call_runtest_hook
    return CallInfo.from_call(
  File "C:\Users\bonjour\AppData\Local\Programs\Python\Python39\lib\site-packages\_pytest\runner.py", line 311, in from_call
    result: Optional[TResult] = func()
  File "C:\Users\bonjour\AppData\Local\Programs\Python\Python39\lib\site-packages\_pytest\runner.py", line 255, in <lambda>
    lambda: ihook(item=item, **kwds), when=when, reraise=reraise
  File "C:\Users\bonjour\AppData\Local\Programs\Python\Python39\lib\site-packages\pluggy\_hooks.py", line 265, in __call__
    return self._hookexec(self.name, self.get_hookimpls(), kwargs, firstresult)
  File "C:\Users\bonjour\AppData\Local\Programs\Python\Python39\lib\site-packages\pluggy\_manager.py", line 80, in _hookexec
    return self._inner_hookexec(hook_name, methods, kwargs, firstresult)
  File "C:\Users\bonjour\AppData\Local\Programs\Python\Python39\lib\site-packages\pluggy\_callers.py", line 39, in _multicall
    res = hook_impl.function(*args)
  File "C:\Users\bonjour\AppData\Local\Programs\Python\Python39\lib\site-packages\_pytest\runner.py", line 162, in pytest_runtest_call
    item.runtest()
  File "C:\Users\bonjour\AppData\Local\Programs\Python\Python39\lib\site-packages\_pytest\python.py", line 1641, in runtest
    self.ihook.pytest_pyfunc_call(pyfuncitem=self)
  File "C:\Users\bonjour\AppData\Local\Programs\Python\Python39\lib\site-packages\pluggy\_hooks.py", line 265, in __call__
    return self._hookexec(self.name, self.get_hookimpls(), kwargs, firstresult)
  File "C:\Users\bonjour\AppData\Local\Programs\Python\Python39\lib\site-packages\pluggy\_manager.py", line 80, in _hookexec
    return self._inner_hookexec(hook_name, methods, kwargs, firstresult)
  File "C:\Users\bonjour\AppData\Local\Programs\Python\Python39\lib\site-packages\pluggy\_callers.py", line 39, in _multicall
    res = hook_impl.function(*args)
  File "C:\Users\bonjour\AppData\Local\Programs\Python\Python39\lib\site-packages\_pytest\python.py", line 183, in pytest_pyfunc_call
    result = testfunction(**testargs)
  File "E:\12\TestCase\test_request.py", line 43, in test_001
    asser.assert_code(final_data[2]['status_code'],requestdata.status_code)
  File ".\Common\assertbase.py", line 28, in assert_code
    self.logger.info(f'预计接口返回code为"{code}",实际返回code为:"{url_code}"')
Message: '预计接口返回code为"200.0",实际返回code为:"405"'
Arguments: ()
2022-01-28 16:06:18,561 - INFO assertbase.py [line:28]: 预计接口返回code为"200.0",实际返回code为:"405"
2022-01-28 16:06:18,561 - INFO assertbase.py [line:28]: 预计接口返回code为"200.0",实际返回code为:"405"
2022-01-28 16:06:18,561 - INFO assertbase.py [line:28]: 预计接口返回code为"200.0",实际返回code为:"405"
2022-01-28 16:06:18,561 - INFO assertbase.py [line:28]: 预计接口返回code为"200.0",实际返回code为:"405"
2022-01-28 16:06:18,561 - INFO assertbase.py [line:28]: 预计接口返回code为"200.0",实际返回code为:"405"
--- Logging error ---
Traceback (most recent call last):
  File ".\Common\assertbase.py", line 30, in assert_code
    assert code == url_code
AssertionError

During handling of the above exception, another exception occurred:

Traceback (most recent call last):
  File "C:\Users\bonjour\AppData\Local\Programs\Python\Python39\lib\logging\__init__.py", line 1082, in emit
    stream.write(msg + self.terminator)
OSError: [WinError 6] 句柄无效。
Call stack:
  File "e:\12\TestCase\test_request.py", line 57, in <module>
    pytest.main(["--alluredir", report_path])
  File "C:\Users\bonjour\AppData\Local\Programs\Python\Python39\lib\site-packages\_pytest\config\__init__.py", line 162, in main
    ret: Union[ExitCode, int] = config.hook.pytest_cmdline_main(
  File "C:\Users\bonjour\AppData\Local\Programs\Python\Python39\lib\site-packages\pluggy\_hooks.py", line 265, in __call__
    return self._hookexec(self.name, self.get_hookimpls(), kwargs, firstresult)
  File "C:\Users\bonjour\AppData\Local\Programs\Python\Python39\lib\site-packages\pluggy\_manager.py", line 80, in _hookexec
    return self._inner_hookexec(hook_name, methods, kwargs, firstresult)
  File "C:\Users\bonjour\AppData\Local\Programs\Python\Python39\lib\site-packages\pluggy\_callers.py", line 39, in _multicall
    res = hook_impl.function(*args)
  File "C:\Users\bonjour\AppData\Local\Programs\Python\Python39\lib\site-packages\_pytest\main.py", line 316, in pytest_cmdline_main
    return wrap_session(config, _main)
  File "C:\Users\bonjour\AppData\Local\Programs\Python\Python39\lib\site-packages\_pytest\main.py", line 269, in wrap_session
    session.exitstatus = doit(config, session) or 0
  File "C:\Users\bonjour\AppData\Local\Programs\Python\Python39\lib\site-packages\_pytest\main.py", line 323, in _main
    config.hook.pytest_runtestloop(session=session)
  File "C:\Users\bonjour\AppData\Local\Programs\Python\Python39\lib\site-packages\pluggy\_hooks.py", line 265, in __call__
    return self._hookexec(self.name, self.get_hookimpls(), kwargs, firstresult)
  File "C:\Users\bonjour\AppData\Local\Programs\Python\Python39\lib\site-packages\pluggy\_manager.py", line 80, in _hookexec
    return self._inner_hookexec(hook_name, methods, kwargs, firstresult)
  File "C:\Users\bonjour\AppData\Local\Programs\Python\Python39\lib\site-packages\pluggy\_callers.py", line 39, in _multicall
    res = hook_impl.function(*args)
  File "C:\Users\bonjour\AppData\Local\Programs\Python\Python39\lib\site-packages\_pytest\main.py", line 348, in pytest_runtestloop
    item.config.hook.pytest_runtest_protocol(item=item, nextitem=nextitem)
  File "C:\Users\bonjour\AppData\Local\Programs\Python\Python39\lib\site-packages\pluggy\_hooks.py", line 265, in __call__
    return self._hookexec(self.name, self.get_hookimpls(), kwargs, firstresult)
  File "C:\Users\bonjour\AppData\Local\Programs\Python\Python39\lib\site-packages\pluggy\_manager.py", line 80, in _hookexec
    return self._inner_hookexec(hook_name, methods, kwargs, firstresult)
  File "C:\Users\bonjour\AppData\Local\Programs\Python\Python39\lib\site-packages\pluggy\_callers.py", line 39, in _multicall
    res = hook_impl.function(*args)
  File "c:\users\bonjour\appdata\local\programs\python\python39\lib\site-packages\pytest_rerunfailures.py", line 497, in pytest_runtest_protocol
    reports = runtestprotocol(item, nextitem=nextitem, log=False)
  File "C:\Users\bonjour\AppData\Local\Programs\Python\Python39\lib\site-packages\_pytest\runner.py", line 126, in runtestprotocol
    reports.append(call_and_report(item, "call", log))
  File "C:\Users\bonjour\AppData\Local\Programs\Python\Python39\lib\site-packages\_pytest\runner.py", line 215, in call_and_report
    call = call_runtest_hook(item, when, **kwds)
  File "C:\Users\bonjour\AppData\Local\Programs\Python\Python39\lib\site-packages\_pytest\runner.py", line 254, in call_runtest_hook
    return CallInfo.from_call(
  File "C:\Users\bonjour\AppData\Local\Programs\Python\Python39\lib\site-packages\_pytest\runner.py", line 311, in from_call
    result: Optional[TResult] = func()
  File "C:\Users\bonjour\AppData\Local\Programs\Python\Python39\lib\site-packages\_pytest\runner.py", line 255, in <lambda>
    lambda: ihook(item=item, **kwds), when=when, reraise=reraise
  File "C:\Users\bonjour\AppData\Local\Programs\Python\Python39\lib\site-packages\pluggy\_hooks.py", line 265, in __call__
    return self._hookexec(self.name, self.get_hookimpls(), kwargs, firstresult)
  File "C:\Users\bonjour\AppData\Local\Programs\Python\Python39\lib\site-packages\pluggy\_manager.py", line 80, in _hookexec
    return self._inner_hookexec(hook_name, methods, kwargs, firstresult)
  File "C:\Users\bonjour\AppData\Local\Programs\Python\Python39\lib\site-packages\pluggy\_callers.py", line 39, in _multicall
    res = hook_impl.function(*args)
  File "C:\Users\bonjour\AppData\Local\Programs\Python\Python39\lib\site-packages\_pytest\runner.py", line 162, in pytest_runtest_call
    item.runtest()
  File "C:\Users\bonjour\AppData\Local\Programs\Python\Python39\lib\site-packages\_pytest\python.py", line 1641, in runtest
    self.ihook.pytest_pyfunc_call(pyfuncitem=self)
  File "C:\Users\bonjour\AppData\Local\Programs\Python\Python39\lib\site-packages\pluggy\_hooks.py", line 265, in __call__
    return self._hookexec(self.name, self.get_hookimpls(), kwargs, firstresult)
  File "C:\Users\bonjour\AppData\Local\Programs\Python\Python39\lib\site-packages\pluggy\_manager.py", line 80, in _hookexec
    return self._inner_hookexec(hook_name, methods, kwargs, firstresult)
  File "C:\Users\bonjour\AppData\Local\Programs\Python\Python39\lib\site-packages\pluggy\_callers.py", line 39, in _multicall
    res = hook_impl.function(*args)
  File "C:\Users\bonjour\AppData\Local\Programs\Python\Python39\lib\site-packages\_pytest\python.py", line 183, in pytest_pyfunc_call
    result = testfunction(**testargs)
  File "E:\12\TestCase\test_request.py", line 43, in test_001
    asser.assert_code(final_data[2]['status_code'],requestdata.status_code)
  File ".\Common\assertbase.py", line 33, in assert_code
    self.logger.error(f'预计接口返回code为"{code}",实际返回code为:"{url_code}",失败')
Message: '预计接口返回code为"200.0",实际返回code为:"405",失败'
Arguments: ()
--- Logging error ---
Traceback (most recent call last):
  File ".\Common\assertbase.py", line 30, in assert_code
    assert code == url_code
AssertionError

During handling of the above exception, another exception occurred:

Traceback (most recent call last):
  File "C:\Users\bonjour\AppData\Local\Programs\Python\Python39\lib\logging\__init__.py", line 1082, in emit
    stream.write(msg + self.terminator)
OSError: [WinError 6] 句柄无效。
Call stack:
  File "e:\12\TestCase\test_request.py", line 57, in <module>
    pytest.main(["--alluredir", report_path])
  File "C:\Users\bonjour\AppData\Local\Programs\Python\Python39\lib\site-packages\_pytest\config\__init__.py", line 162, in main
    ret: Union[ExitCode, int] = config.hook.pytest_cmdline_main(
  File "C:\Users\bonjour\AppData\Local\Programs\Python\Python39\lib\site-packages\pluggy\_hooks.py", line 265, in __call__
    return self._hookexec(self.name, self.get_hookimpls(), kwargs, firstresult)
  File "C:\Users\bonjour\AppData\Local\Programs\Python\Python39\lib\site-packages\pluggy\_manager.py", line 80, in _hookexec
    return self._inner_hookexec(hook_name, methods, kwargs, firstresult)
  File "C:\Users\bonjour\AppData\Local\Programs\Python\Python39\lib\site-packages\pluggy\_callers.py", line 39, in _multicall
    res = hook_impl.function(*args)
  File "C:\Users\bonjour\AppData\Local\Programs\Python\Python39\lib\site-packages\_pytest\main.py", line 316, in pytest_cmdline_main
    return wrap_session(config, _main)
  File "C:\Users\bonjour\AppData\Local\Programs\Python\Python39\lib\site-packages\_pytest\main.py", line 269, in wrap_session
    session.exitstatus = doit(config, session) or 0
  File "C:\Users\bonjour\AppData\Local\Programs\Python\Python39\lib\site-packages\_pytest\main.py", line 323, in _main
    config.hook.pytest_runtestloop(session=session)
  File "C:\Users\bonjour\AppData\Local\Programs\Python\Python39\lib\site-packages\pluggy\_hooks.py", line 265, in __call__
    return self._hookexec(self.name, self.get_hookimpls(), kwargs, firstresult)
  File "C:\Users\bonjour\AppData\Local\Programs\Python\Python39\lib\site-packages\pluggy\_manager.py", line 80, in _hookexec
    return self._inner_hookexec(hook_name, methods, kwargs, firstresult)
  File "C:\Users\bonjour\AppData\Local\Programs\Python\Python39\lib\site-packages\pluggy\_callers.py", line 39, in _multicall
    res = hook_impl.function(*args)
  File "C:\Users\bonjour\AppData\Local\Programs\Python\Python39\lib\site-packages\_pytest\main.py", line 348, in pytest_runtestloop
    item.config.hook.pytest_runtest_protocol(item=item, nextitem=nextitem)
  File "C:\Users\bonjour\AppData\Local\Programs\Python\Python39\lib\site-packages\pluggy\_hooks.py", line 265, in __call__
    return self._hookexec(self.name, self.get_hookimpls(), kwargs, firstresult)
  File "C:\Users\bonjour\AppData\Local\Programs\Python\Python39\lib\site-packages\pluggy\_manager.py", line 80, in _hookexec
    return self._inner_hookexec(hook_name, methods, kwargs, firstresult)
  File "C:\Users\bonjour\AppData\Local\Programs\Python\Python39\lib\site-packages\pluggy\_callers.py", line 39, in _multicall
    res = hook_impl.function(*args)
  File "c:\users\bonjour\appdata\local\programs\python\python39\lib\site-packages\pytest_rerunfailures.py", line 497, in pytest_runtest_protocol
    reports = runtestprotocol(item, nextitem=nextitem, log=False)
  File "C:\Users\bonjour\AppData\Local\Programs\Python\Python39\lib\site-packages\_pytest\runner.py", line 126, in runtestprotocol
    reports.append(call_and_report(item, "call", log))
  File "C:\Users\bonjour\AppData\Local\Programs\Python\Python39\lib\site-packages\_pytest\runner.py", line 215, in call_and_report
    call = call_runtest_hook(item, when, **kwds)
  File "C:\Users\bonjour\AppData\Local\Programs\Python\Python39\lib\site-packages\_pytest\runner.py", line 254, in call_runtest_hook
    return CallInfo.from_call(
  File "C:\Users\bonjour\AppData\Local\Programs\Python\Python39\lib\site-packages\_pytest\runner.py", line 311, in from_call
    result: Optional[TResult] = func()
  File "C:\Users\bonjour\AppData\Local\Programs\Python\Python39\lib\site-packages\_pytest\runner.py", line 255, in <lambda>
    lambda: ihook(item=item, **kwds), when=when, reraise=reraise
  File "C:\Users\bonjour\AppData\Local\Programs\Python\Python39\lib\site-packages\pluggy\_hooks.py", line 265, in __call__
    return self._hookexec(self.name, self.get_hookimpls(), kwargs, firstresult)
  File "C:\Users\bonjour\AppData\Local\Programs\Python\Python39\lib\site-packages\pluggy\_manager.py", line 80, in _hookexec
    return self._inner_hookexec(hook_name, methods, kwargs, firstresult)
  File "C:\Users\bonjour\AppData\Local\Programs\Python\Python39\lib\site-packages\pluggy\_callers.py", line 39, in _multicall
    res = hook_impl.function(*args)
  File "C:\Users\bonjour\AppData\Local\Programs\Python\Python39\lib\site-packages\_pytest\runner.py", line 162, in pytest_runtest_call
    item.runtest()
  File "C:\Users\bonjour\AppData\Local\Programs\Python\Python39\lib\site-packages\_pytest\python.py", line 1641, in runtest
    self.ihook.pytest_pyfunc_call(pyfuncitem=self)
  File "C:\Users\bonjour\AppData\Local\Programs\Python\Python39\lib\site-packages\pluggy\_hooks.py", line 265, in __call__
    return self._hookexec(self.name, self.get_hookimpls(), kwargs, firstresult)
  File "C:\Users\bonjour\AppData\Local\Programs\Python\Python39\lib\site-packages\pluggy\_manager.py", line 80, in _hookexec
    return self._inner_hookexec(hook_name, methods, kwargs, firstresult)
  File "C:\Users\bonjour\AppData\Local\Programs\Python\Python39\lib\site-packages\pluggy\_callers.py", line 39, in _multicall
    res = hook_impl.function(*args)
  File "C:\Users\bonjour\AppData\Local\Programs\Python\Python39\lib\site-packages\_pytest\python.py", line 183, in pytest_pyfunc_call
    result = testfunction(**testargs)
  File "E:\12\TestCase\test_request.py", line 43, in test_001
    asser.assert_code(final_data[2]['status_code'],requestdata.status_code)
  File ".\Common\assertbase.py", line 33, in assert_code
    self.logger.error(f'预计接口返回code为"{code}",实际返回code为:"{url_code}",失败')
Message: '预计接口返回code为"200.0",实际返回code为:"405",失败'
Arguments: ()
2022-01-28 16:06:18,564 - ERROR assertbase.py [line:33]: 预计接口返回code为"200.0",实际返回code为:"405",失败
2022-01-28 16:06:18,564 - ERROR assertbase.py [line:33]: 预计接口返回code为"200.0",实际返回code为:"405",失败
2022-01-28 16:06:18,564 - ERROR assertbase.py [line:33]: 预计接口返回code为"200.0",实际返回code为:"405",失败
2022-01-28 16:06:18,564 - ERROR assertbase.py [line:33]: 预计接口返回code为"200.0",实际返回code为:"405",失败
2022-01-28 16:06:18,564 - ERROR assertbase.py [line:33]: 预计接口返回code为"200.0",实际返回code为:"405",失败
