--- Logging error ---
Traceback (most recent call last):
  File "C:\Users\bonjour\AppData\Local\Programs\Python\Python39\lib\logging\__init__.py", line 1082, in emit
    stream.write(msg + self.terminator)
OSError: [WinError 6] 句柄无效。
Call stack:
  File "e:\12\TestCase\test_request.py", line 59, in <module>
    pytest.main(["--alluredir", report_path])
  File "C:\Users\bonjour\AppData\Local\Programs\Python\Python39\lib\site-packages\_pytest\config\__init__.py", line 162, in main
    ret: Union[ExitCode, int] = config.hook.pytest_cmdline_main(
  File "C:\Users\bonjour\AppData\Local\Programs\Python\Python39\lib\site-packages\pluggy\_hooks.py", line 265, in __call__
    return self._hookexec(self.name, self.get_hookimpls(), kwargs, firstresult)
  File "C:\Users\bonjour\AppData\Local\Programs\Python\Python39\lib\site-packages\pluggy\_manager.py", line 80, in _hookexec
    return self._inner_hookexec(hook_name, methods, kwargs, firstresult)
  File "C:\Users\bonjour\AppData\Local\Programs\Python\Python39\lib\site-packages\pluggy\_callers.py", line 39, in _multicall
    res = hook_impl.function(*args)
  File "C:\Users\bonjour\AppData\Local\Programs\Python\Python39\lib\site-packages\_pytest\main.py", line 316, in pytest_cmdline_main
    return wrap_session(config, _main)
  File "C:\Users\bonjour\AppData\Local\Programs\Python\Python39\lib\site-packages\_pytest\main.py", line 269, in wrap_session
    session.exitstatus = doit(config, session) or 0
  File "C:\Users\bonjour\AppData\Local\Programs\Python\Python39\lib\site-packages\_pytest\main.py", line 323, in _main
    config.hook.pytest_runtestloop(session=session)
  File "C:\Users\bonjour\AppData\Local\Programs\Python\Python39\lib\site-packages\pluggy\_hooks.py", line 265, in __call__
    return self._hookexec(self.name, self.get_hookimpls(), kwargs, firstresult)
  File "C:\Users\bonjour\AppData\Local\Programs\Python\Python39\lib\site-packages\pluggy\_manager.py", line 80, in _hookexec
    return self._inner_hookexec(hook_name, methods, kwargs, firstresult)
  File "C:\Users\bonjour\AppData\Local\Programs\Python\Python39\lib\site-packages\pluggy\_callers.py", line 39, in _multicall
    res = hook_impl.function(*args)
  File "C:\Users\bonjour\AppData\Local\Programs\Python\Python39\lib\site-packages\_pytest\main.py", line 348, in pytest_runtestloop
    item.config.hook.pytest_runtest_protocol(item=item, nextitem=nextitem)
  File "C:\Users\bonjour\AppData\Local\Programs\Python\Python39\lib\site-packages\pluggy\_hooks.py", line 265, in __call__
    return self._hookexec(self.name, self.get_hookimpls(), kwargs, firstresult)
  File "C:\Users\bonjour\AppData\Local\Programs\Python\Python39\lib\site-packages\pluggy\_manager.py", line 80, in _hookexec
    return self._inner_hookexec(hook_name, methods, kwargs, firstresult)
  File "C:\Users\bonjour\AppData\Local\Programs\Python\Python39\lib\site-packages\pluggy\_callers.py", line 39, in _multicall
    res = hook_impl.function(*args)
  File "c:\users\bonjour\appdata\local\programs\python\python39\lib\site-packages\pytest_rerunfailures.py", line 497, in pytest_runtest_protocol
    reports = runtestprotocol(item, nextitem=nextitem, log=False)
  File "C:\Users\bonjour\AppData\Local\Programs\Python\Python39\lib\site-packages\_pytest\runner.py", line 126, in runtestprotocol
    reports.append(call_and_report(item, "call", log))
  File "C:\Users\bonjour\AppData\Local\Programs\Python\Python39\lib\site-packages\_pytest\runner.py", line 215, in call_and_report
    call = call_runtest_hook(item, when, **kwds)
  File "C:\Users\bonjour\AppData\Local\Programs\Python\Python39\lib\site-packages\_pytest\runner.py", line 254, in call_runtest_hook
    return CallInfo.from_call(
  File "C:\Users\bonjour\AppData\Local\Programs\Python\Python39\lib\site-packages\_pytest\runner.py", line 311, in from_call
    result: Optional[TResult] = func()
  File "C:\Users\bonjour\AppData\Local\Programs\Python\Python39\lib\site-packages\_pytest\runner.py", line 255, in <lambda>
    lambda: ihook(item=item, **kwds), when=when, reraise=reraise
  File "C:\Users\bonjour\AppData\Local\Programs\Python\Python39\lib\site-packages\pluggy\_hooks.py", line 265, in __call__
    return self._hookexec(self.name, self.get_hookimpls(), kwargs, firstresult)
  File "C:\Users\bonjour\AppData\Local\Programs\Python\Python39\lib\site-packages\pluggy\_manager.py", line 80, in _hookexec
    return self._inner_hookexec(hook_name, methods, kwargs, firstresult)
  File "C:\Users\bonjour\AppData\Local\Programs\Python\Python39\lib\site-packages\pluggy\_callers.py", line 39, in _multicall
    res = hook_impl.function(*args)
  File "C:\Users\bonjour\AppData\Local\Programs\Python\Python39\lib\site-packages\_pytest\runner.py", line 162, in pytest_runtest_call
    item.runtest()
  File "C:\Users\bonjour\AppData\Local\Programs\Python\Python39\lib\site-packages\_pytest\python.py", line 1641, in runtest
    self.ihook.pytest_pyfunc_call(pyfuncitem=self)
  File "C:\Users\bonjour\AppData\Local\Programs\Python\Python39\lib\site-packages\pluggy\_hooks.py", line 265, in __call__
    return self._hookexec(self.name, self.get_hookimpls(), kwargs, firstresult)
  File "C:\Users\bonjour\AppData\Local\Programs\Python\Python39\lib\site-packages\pluggy\_manager.py", line 80, in _hookexec
    return self._inner_hookexec(hook_name, methods, kwargs, firstresult)
  File "C:\Users\bonjour\AppData\Local\Programs\Python\Python39\lib\site-packages\pluggy\_callers.py", line 39, in _multicall
    res = hook_impl.function(*args)
  File "C:\Users\bonjour\AppData\Local\Programs\Python\Python39\lib\site-packages\_pytest\python.py", line 183, in pytest_pyfunc_call
    result = testfunction(**testargs)
  File "E:\12\TestCase\test_request.py", line 34, in test_001
    requestdata=RequestsHandler().get_Req(url=final_data[0]['url'],params=eval(final_data[0]['params']),headers=header_list,json="",data="")
  File ".\Common\requestbase.py", line 21, in get_Req
    self.logger.info(f'连通接口"{url}",接口header为:"{headers}",接口param为：{params}')
Message: '连通接口"https://supplychain-server-stg.jmj1995.com/items",接口header为:"{\'authorization\': \'Bearer eyJhbGciOiJIUzUxMiJ9.eyJqdGkiOiIzMTgyNGVlMzU3ODQ0NTU2OTI3NzU4YmI2YWIzZGMwMiIsImF1dGgiOiIiLCJpZCI6NTk2LCJzdWIiOiIxMiJ9.FAMtF8lnItJNt6d8AwlaDTEdY0VPs8rm_iY0Lpmta8OaG-ARUL4vRt-xD1-eCteU8v9QYiJq1kgDrBoOPYuLTw\'}",接口param为：{\'pageNum\': \'1\', \'pageSize\': \'20\'}'
Arguments: ()
--- Logging error ---
Traceback (most recent call last):
  File "C:\Users\bonjour\AppData\Local\Programs\Python\Python39\lib\logging\__init__.py", line 1082, in emit
    stream.write(msg + self.terminator)
OSError: [WinError 6] 句柄无效。
Call stack:
  File "e:\12\TestCase\test_request.py", line 59, in <module>
    pytest.main(["--alluredir", report_path])
  File "C:\Users\bonjour\AppData\Local\Programs\Python\Python39\lib\site-packages\_pytest\config\__init__.py", line 162, in main
    ret: Union[ExitCode, int] = config.hook.pytest_cmdline_main(
  File "C:\Users\bonjour\AppData\Local\Programs\Python\Python39\lib\site-packages\pluggy\_hooks.py", line 265, in __call__
    return self._hookexec(self.name, self.get_hookimpls(), kwargs, firstresult)
  File "C:\Users\bonjour\AppData\Local\Programs\Python\Python39\lib\site-packages\pluggy\_manager.py", line 80, in _hookexec
    return self._inner_hookexec(hook_name, methods, kwargs, firstresult)
  File "C:\Users\bonjour\AppData\Local\Programs\Python\Python39\lib\site-packages\pluggy\_callers.py", line 39, in _multicall
    res = hook_impl.function(*args)
  File "C:\Users\bonjour\AppData\Local\Programs\Python\Python39\lib\site-packages\_pytest\main.py", line 316, in pytest_cmdline_main
    return wrap_session(config, _main)
  File "C:\Users\bonjour\AppData\Local\Programs\Python\Python39\lib\site-packages\_pytest\main.py", line 269, in wrap_session
    session.exitstatus = doit(config, session) or 0
  File "C:\Users\bonjour\AppData\Local\Programs\Python\Python39\lib\site-packages\_pytest\main.py", line 323, in _main
    config.hook.pytest_runtestloop(session=session)
  File "C:\Users\bonjour\AppData\Local\Programs\Python\Python39\lib\site-packages\pluggy\_hooks.py", line 265, in __call__
    return self._hookexec(self.name, self.get_hookimpls(), kwargs, firstresult)
  File "C:\Users\bonjour\AppData\Local\Programs\Python\Python39\lib\site-packages\pluggy\_manager.py", line 80, in _hookexec
    return self._inner_hookexec(hook_name, methods, kwargs, firstresult)
  File "C:\Users\bonjour\AppData\Local\Programs\Python\Python39\lib\site-packages\pluggy\_callers.py", line 39, in _multicall
    res = hook_impl.function(*args)
  File "C:\Users\bonjour\AppData\Local\Programs\Python\Python39\lib\site-packages\_pytest\main.py", line 348, in pytest_runtestloop
    item.config.hook.pytest_runtest_protocol(item=item, nextitem=nextitem)
  File "C:\Users\bonjour\AppData\Local\Programs\Python\Python39\lib\site-packages\pluggy\_hooks.py", line 265, in __call__
    return self._hookexec(self.name, self.get_hookimpls(), kwargs, firstresult)
  File "C:\Users\bonjour\AppData\Local\Programs\Python\Python39\lib\site-packages\pluggy\_manager.py", line 80, in _hookexec
    return self._inner_hookexec(hook_name, methods, kwargs, firstresult)
  File "C:\Users\bonjour\AppData\Local\Programs\Python\Python39\lib\site-packages\pluggy\_callers.py", line 39, in _multicall
    res = hook_impl.function(*args)
  File "c:\users\bonjour\appdata\local\programs\python\python39\lib\site-packages\pytest_rerunfailures.py", line 497, in pytest_runtest_protocol
    reports = runtestprotocol(item, nextitem=nextitem, log=False)
  File "C:\Users\bonjour\AppData\Local\Programs\Python\Python39\lib\site-packages\_pytest\runner.py", line 126, in runtestprotocol
    reports.append(call_and_report(item, "call", log))
  File "C:\Users\bonjour\AppData\Local\Programs\Python\Python39\lib\site-packages\_pytest\runner.py", line 215, in call_and_report
    call = call_runtest_hook(item, when, **kwds)
  File "C:\Users\bonjour\AppData\Local\Programs\Python\Python39\lib\site-packages\_pytest\runner.py", line 254, in call_runtest_hook
    return CallInfo.from_call(
  File "C:\Users\bonjour\AppData\Local\Programs\Python\Python39\lib\site-packages\_pytest\runner.py", line 311, in from_call
    result: Optional[TResult] = func()
  File "C:\Users\bonjour\AppData\Local\Programs\Python\Python39\lib\site-packages\_pytest\runner.py", line 255, in <lambda>
    lambda: ihook(item=item, **kwds), when=when, reraise=reraise
  File "C:\Users\bonjour\AppData\Local\Programs\Python\Python39\lib\site-packages\pluggy\_hooks.py", line 265, in __call__
    return self._hookexec(self.name, self.get_hookimpls(), kwargs, firstresult)
  File "C:\Users\bonjour\AppData\Local\Programs\Python\Python39\lib\site-packages\pluggy\_manager.py", line 80, in _hookexec
    return self._inner_hookexec(hook_name, methods, kwargs, firstresult)
  File "C:\Users\bonjour\AppData\Local\Programs\Python\Python39\lib\site-packages\pluggy\_callers.py", line 39, in _multicall
    res = hook_impl.function(*args)
  File "C:\Users\bonjour\AppData\Local\Programs\Python\Python39\lib\site-packages\_pytest\runner.py", line 162, in pytest_runtest_call
    item.runtest()
  File "C:\Users\bonjour\AppData\Local\Programs\Python\Python39\lib\site-packages\_pytest\python.py", line 1641, in runtest
    self.ihook.pytest_pyfunc_call(pyfuncitem=self)
  File "C:\Users\bonjour\AppData\Local\Programs\Python\Python39\lib\site-packages\pluggy\_hooks.py", line 265, in __call__
    return self._hookexec(self.name, self.get_hookimpls(), kwargs, firstresult)
  File "C:\Users\bonjour\AppData\Local\Programs\Python\Python39\lib\site-packages\pluggy\_manager.py", line 80, in _hookexec
    return self._inner_hookexec(hook_name, methods, kwargs, firstresult)
  File "C:\Users\bonjour\AppData\Local\Programs\Python\Python39\lib\site-packages\pluggy\_callers.py", line 39, in _multicall
    res = hook_impl.function(*args)
  File "C:\Users\bonjour\AppData\Local\Programs\Python\Python39\lib\site-packages\_pytest\python.py", line 183, in pytest_pyfunc_call
    result = testfunction(**testargs)
  File "E:\12\TestCase\test_request.py", line 34, in test_001
    requestdata=RequestsHandler().get_Req(url=final_data[0]['url'],params=eval(final_data[0]['params']),headers=header_list,json="",data="")
  File ".\Common\requestbase.py", line 21, in get_Req
    self.logger.info(f'连通接口"{url}",接口header为:"{headers}",接口param为：{params}')
Message: '连通接口"https://supplychain-server-stg.jmj1995.com/items",接口header为:"{\'authorization\': \'Bearer eyJhbGciOiJIUzUxMiJ9.eyJqdGkiOiIzMTgyNGVlMzU3ODQ0NTU2OTI3NzU4YmI2YWIzZGMwMiIsImF1dGgiOiIiLCJpZCI6NTk2LCJzdWIiOiIxMiJ9.FAMtF8lnItJNt6d8AwlaDTEdY0VPs8rm_iY0Lpmta8OaG-ARUL4vRt-xD1-eCteU8v9QYiJq1kgDrBoOPYuLTw\'}",接口param为：{\'pageNum\': \'1\', \'pageSize\': \'20\'}'
Arguments: ()
2022-01-28 16:21:49,753 - INFO requestbase.py [line:21]: 连通接口"https://supplychain-server-stg.jmj1995.com/items",接口header为:"{'authorization': 'Bearer eyJhbGciOiJIUzUxMiJ9.eyJqdGkiOiIzMTgyNGVlMzU3ODQ0NTU2OTI3NzU4YmI2YWIzZGMwMiIsImF1dGgiOiIiLCJpZCI6NTk2LCJzdWIiOiIxMiJ9.FAMtF8lnItJNt6d8AwlaDTEdY0VPs8rm_iY0Lpmta8OaG-ARUL4vRt-xD1-eCteU8v9QYiJq1kgDrBoOPYuLTw'}",接口param为：{'pageNum': '1', 'pageSize': '20'}
2022-01-28 16:21:49,753 - INFO requestbase.py [line:21]: 连通接口"https://supplychain-server-stg.jmj1995.com/items",接口header为:"{'authorization': 'Bearer eyJhbGciOiJIUzUxMiJ9.eyJqdGkiOiIzMTgyNGVlMzU3ODQ0NTU2OTI3NzU4YmI2YWIzZGMwMiIsImF1dGgiOiIiLCJpZCI6NTk2LCJzdWIiOiIxMiJ9.FAMtF8lnItJNt6d8AwlaDTEdY0VPs8rm_iY0Lpmta8OaG-ARUL4vRt-xD1-eCteU8v9QYiJq1kgDrBoOPYuLTw'}",接口param为：{'pageNum': '1', 'pageSize': '20'}
2022-01-28 16:21:49,753 - INFO requestbase.py [line:21]: 连通接口"https://supplychain-server-stg.jmj1995.com/items",接口header为:"{'authorization': 'Bearer eyJhbGciOiJIUzUxMiJ9.eyJqdGkiOiIzMTgyNGVlMzU3ODQ0NTU2OTI3NzU4YmI2YWIzZGMwMiIsImF1dGgiOiIiLCJpZCI6NTk2LCJzdWIiOiIxMiJ9.FAMtF8lnItJNt6d8AwlaDTEdY0VPs8rm_iY0Lpmta8OaG-ARUL4vRt-xD1-eCteU8v9QYiJq1kgDrBoOPYuLTw'}",接口param为：{'pageNum': '1', 'pageSize': '20'}
--- Logging error ---
Traceback (most recent call last):
  File "C:\Users\bonjour\AppData\Local\Programs\Python\Python39\lib\logging\__init__.py", line 1082, in emit
    stream.write(msg + self.terminator)
OSError: [WinError 6] 句柄无效。
Call stack:
  File "e:\12\TestCase\test_request.py", line 59, in <module>
    pytest.main(["--alluredir", report_path])
  File "C:\Users\bonjour\AppData\Local\Programs\Python\Python39\lib\site-packages\_pytest\config\__init__.py", line 162, in main
    ret: Union[ExitCode, int] = config.hook.pytest_cmdline_main(
  File "C:\Users\bonjour\AppData\Local\Programs\Python\Python39\lib\site-packages\pluggy\_hooks.py", line 265, in __call__
    return self._hookexec(self.name, self.get_hookimpls(), kwargs, firstresult)
  File "C:\Users\bonjour\AppData\Local\Programs\Python\Python39\lib\site-packages\pluggy\_manager.py", line 80, in _hookexec
    return self._inner_hookexec(hook_name, methods, kwargs, firstresult)
  File "C:\Users\bonjour\AppData\Local\Programs\Python\Python39\lib\site-packages\pluggy\_callers.py", line 39, in _multicall
    res = hook_impl.function(*args)
  File "C:\Users\bonjour\AppData\Local\Programs\Python\Python39\lib\site-packages\_pytest\main.py", line 316, in pytest_cmdline_main
    return wrap_session(config, _main)
  File "C:\Users\bonjour\AppData\Local\Programs\Python\Python39\lib\site-packages\_pytest\main.py", line 269, in wrap_session
    session.exitstatus = doit(config, session) or 0
  File "C:\Users\bonjour\AppData\Local\Programs\Python\Python39\lib\site-packages\_pytest\main.py", line 323, in _main
    config.hook.pytest_runtestloop(session=session)
  File "C:\Users\bonjour\AppData\Local\Programs\Python\Python39\lib\site-packages\pluggy\_hooks.py", line 265, in __call__
    return self._hookexec(self.name, self.get_hookimpls(), kwargs, firstresult)
  File "C:\Users\bonjour\AppData\Local\Programs\Python\Python39\lib\site-packages\pluggy\_manager.py", line 80, in _hookexec
    return self._inner_hookexec(hook_name, methods, kwargs, firstresult)
  File "C:\Users\bonjour\AppData\Local\Programs\Python\Python39\lib\site-packages\pluggy\_callers.py", line 39, in _multicall
    res = hook_impl.function(*args)
  File "C:\Users\bonjour\AppData\Local\Programs\Python\Python39\lib\site-packages\_pytest\main.py", line 348, in pytest_runtestloop
    item.config.hook.pytest_runtest_protocol(item=item, nextitem=nextitem)
  File "C:\Users\bonjour\AppData\Local\Programs\Python\Python39\lib\site-packages\pluggy\_hooks.py", line 265, in __call__
    return self._hookexec(self.name, self.get_hookimpls(), kwargs, firstresult)
  File "C:\Users\bonjour\AppData\Local\Programs\Python\Python39\lib\site-packages\pluggy\_manager.py", line 80, in _hookexec
    return self._inner_hookexec(hook_name, methods, kwargs, firstresult)
  File "C:\Users\bonjour\AppData\Local\Programs\Python\Python39\lib\site-packages\pluggy\_callers.py", line 39, in _multicall
    res = hook_impl.function(*args)
  File "c:\users\bonjour\appdata\local\programs\python\python39\lib\site-packages\pytest_rerunfailures.py", line 497, in pytest_runtest_protocol
    reports = runtestprotocol(item, nextitem=nextitem, log=False)
  File "C:\Users\bonjour\AppData\Local\Programs\Python\Python39\lib\site-packages\_pytest\runner.py", line 126, in runtestprotocol
    reports.append(call_and_report(item, "call", log))
  File "C:\Users\bonjour\AppData\Local\Programs\Python\Python39\lib\site-packages\_pytest\runner.py", line 215, in call_and_report
    call = call_runtest_hook(item, when, **kwds)
  File "C:\Users\bonjour\AppData\Local\Programs\Python\Python39\lib\site-packages\_pytest\runner.py", line 254, in call_runtest_hook
    return CallInfo.from_call(
  File "C:\Users\bonjour\AppData\Local\Programs\Python\Python39\lib\site-packages\_pytest\runner.py", line 311, in from_call
    result: Optional[TResult] = func()
  File "C:\Users\bonjour\AppData\Local\Programs\Python\Python39\lib\site-packages\_pytest\runner.py", line 255, in <lambda>
    lambda: ihook(item=item, **kwds), when=when, reraise=reraise
  File "C:\Users\bonjour\AppData\Local\Programs\Python\Python39\lib\site-packages\pluggy\_hooks.py", line 265, in __call__
    return self._hookexec(self.name, self.get_hookimpls(), kwargs, firstresult)
  File "C:\Users\bonjour\AppData\Local\Programs\Python\Python39\lib\site-packages\pluggy\_manager.py", line 80, in _hookexec
    return self._inner_hookexec(hook_name, methods, kwargs, firstresult)
  File "C:\Users\bonjour\AppData\Local\Programs\Python\Python39\lib\site-packages\pluggy\_callers.py", line 39, in _multicall
    res = hook_impl.function(*args)
  File "C:\Users\bonjour\AppData\Local\Programs\Python\Python39\lib\site-packages\_pytest\runner.py", line 162, in pytest_runtest_call
    item.runtest()
  File "C:\Users\bonjour\AppData\Local\Programs\Python\Python39\lib\site-packages\_pytest\python.py", line 1641, in runtest
    self.ihook.pytest_pyfunc_call(pyfuncitem=self)
  File "C:\Users\bonjour\AppData\Local\Programs\Python\Python39\lib\site-packages\pluggy\_hooks.py", line 265, in __call__
    return self._hookexec(self.name, self.get_hookimpls(), kwargs, firstresult)
  File "C:\Users\bonjour\AppData\Local\Programs\Python\Python39\lib\site-packages\pluggy\_manager.py", line 80, in _hookexec
    return self._inner_hookexec(hook_name, methods, kwargs, firstresult)
  File "C:\Users\bonjour\AppData\Local\Programs\Python\Python39\lib\site-packages\pluggy\_callers.py", line 39, in _multicall
    res = hook_impl.function(*args)
  File "C:\Users\bonjour\AppData\Local\Programs\Python\Python39\lib\site-packages\_pytest\python.py", line 183, in pytest_pyfunc_call
    result = testfunction(**testargs)
  File "E:\12\TestCase\test_request.py", line 34, in test_001
    requestdata=RequestsHandler().get_Req(url=final_data[0]['url'],params=eval(final_data[0]['params']),headers=header_list,json="",data="")
  File ".\Common\requestbase.py", line 26, in get_Req
    self.logger.info(f'等待接口"{url}"时长:{end - start}')
Message: '等待接口"https://supplychain-server-stg.jmj1995.com/items"时长:0:00:00.149598'
Arguments: ()
--- Logging error ---
Traceback (most recent call last):
  File "C:\Users\bonjour\AppData\Local\Programs\Python\Python39\lib\logging\__init__.py", line 1082, in emit
    stream.write(msg + self.terminator)
OSError: [WinError 6] 句柄无效。
Call stack:
  File "e:\12\TestCase\test_request.py", line 59, in <module>
    pytest.main(["--alluredir", report_path])
  File "C:\Users\bonjour\AppData\Local\Programs\Python\Python39\lib\site-packages\_pytest\config\__init__.py", line 162, in main
    ret: Union[ExitCode, int] = config.hook.pytest_cmdline_main(
  File "C:\Users\bonjour\AppData\Local\Programs\Python\Python39\lib\site-packages\pluggy\_hooks.py", line 265, in __call__
    return self._hookexec(self.name, self.get_hookimpls(), kwargs, firstresult)
  File "C:\Users\bonjour\AppData\Local\Programs\Python\Python39\lib\site-packages\pluggy\_manager.py", line 80, in _hookexec
    return self._inner_hookexec(hook_name, methods, kwargs, firstresult)
  File "C:\Users\bonjour\AppData\Local\Programs\Python\Python39\lib\site-packages\pluggy\_callers.py", line 39, in _multicall
    res = hook_impl.function(*args)
  File "C:\Users\bonjour\AppData\Local\Programs\Python\Python39\lib\site-packages\_pytest\main.py", line 316, in pytest_cmdline_main
    return wrap_session(config, _main)
  File "C:\Users\bonjour\AppData\Local\Programs\Python\Python39\lib\site-packages\_pytest\main.py", line 269, in wrap_session
    session.exitstatus = doit(config, session) or 0
  File "C:\Users\bonjour\AppData\Local\Programs\Python\Python39\lib\site-packages\_pytest\main.py", line 323, in _main
    config.hook.pytest_runtestloop(session=session)
  File "C:\Users\bonjour\AppData\Local\Programs\Python\Python39\lib\site-packages\pluggy\_hooks.py", line 265, in __call__
    return self._hookexec(self.name, self.get_hookimpls(), kwargs, firstresult)
  File "C:\Users\bonjour\AppData\Local\Programs\Python\Python39\lib\site-packages\pluggy\_manager.py", line 80, in _hookexec
    return self._inner_hookexec(hook_name, methods, kwargs, firstresult)
  File "C:\Users\bonjour\AppData\Local\Programs\Python\Python39\lib\site-packages\pluggy\_callers.py", line 39, in _multicall
    res = hook_impl.function(*args)
  File "C:\Users\bonjour\AppData\Local\Programs\Python\Python39\lib\site-packages\_pytest\main.py", line 348, in pytest_runtestloop
    item.config.hook.pytest_runtest_protocol(item=item, nextitem=nextitem)
  File "C:\Users\bonjour\AppData\Local\Programs\Python\Python39\lib\site-packages\pluggy\_hooks.py", line 265, in __call__
    return self._hookexec(self.name, self.get_hookimpls(), kwargs, firstresult)
  File "C:\Users\bonjour\AppData\Local\Programs\Python\Python39\lib\site-packages\pluggy\_manager.py", line 80, in _hookexec
    return self._inner_hookexec(hook_name, methods, kwargs, firstresult)
  File "C:\Users\bonjour\AppData\Local\Programs\Python\Python39\lib\site-packages\pluggy\_callers.py", line 39, in _multicall
    res = hook_impl.function(*args)
  File "c:\users\bonjour\appdata\local\programs\python\python39\lib\site-packages\pytest_rerunfailures.py", line 497, in pytest_runtest_protocol
    reports = runtestprotocol(item, nextitem=nextitem, log=False)
  File "C:\Users\bonjour\AppData\Local\Programs\Python\Python39\lib\site-packages\_pytest\runner.py", line 126, in runtestprotocol
    reports.append(call_and_report(item, "call", log))
  File "C:\Users\bonjour\AppData\Local\Programs\Python\Python39\lib\site-packages\_pytest\runner.py", line 215, in call_and_report
    call = call_runtest_hook(item, when, **kwds)
  File "C:\Users\bonjour\AppData\Local\Programs\Python\Python39\lib\site-packages\_pytest\runner.py", line 254, in call_runtest_hook
    return CallInfo.from_call(
  File "C:\Users\bonjour\AppData\Local\Programs\Python\Python39\lib\site-packages\_pytest\runner.py", line 311, in from_call
    result: Optional[TResult] = func()
  File "C:\Users\bonjour\AppData\Local\Programs\Python\Python39\lib\site-packages\_pytest\runner.py", line 255, in <lambda>
    lambda: ihook(item=item, **kwds), when=when, reraise=reraise
  File "C:\Users\bonjour\AppData\Local\Programs\Python\Python39\lib\site-packages\pluggy\_hooks.py", line 265, in __call__
    return self._hookexec(self.name, self.get_hookimpls(), kwargs, firstresult)
  File "C:\Users\bonjour\AppData\Local\Programs\Python\Python39\lib\site-packages\pluggy\_manager.py", line 80, in _hookexec
    return self._inner_hookexec(hook_name, methods, kwargs, firstresult)
  File "C:\Users\bonjour\AppData\Local\Programs\Python\Python39\lib\site-packages\pluggy\_callers.py", line 39, in _multicall
    res = hook_impl.function(*args)
  File "C:\Users\bonjour\AppData\Local\Programs\Python\Python39\lib\site-packages\_pytest\runner.py", line 162, in pytest_runtest_call
    item.runtest()
  File "C:\Users\bonjour\AppData\Local\Programs\Python\Python39\lib\site-packages\_pytest\python.py", line 1641, in runtest
    self.ihook.pytest_pyfunc_call(pyfuncitem=self)
  File "C:\Users\bonjour\AppData\Local\Programs\Python\Python39\lib\site-packages\pluggy\_hooks.py", line 265, in __call__
    return self._hookexec(self.name, self.get_hookimpls(), kwargs, firstresult)
  File "C:\Users\bonjour\AppData\Local\Programs\Python\Python39\lib\site-packages\pluggy\_manager.py", line 80, in _hookexec
    return self._inner_hookexec(hook_name, methods, kwargs, firstresult)
  File "C:\Users\bonjour\AppData\Local\Programs\Python\Python39\lib\site-packages\pluggy\_callers.py", line 39, in _multicall
    res = hook_impl.function(*args)
  File "C:\Users\bonjour\AppData\Local\Programs\Python\Python39\lib\site-packages\_pytest\python.py", line 183, in pytest_pyfunc_call
    result = testfunction(**testargs)
  File "E:\12\TestCase\test_request.py", line 34, in test_001
    requestdata=RequestsHandler().get_Req(url=final_data[0]['url'],params=eval(final_data[0]['params']),headers=header_list,json="",data="")
  File ".\Common\requestbase.py", line 26, in get_Req
    self.logger.info(f'等待接口"{url}"时长:{end - start}')
Message: '等待接口"https://supplychain-server-stg.jmj1995.com/items"时长:0:00:00.149598'
Arguments: ()
2022-01-28 16:21:49,907 - INFO requestbase.py [line:26]: 等待接口"https://supplychain-server-stg.jmj1995.com/items"时长:0:00:00.149598
2022-01-28 16:21:49,907 - INFO requestbase.py [line:26]: 等待接口"https://supplychain-server-stg.jmj1995.com/items"时长:0:00:00.149598
2022-01-28 16:21:49,907 - INFO requestbase.py [line:26]: 等待接口"https://supplychain-server-stg.jmj1995.com/items"时长:0:00:00.149598
--- Logging error ---
Traceback (most recent call last):
  File "C:\Users\bonjour\AppData\Local\Programs\Python\Python39\lib\logging\__init__.py", line 1082, in emit
    stream.write(msg + self.terminator)
OSError: [WinError 6] 句柄无效。
Call stack:
  File "e:\12\TestCase\test_request.py", line 59, in <module>
    pytest.main(["--alluredir", report_path])
  File "C:\Users\bonjour\AppData\Local\Programs\Python\Python39\lib\site-packages\_pytest\config\__init__.py", line 162, in main
    ret: Union[ExitCode, int] = config.hook.pytest_cmdline_main(
  File "C:\Users\bonjour\AppData\Local\Programs\Python\Python39\lib\site-packages\pluggy\_hooks.py", line 265, in __call__
    return self._hookexec(self.name, self.get_hookimpls(), kwargs, firstresult)
  File "C:\Users\bonjour\AppData\Local\Programs\Python\Python39\lib\site-packages\pluggy\_manager.py", line 80, in _hookexec
    return self._inner_hookexec(hook_name, methods, kwargs, firstresult)
  File "C:\Users\bonjour\AppData\Local\Programs\Python\Python39\lib\site-packages\pluggy\_callers.py", line 39, in _multicall
    res = hook_impl.function(*args)
  File "C:\Users\bonjour\AppData\Local\Programs\Python\Python39\lib\site-packages\_pytest\main.py", line 316, in pytest_cmdline_main
    return wrap_session(config, _main)
  File "C:\Users\bonjour\AppData\Local\Programs\Python\Python39\lib\site-packages\_pytest\main.py", line 269, in wrap_session
    session.exitstatus = doit(config, session) or 0
  File "C:\Users\bonjour\AppData\Local\Programs\Python\Python39\lib\site-packages\_pytest\main.py", line 323, in _main
    config.hook.pytest_runtestloop(session=session)
  File "C:\Users\bonjour\AppData\Local\Programs\Python\Python39\lib\site-packages\pluggy\_hooks.py", line 265, in __call__
    return self._hookexec(self.name, self.get_hookimpls(), kwargs, firstresult)
  File "C:\Users\bonjour\AppData\Local\Programs\Python\Python39\lib\site-packages\pluggy\_manager.py", line 80, in _hookexec
    return self._inner_hookexec(hook_name, methods, kwargs, firstresult)
  File "C:\Users\bonjour\AppData\Local\Programs\Python\Python39\lib\site-packages\pluggy\_callers.py", line 39, in _multicall
    res = hook_impl.function(*args)
  File "C:\Users\bonjour\AppData\Local\Programs\Python\Python39\lib\site-packages\_pytest\main.py", line 348, in pytest_runtestloop
    item.config.hook.pytest_runtest_protocol(item=item, nextitem=nextitem)
  File "C:\Users\bonjour\AppData\Local\Programs\Python\Python39\lib\site-packages\pluggy\_hooks.py", line 265, in __call__
    return self._hookexec(self.name, self.get_hookimpls(), kwargs, firstresult)
  File "C:\Users\bonjour\AppData\Local\Programs\Python\Python39\lib\site-packages\pluggy\_manager.py", line 80, in _hookexec
    return self._inner_hookexec(hook_name, methods, kwargs, firstresult)
  File "C:\Users\bonjour\AppData\Local\Programs\Python\Python39\lib\site-packages\pluggy\_callers.py", line 39, in _multicall
    res = hook_impl.function(*args)
  File "c:\users\bonjour\appdata\local\programs\python\python39\lib\site-packages\pytest_rerunfailures.py", line 497, in pytest_runtest_protocol
    reports = runtestprotocol(item, nextitem=nextitem, log=False)
  File "C:\Users\bonjour\AppData\Local\Programs\Python\Python39\lib\site-packages\_pytest\runner.py", line 126, in runtestprotocol
    reports.append(call_and_report(item, "call", log))
  File "C:\Users\bonjour\AppData\Local\Programs\Python\Python39\lib\site-packages\_pytest\runner.py", line 215, in call_and_report
    call = call_runtest_hook(item, when, **kwds)
  File "C:\Users\bonjour\AppData\Local\Programs\Python\Python39\lib\site-packages\_pytest\runner.py", line 254, in call_runtest_hook
    return CallInfo.from_call(
  File "C:\Users\bonjour\AppData\Local\Programs\Python\Python39\lib\site-packages\_pytest\runner.py", line 311, in from_call
    result: Optional[TResult] = func()
  File "C:\Users\bonjour\AppData\Local\Programs\Python\Python39\lib\site-packages\_pytest\runner.py", line 255, in <lambda>
    lambda: ihook(item=item, **kwds), when=when, reraise=reraise
  File "C:\Users\bonjour\AppData\Local\Programs\Python\Python39\lib\site-packages\pluggy\_hooks.py", line 265, in __call__
    return self._hookexec(self.name, self.get_hookimpls(), kwargs, firstresult)
  File "C:\Users\bonjour\AppData\Local\Programs\Python\Python39\lib\site-packages\pluggy\_manager.py", line 80, in _hookexec
    return self._inner_hookexec(hook_name, methods, kwargs, firstresult)
  File "C:\Users\bonjour\AppData\Local\Programs\Python\Python39\lib\site-packages\pluggy\_callers.py", line 39, in _multicall
    res = hook_impl.function(*args)
  File "C:\Users\bonjour\AppData\Local\Programs\Python\Python39\lib\site-packages\_pytest\runner.py", line 162, in pytest_runtest_call
    item.runtest()
  File "C:\Users\bonjour\AppData\Local\Programs\Python\Python39\lib\site-packages\_pytest\python.py", line 1641, in runtest
    self.ihook.pytest_pyfunc_call(pyfuncitem=self)
  File "C:\Users\bonjour\AppData\Local\Programs\Python\Python39\lib\site-packages\pluggy\_hooks.py", line 265, in __call__
    return self._hookexec(self.name, self.get_hookimpls(), kwargs, firstresult)
  File "C:\Users\bonjour\AppData\Local\Programs\Python\Python39\lib\site-packages\pluggy\_manager.py", line 80, in _hookexec
    return self._inner_hookexec(hook_name, methods, kwargs, firstresult)
  File "C:\Users\bonjour\AppData\Local\Programs\Python\Python39\lib\site-packages\pluggy\_callers.py", line 39, in _multicall
    res = hook_impl.function(*args)
  File "C:\Users\bonjour\AppData\Local\Programs\Python\Python39\lib\site-packages\_pytest\python.py", line 183, in pytest_pyfunc_call
    result = testfunction(**testargs)
  File "E:\12\TestCase\test_request.py", line 35, in test_001
    asser.assert_code(final_data[0]['status_code'],requestdata.status_code)
  File ".\Common\assertbase.py", line 28, in assert_code
    self.logger.info(f'预计接口返回code为"{code}",实际返回code为:"{url_code}"')
Message: '预计接口返回code为"200.0",实际返回code为:"200"'
Arguments: ()
--- Logging error ---
Traceback (most recent call last):
  File "C:\Users\bonjour\AppData\Local\Programs\Python\Python39\lib\logging\__init__.py", line 1082, in emit
    stream.write(msg + self.terminator)
OSError: [WinError 6] 句柄无效。
Call stack:
  File "e:\12\TestCase\test_request.py", line 59, in <module>
    pytest.main(["--alluredir", report_path])
  File "C:\Users\bonjour\AppData\Local\Programs\Python\Python39\lib\site-packages\_pytest\config\__init__.py", line 162, in main
    ret: Union[ExitCode, int] = config.hook.pytest_cmdline_main(
  File "C:\Users\bonjour\AppData\Local\Programs\Python\Python39\lib\site-packages\pluggy\_hooks.py", line 265, in __call__
    return self._hookexec(self.name, self.get_hookimpls(), kwargs, firstresult)
  File "C:\Users\bonjour\AppData\Local\Programs\Python\Python39\lib\site-packages\pluggy\_manager.py", line 80, in _hookexec
    return self._inner_hookexec(hook_name, methods, kwargs, firstresult)
  File "C:\Users\bonjour\AppData\Local\Programs\Python\Python39\lib\site-packages\pluggy\_callers.py", line 39, in _multicall
    res = hook_impl.function(*args)
  File "C:\Users\bonjour\AppData\Local\Programs\Python\Python39\lib\site-packages\_pytest\main.py", line 316, in pytest_cmdline_main
    return wrap_session(config, _main)
  File "C:\Users\bonjour\AppData\Local\Programs\Python\Python39\lib\site-packages\_pytest\main.py", line 269, in wrap_session
    session.exitstatus = doit(config, session) or 0
  File "C:\Users\bonjour\AppData\Local\Programs\Python\Python39\lib\site-packages\_pytest\main.py", line 323, in _main
    config.hook.pytest_runtestloop(session=session)
  File "C:\Users\bonjour\AppData\Local\Programs\Python\Python39\lib\site-packages\pluggy\_hooks.py", line 265, in __call__
    return self._hookexec(self.name, self.get_hookimpls(), kwargs, firstresult)
  File "C:\Users\bonjour\AppData\Local\Programs\Python\Python39\lib\site-packages\pluggy\_manager.py", line 80, in _hookexec
    return self._inner_hookexec(hook_name, methods, kwargs, firstresult)
  File "C:\Users\bonjour\AppData\Local\Programs\Python\Python39\lib\site-packages\pluggy\_callers.py", line 39, in _multicall
    res = hook_impl.function(*args)
  File "C:\Users\bonjour\AppData\Local\Programs\Python\Python39\lib\site-packages\_pytest\main.py", line 348, in pytest_runtestloop
    item.config.hook.pytest_runtest_protocol(item=item, nextitem=nextitem)
  File "C:\Users\bonjour\AppData\Local\Programs\Python\Python39\lib\site-packages\pluggy\_hooks.py", line 265, in __call__
    return self._hookexec(self.name, self.get_hookimpls(), kwargs, firstresult)
  File "C:\Users\bonjour\AppData\Local\Programs\Python\Python39\lib\site-packages\pluggy\_manager.py", line 80, in _hookexec
    return self._inner_hookexec(hook_name, methods, kwargs, firstresult)
  File "C:\Users\bonjour\AppData\Local\Programs\Python\Python39\lib\site-packages\pluggy\_callers.py", line 39, in _multicall
    res = hook_impl.function(*args)
  File "c:\users\bonjour\appdata\local\programs\python\python39\lib\site-packages\pytest_rerunfailures.py", line 497, in pytest_runtest_protocol
    reports = runtestprotocol(item, nextitem=nextitem, log=False)
  File "C:\Users\bonjour\AppData\Local\Programs\Python\Python39\lib\site-packages\_pytest\runner.py", line 126, in runtestprotocol
    reports.append(call_and_report(item, "call", log))
  File "C:\Users\bonjour\AppData\Local\Programs\Python\Python39\lib\site-packages\_pytest\runner.py", line 215, in call_and_report
    call = call_runtest_hook(item, when, **kwds)
  File "C:\Users\bonjour\AppData\Local\Programs\Python\Python39\lib\site-packages\_pytest\runner.py", line 254, in call_runtest_hook
    return CallInfo.from_call(
  File "C:\Users\bonjour\AppData\Local\Programs\Python\Python39\lib\site-packages\_pytest\runner.py", line 311, in from_call
    result: Optional[TResult] = func()
  File "C:\Users\bonjour\AppData\Local\Programs\Python\Python39\lib\site-packages\_pytest\runner.py", line 255, in <lambda>
    lambda: ihook(item=item, **kwds), when=when, reraise=reraise
  File "C:\Users\bonjour\AppData\Local\Programs\Python\Python39\lib\site-packages\pluggy\_hooks.py", line 265, in __call__
    return self._hookexec(self.name, self.get_hookimpls(), kwargs, firstresult)
  File "C:\Users\bonjour\AppData\Local\Programs\Python\Python39\lib\site-packages\pluggy\_manager.py", line 80, in _hookexec
    return self._inner_hookexec(hook_name, methods, kwargs, firstresult)
  File "C:\Users\bonjour\AppData\Local\Programs\Python\Python39\lib\site-packages\pluggy\_callers.py", line 39, in _multicall
    res = hook_impl.function(*args)
  File "C:\Users\bonjour\AppData\Local\Programs\Python\Python39\lib\site-packages\_pytest\runner.py", line 162, in pytest_runtest_call
    item.runtest()
  File "C:\Users\bonjour\AppData\Local\Programs\Python\Python39\lib\site-packages\_pytest\python.py", line 1641, in runtest
    self.ihook.pytest_pyfunc_call(pyfuncitem=self)
  File "C:\Users\bonjour\AppData\Local\Programs\Python\Python39\lib\site-packages\pluggy\_hooks.py", line 265, in __call__
    return self._hookexec(self.name, self.get_hookimpls(), kwargs, firstresult)
  File "C:\Users\bonjour\AppData\Local\Programs\Python\Python39\lib\site-packages\pluggy\_manager.py", line 80, in _hookexec
    return self._inner_hookexec(hook_name, methods, kwargs, firstresult)
  File "C:\Users\bonjour\AppData\Local\Programs\Python\Python39\lib\site-packages\pluggy\_callers.py", line 39, in _multicall
    res = hook_impl.function(*args)
  File "C:\Users\bonjour\AppData\Local\Programs\Python\Python39\lib\site-packages\_pytest\python.py", line 183, in pytest_pyfunc_call
    result = testfunction(**testargs)
  File "E:\12\TestCase\test_request.py", line 35, in test_001
    asser.assert_code(final_data[0]['status_code'],requestdata.status_code)
  File ".\Common\assertbase.py", line 28, in assert_code
    self.logger.info(f'预计接口返回code为"{code}",实际返回code为:"{url_code}"')
Message: '预计接口返回code为"200.0",实际返回code为:"200"'
Arguments: ()
2022-01-28 16:21:49,909 - INFO assertbase.py [line:28]: 预计接口返回code为"200.0",实际返回code为:"200"
2022-01-28 16:21:49,909 - INFO assertbase.py [line:28]: 预计接口返回code为"200.0",实际返回code为:"200"
2022-01-28 16:21:49,909 - INFO assertbase.py [line:28]: 预计接口返回code为"200.0",实际返回code为:"200"
--- Logging error ---
Traceback (most recent call last):
  File "C:\Users\bonjour\AppData\Local\Programs\Python\Python39\lib\logging\__init__.py", line 1082, in emit
    stream.write(msg + self.terminator)
OSError: [WinError 6] 句柄无效。
Call stack:
  File "e:\12\TestCase\test_request.py", line 59, in <module>
    pytest.main(["--alluredir", report_path])
  File "C:\Users\bonjour\AppData\Local\Programs\Python\Python39\lib\site-packages\_pytest\config\__init__.py", line 162, in main
    ret: Union[ExitCode, int] = config.hook.pytest_cmdline_main(
  File "C:\Users\bonjour\AppData\Local\Programs\Python\Python39\lib\site-packages\pluggy\_hooks.py", line 265, in __call__
    return self._hookexec(self.name, self.get_hookimpls(), kwargs, firstresult)
  File "C:\Users\bonjour\AppData\Local\Programs\Python\Python39\lib\site-packages\pluggy\_manager.py", line 80, in _hookexec
    return self._inner_hookexec(hook_name, methods, kwargs, firstresult)
  File "C:\Users\bonjour\AppData\Local\Programs\Python\Python39\lib\site-packages\pluggy\_callers.py", line 39, in _multicall
    res = hook_impl.function(*args)
  File "C:\Users\bonjour\AppData\Local\Programs\Python\Python39\lib\site-packages\_pytest\main.py", line 316, in pytest_cmdline_main
    return wrap_session(config, _main)
  File "C:\Users\bonjour\AppData\Local\Programs\Python\Python39\lib\site-packages\_pytest\main.py", line 269, in wrap_session
    session.exitstatus = doit(config, session) or 0
  File "C:\Users\bonjour\AppData\Local\Programs\Python\Python39\lib\site-packages\_pytest\main.py", line 323, in _main
    config.hook.pytest_runtestloop(session=session)
  File "C:\Users\bonjour\AppData\Local\Programs\Python\Python39\lib\site-packages\pluggy\_hooks.py", line 265, in __call__
    return self._hookexec(self.name, self.get_hookimpls(), kwargs, firstresult)
  File "C:\Users\bonjour\AppData\Local\Programs\Python\Python39\lib\site-packages\pluggy\_manager.py", line 80, in _hookexec
    return self._inner_hookexec(hook_name, methods, kwargs, firstresult)
  File "C:\Users\bonjour\AppData\Local\Programs\Python\Python39\lib\site-packages\pluggy\_callers.py", line 39, in _multicall
    res = hook_impl.function(*args)
  File "C:\Users\bonjour\AppData\Local\Programs\Python\Python39\lib\site-packages\_pytest\main.py", line 348, in pytest_runtestloop
    item.config.hook.pytest_runtest_protocol(item=item, nextitem=nextitem)
  File "C:\Users\bonjour\AppData\Local\Programs\Python\Python39\lib\site-packages\pluggy\_hooks.py", line 265, in __call__
    return self._hookexec(self.name, self.get_hookimpls(), kwargs, firstresult)
  File "C:\Users\bonjour\AppData\Local\Programs\Python\Python39\lib\site-packages\pluggy\_manager.py", line 80, in _hookexec
    return self._inner_hookexec(hook_name, methods, kwargs, firstresult)
  File "C:\Users\bonjour\AppData\Local\Programs\Python\Python39\lib\site-packages\pluggy\_callers.py", line 39, in _multicall
    res = hook_impl.function(*args)
  File "c:\users\bonjour\appdata\local\programs\python\python39\lib\site-packages\pytest_rerunfailures.py", line 497, in pytest_runtest_protocol
    reports = runtestprotocol(item, nextitem=nextitem, log=False)
  File "C:\Users\bonjour\AppData\Local\Programs\Python\Python39\lib\site-packages\_pytest\runner.py", line 126, in runtestprotocol
    reports.append(call_and_report(item, "call", log))
  File "C:\Users\bonjour\AppData\Local\Programs\Python\Python39\lib\site-packages\_pytest\runner.py", line 215, in call_and_report
    call = call_runtest_hook(item, when, **kwds)
  File "C:\Users\bonjour\AppData\Local\Programs\Python\Python39\lib\site-packages\_pytest\runner.py", line 254, in call_runtest_hook
    return CallInfo.from_call(
  File "C:\Users\bonjour\AppData\Local\Programs\Python\Python39\lib\site-packages\_pytest\runner.py", line 311, in from_call
    result: Optional[TResult] = func()
  File "C:\Users\bonjour\AppData\Local\Programs\Python\Python39\lib\site-packages\_pytest\runner.py", line 255, in <lambda>
    lambda: ihook(item=item, **kwds), when=when, reraise=reraise
  File "C:\Users\bonjour\AppData\Local\Programs\Python\Python39\lib\site-packages\pluggy\_hooks.py", line 265, in __call__
    return self._hookexec(self.name, self.get_hookimpls(), kwargs, firstresult)
  File "C:\Users\bonjour\AppData\Local\Programs\Python\Python39\lib\site-packages\pluggy\_manager.py", line 80, in _hookexec
    return self._inner_hookexec(hook_name, methods, kwargs, firstresult)
  File "C:\Users\bonjour\AppData\Local\Programs\Python\Python39\lib\site-packages\pluggy\_callers.py", line 39, in _multicall
    res = hook_impl.function(*args)
  File "C:\Users\bonjour\AppData\Local\Programs\Python\Python39\lib\site-packages\_pytest\runner.py", line 162, in pytest_runtest_call
    item.runtest()
  File "C:\Users\bonjour\AppData\Local\Programs\Python\Python39\lib\site-packages\_pytest\python.py", line 1641, in runtest
    self.ihook.pytest_pyfunc_call(pyfuncitem=self)
  File "C:\Users\bonjour\AppData\Local\Programs\Python\Python39\lib\site-packages\pluggy\_hooks.py", line 265, in __call__
    return self._hookexec(self.name, self.get_hookimpls(), kwargs, firstresult)
  File "C:\Users\bonjour\AppData\Local\Programs\Python\Python39\lib\site-packages\pluggy\_manager.py", line 80, in _hookexec
    return self._inner_hookexec(hook_name, methods, kwargs, firstresult)
  File "C:\Users\bonjour\AppData\Local\Programs\Python\Python39\lib\site-packages\pluggy\_callers.py", line 39, in _multicall
    res = hook_impl.function(*args)
  File "C:\Users\bonjour\AppData\Local\Programs\Python\Python39\lib\site-packages\_pytest\python.py", line 183, in pytest_pyfunc_call
    result = testfunction(**testargs)
  File "E:\12\TestCase\test_request.py", line 35, in test_001
    asser.assert_code(final_data[0]['status_code'],requestdata.status_code)
  File ".\Common\assertbase.py", line 31, in assert_code
    self.logger.info(f'预计接口返回code为"{code}",实际返回code为:"{url_code}"')
Message: '预计接口返回code为"200.0",实际返回code为:"200"'
Arguments: ()
--- Logging error ---
Traceback (most recent call last):
  File "C:\Users\bonjour\AppData\Local\Programs\Python\Python39\lib\logging\__init__.py", line 1082, in emit
    stream.write(msg + self.terminator)
OSError: [WinError 6] 句柄无效。
Call stack:
  File "e:\12\TestCase\test_request.py", line 59, in <module>
    pytest.main(["--alluredir", report_path])
  File "C:\Users\bonjour\AppData\Local\Programs\Python\Python39\lib\site-packages\_pytest\config\__init__.py", line 162, in main
    ret: Union[ExitCode, int] = config.hook.pytest_cmdline_main(
  File "C:\Users\bonjour\AppData\Local\Programs\Python\Python39\lib\site-packages\pluggy\_hooks.py", line 265, in __call__
    return self._hookexec(self.name, self.get_hookimpls(), kwargs, firstresult)
  File "C:\Users\bonjour\AppData\Local\Programs\Python\Python39\lib\site-packages\pluggy\_manager.py", line 80, in _hookexec
    return self._inner_hookexec(hook_name, methods, kwargs, firstresult)
  File "C:\Users\bonjour\AppData\Local\Programs\Python\Python39\lib\site-packages\pluggy\_callers.py", line 39, in _multicall
    res = hook_impl.function(*args)
  File "C:\Users\bonjour\AppData\Local\Programs\Python\Python39\lib\site-packages\_pytest\main.py", line 316, in pytest_cmdline_main
    return wrap_session(config, _main)
  File "C:\Users\bonjour\AppData\Local\Programs\Python\Python39\lib\site-packages\_pytest\main.py", line 269, in wrap_session
    session.exitstatus = doit(config, session) or 0
  File "C:\Users\bonjour\AppData\Local\Programs\Python\Python39\lib\site-packages\_pytest\main.py", line 323, in _main
    config.hook.pytest_runtestloop(session=session)
  File "C:\Users\bonjour\AppData\Local\Programs\Python\Python39\lib\site-packages\pluggy\_hooks.py", line 265, in __call__
    return self._hookexec(self.name, self.get_hookimpls(), kwargs, firstresult)
  File "C:\Users\bonjour\AppData\Local\Programs\Python\Python39\lib\site-packages\pluggy\_manager.py", line 80, in _hookexec
    return self._inner_hookexec(hook_name, methods, kwargs, firstresult)
  File "C:\Users\bonjour\AppData\Local\Programs\Python\Python39\lib\site-packages\pluggy\_callers.py", line 39, in _multicall
    res = hook_impl.function(*args)
  File "C:\Users\bonjour\AppData\Local\Programs\Python\Python39\lib\site-packages\_pytest\main.py", line 348, in pytest_runtestloop
    item.config.hook.pytest_runtest_protocol(item=item, nextitem=nextitem)
  File "C:\Users\bonjour\AppData\Local\Programs\Python\Python39\lib\site-packages\pluggy\_hooks.py", line 265, in __call__
    return self._hookexec(self.name, self.get_hookimpls(), kwargs, firstresult)
  File "C:\Users\bonjour\AppData\Local\Programs\Python\Python39\lib\site-packages\pluggy\_manager.py", line 80, in _hookexec
    return self._inner_hookexec(hook_name, methods, kwargs, firstresult)
  File "C:\Users\bonjour\AppData\Local\Programs\Python\Python39\lib\site-packages\pluggy\_callers.py", line 39, in _multicall
    res = hook_impl.function(*args)
  File "c:\users\bonjour\appdata\local\programs\python\python39\lib\site-packages\pytest_rerunfailures.py", line 497, in pytest_runtest_protocol
    reports = runtestprotocol(item, nextitem=nextitem, log=False)
  File "C:\Users\bonjour\AppData\Local\Programs\Python\Python39\lib\site-packages\_pytest\runner.py", line 126, in runtestprotocol
    reports.append(call_and_report(item, "call", log))
  File "C:\Users\bonjour\AppData\Local\Programs\Python\Python39\lib\site-packages\_pytest\runner.py", line 215, in call_and_report
    call = call_runtest_hook(item, when, **kwds)
  File "C:\Users\bonjour\AppData\Local\Programs\Python\Python39\lib\site-packages\_pytest\runner.py", line 254, in call_runtest_hook
    return CallInfo.from_call(
  File "C:\Users\bonjour\AppData\Local\Programs\Python\Python39\lib\site-packages\_pytest\runner.py", line 311, in from_call
    result: Optional[TResult] = func()
  File "C:\Users\bonjour\AppData\Local\Programs\Python\Python39\lib\site-packages\_pytest\runner.py", line 255, in <lambda>
    lambda: ihook(item=item, **kwds), when=when, reraise=reraise
  File "C:\Users\bonjour\AppData\Local\Programs\Python\Python39\lib\site-packages\pluggy\_hooks.py", line 265, in __call__
    return self._hookexec(self.name, self.get_hookimpls(), kwargs, firstresult)
  File "C:\Users\bonjour\AppData\Local\Programs\Python\Python39\lib\site-packages\pluggy\_manager.py", line 80, in _hookexec
    return self._inner_hookexec(hook_name, methods, kwargs, firstresult)
  File "C:\Users\bonjour\AppData\Local\Programs\Python\Python39\lib\site-packages\pluggy\_callers.py", line 39, in _multicall
    res = hook_impl.function(*args)
  File "C:\Users\bonjour\AppData\Local\Programs\Python\Python39\lib\site-packages\_pytest\runner.py", line 162, in pytest_runtest_call
    item.runtest()
  File "C:\Users\bonjour\AppData\Local\Programs\Python\Python39\lib\site-packages\_pytest\python.py", line 1641, in runtest
    self.ihook.pytest_pyfunc_call(pyfuncitem=self)
  File "C:\Users\bonjour\AppData\Local\Programs\Python\Python39\lib\site-packages\pluggy\_hooks.py", line 265, in __call__
    return self._hookexec(self.name, self.get_hookimpls(), kwargs, firstresult)
  File "C:\Users\bonjour\AppData\Local\Programs\Python\Python39\lib\site-packages\pluggy\_manager.py", line 80, in _hookexec
    return self._inner_hookexec(hook_name, methods, kwargs, firstresult)
  File "C:\Users\bonjour\AppData\Local\Programs\Python\Python39\lib\site-packages\pluggy\_callers.py", line 39, in _multicall
    res = hook_impl.function(*args)
  File "C:\Users\bonjour\AppData\Local\Programs\Python\Python39\lib\site-packages\_pytest\python.py", line 183, in pytest_pyfunc_call
    result = testfunction(**testargs)
  File "E:\12\TestCase\test_request.py", line 35, in test_001
    asser.assert_code(final_data[0]['status_code'],requestdata.status_code)
  File ".\Common\assertbase.py", line 31, in assert_code
    self.logger.info(f'预计接口返回code为"{code}",实际返回code为:"{url_code}"')
Message: '预计接口返回code为"200.0",实际返回code为:"200"'
Arguments: ()
2022-01-28 16:21:49,911 - INFO assertbase.py [line:31]: 预计接口返回code为"200.0",实际返回code为:"200"
2022-01-28 16:21:49,911 - INFO assertbase.py [line:31]: 预计接口返回code为"200.0",实际返回code为:"200"
2022-01-28 16:21:49,911 - INFO assertbase.py [line:31]: 预计接口返回code为"200.0",实际返回code为:"200"
